Workbook

Sheet Variables
B1: Arabica - Commercial | C1: Arabica - Micro-Lots | D1: Robusta
A3: Parameter | B3: Arabica (Commercial) | C3: Arabica (Micro-Lots) | D3: Robusta | E3: Unit
A5: Avg value of Coffee | B5: =443*1000/60 -> 7383.3333 | C5: =505*16.67 -> 8418.35 | D5: N/A | E5: USD/MT
A6: Avg NY value | B6: 290.8 | C6: 290.8 | D6: N/A | E6: USD cents/lb
A7: Cost of financing per annum | B7: =(3.08+3.36822)/100 -> 0.0644822 | C7: =(3.08+3.36822)/100 -> 0.0644822 | D7: N/A | E7: % p.a.
A8: Cost of storage (USD/MT/Day) | B8: =0.05*16.67 -> 0.8335 | C8: =0.05*16.67 -> 0.8335 | D8: N/A | E8: USD/MT/day
A9: Cost of Insurance per annum | B9: 0.0008313 | C9: 0.0008313 | D9: N/A | E9: % p.a.
A11: Parameter | B11: Value | E11: Unit | F11: Department
A13: Days before expected shipment date to stuff | B13: 15 | E13: days
A14: Days before shipment for sample approval | B14: 30 | E14: days
A15: Days to move coffee to warehouse | B15: 7 | E15: days
A16: Days bulk coffee | B16: 5 | E16: days
A17: Days to stuff coffee | B17: 3 | E17: days
A18: Days to sail after stuffing | B18: 15 | E18: days | F18: 1
A19: Days to dispatch docs after sailing | B19: 5 | E19: days
A21: Packaging Type | B21: Bags per Container | E21: Unit
A22: Jute bags | B22: 320 | E22: bags
A23: Blowing | B23: 360 | E23: bags
A24: Big bags | B24: 333 | E24: bags
A33: Parameter | B33: Value | E33: Unit
A34: Bags per container – minimum | B34: 320 | E34: bags
A35: Bags per container – maximum | B35: 360 | E35: bags
A37: Sample Type | B37: PSS Required? (Yes / No)
A38: SAS | B38: Yes
A39: APS | B39: No
A40: No PSS Needed | B40: No
A41: No SAS | B41: No
A42: NANS | B42: Yes

Sheet KENYA
A1: Origin County | B1: Type (Arabica / Robusta) | C1: Subtype (Commercial / Micro-Lots) | D1: Contract Date | E1: Shipment Start Date | F1: Shipment End Date | G1: Sale Contract Ref | H1: Purchase Contract Ref | I1: Client Ref | J1: Buyer | K1: SI No. | L1: Bags | M1: Containers (Keyed In) | N1: Quality Description | O1: Quality Basket / Grade | P1: Quality Code | Q1: Certification | R1: Packaging Type | S1: Destination Port | T1: Destination Country | U1: Continent | V1: Differential | W1: USD Value of Shipment | X1: Sample Type | Y1: PSS Required (Yes / No) | Z1: PSS Dispatch Date | AA1: PSS Dispatch Info | AB1: PSS Approval Date | AC1: Sample Approval Status | AD1: Shipping Instructions Receipt Date | AE1: Bulk Ref | AF1: Bulk Instruction Date | AG1: Expected Shipment Period | AH1: Trade & QC Days Lost | AI1: Expected Stuffing Date | AJ1: Actual Stuffing Date | AK1: Operational Days Lost | AL1: C&F Agent | AM1: Shipping Line | AN1: Vessel | AO1: Gate In POL | AP1: ETD POL | AQ1: ETA POD | AR1: B/L No | AS1: Actual Sailing Date | AT1: Edox Ref No. | AU1: Shipping Advice Sent Date | AV1: Courier Tracking No | AW1: Docs Dispatch Date | AX1: Contract Status (Open / Cancelled / Closed) | AY1: Reason for Open Contracts Status | AZ1: Delay Category | BA1: Main Delay Root Cause | BB1: Department | BC1: Comments | BD1: In Transit & Port Dwell Days | BE1: Days Gain/Loss from Docs Dispatch | BF1: USD Loss/Gain from Docs | BG1: P&L Impact on Sample Approval | BH1: USD Saved/Lost on Processing | BI1: USD Saved/Lost on Shipping | BJ1: Days Late / Early | BK1: Cost
A2: Kenya | B2: Arabica | C2: Commercial | D2: 45420 | E2: 45672 | F2: 45688 | G2: 3786364 | H2: P38155 | J2: Serengeti | K2: 5146 | L2: 1280 | M2: 4 | N2: AB FAQ Scr 15+.SAS on replacement basis. | O2: ABC FAQ | P2: 10080 | R2: 60kg Jute Bags | S2: New Orleans | T2: USA | U2: North America | V2: 16 | W2: =IF($AX2="Cancelled","",IFERROR(((V2+INDEX(Variables!$B$6:$D$6,IFERROR(MATCH(IF($B2="Robusta","Robusta",(IF($B2="","Arabica",$B2))&" - "&(IF($C2="","Commercial",$C2))),Variables!$B$1:$D$1,0),1)))*22.0462)*(L2/16.67),"")) -> 519353.98 | X2: SAS | Y2: =IF($AX2="Cancelled","",IF(X2="","",IFERROR(IF(INDEX(Variables!$B$38:$B$47,MATCH(X2,Variables!$A$38:$A$47,0))="Yes","Yes","No"),"No"))) -> Yes | Z2: 45617 | AB2: 45623 | AC2: =IF($AX2="Cancelled","",IF(ISNUMBER(AB2),"Approved","")) -> Approved | AF2: 45680 | AG2: =IF($AX2="Cancelled","",IFERROR(IF(F2="","",F2-Variables!$B$13),"")) -> 45673 | AH2: =IF($AX2="Cancelled","",IFERROR(IF(AB2="","",(AVERAGE(E2:F2)-AB2)-Variables!$B$14),"")) -> 27 | AJ2: 45681 | AK2: =IF($AX2="Cancelled","",IFERROR(IF(AJ2="","",IF(AND(AB2="",AF2=""),"",IF(AF2>AB2,AF2+Variables!$B$15+Variables!$B$16+Variables!$B$17-AJ2,AB2+Variables!$B$16+Variables!$B$17-AJ2))),"")) -> 14 | AL2: Iceberg | AM2: Maersk FCL/FCL | AN2: Maersk Cape Town | AP2: 45688 | AR2: 249329922 | AS2: 45688 | AU2: 45691 | AV2: Email | AW2: 45693 | AX2: =IF(ISNUMBER(SEARCH("cancel",#REF!)),"Cancelled",IF(AND(AS2<>"",AU2<>"",AW2<>""),"Closed","Open")) -> Closed | AY2: =IF($AX2="Cancelled","",IF(AND(AS2<>"",AU2<>"",AW2<>""),"All dates received",_xlfn.TEXTJOIN(" and ",TRUE(),IF(AS2="","No sailing date",""),IF(AU2="","No shipping advice sent",""),IF(AW2="","No docs dispatch date","")))) -> All dates received | BD2: =IF($AX2="Cancelled","",IFERROR(IF(OR(AS2="",AJ2=""),"",(AJ2+Variables!$B$18-AS2)),"")) -> 8 | BE2: =IF($AX2="Cancelled","",IFERROR(IF(OR(AW2="",AS2=""),"",(AS2+Variables!$B$19)-AW2),"")) -> 0 | BF2: =IF($AX2="Cancelled","",IFERROR(W2*INDEX(Variables!$B$7:$D$7,IFERROR(MATCH(IF($B2="Robusta","Robusta",(IF($B2="","Arabica",$B2))&" - "&(IF($C2="","Commercial",$C2))),Variables!$B$1:$D$1,0),1))*(BE2/365),"")) -> 0 | BG2: =IF($AX2="Cancelled","",IFERROR((W2*INDEX(Variables!$B$7:$D$7,IFERROR(MATCH(IF($B2="Robusta","Robusta",(IF($B2="","Arabica",$B2))&" - "&(IF($C2="","Commercial",$C2))),Variables!$B$1:$D$1,0),1))*IFERROR(IF(AB2="","",(AVERAGE(E2:F2)-AB2)-Variables!$B$14),"")/365)+(L2/16.67*INDEX(Variables!$B$8:$D$8,IFERROR(MATCH(IF($B2="Robusta","Robusta",(IF($B2="","Arabica",$B2))&" - "&(IF($C2="","Commercial",$C2))),Variables!$B$1:$D$1,0),1))*IFERROR(IF(AB2="","",(AVERAGE(E2:F2)-AB2)-Variables!$B$14),""))+(W2*INDEX(Variables!$B$9:$D$9,IFERROR(MATCH(IF($B2="Robusta","Robusta",(IF($B2="","Arabica",$B2))&" - "&(IF($C2="","Commercial",$C2))),Variables!$B$1:$D$1,0),1))*IFERROR(IF(AB2="","",(AVERAGE(E2:F2)-AB2)-Variables!$B$14),"")/365),"")) -> 4237.2118 | BH2: =IF($AX2="Cancelled","",IFERROR((W2*INDEX(Variables!$B$7:$D$7,IFERROR(MATCH(IF($B2="Robusta","Robusta",(IF($B2="","Arabica",$B2))&" - "&(IF($C2="","Commercial",$C2))),Variables!$B$1:$D$1,0),1))*AK2/365)+(L2/16.67*INDEX(Variables!$B$8:$D$8,IFERROR(MATCH(IF($B2="Robusta","Robusta",(IF($B2="","Arabica",$B2))&" - "&(IF($C2="","Commercial",$C2))),Variables!$B$1:$D$1,0),1))*AK2)+(W2*INDEX(Variables!$B$9:$D$9,IFERROR(MATCH(IF($B2="Robusta","Robusta",(IF($B2="","Arabica",$B2))&" - "&(IF($C2="","Commercial",$C2))),Variables!$B$1:$D$1,0),1))*AK2/365),"")) -> 2197.0728 | BI2: =IF($AX2="Cancelled","",IFERROR((W2*INDEX(Variables!$B$7:$D$7,IFERROR(MATCH(IF($B2="Robusta","Robusta",(IF($B2="","Arabica",$B2))&" - "&(IF($C2="","Commercial",$C2))),Variables!$B$1:$D$1,0),1))*BD2/365)+(L2/16.67*INDEX(Variables!$B$8:$D$8,IFERROR(MATCH(IF($B2="Robusta","Robusta",(IF($B2="","Arabica",$B2))&" - "&(IF($C2="","Commercial",$C2))),Variables!$B$1:$D$1,0),1))*BD2)+(W2*INDEX(Variables!$B$9:$D$9,IFERROR(MATCH(IF($B2="Robusta","Robusta",(IF($B2="","Arabica",$B2))&" - "&(IF($C2="","Commercial",$C2))),Variables!$B$1:$D$1,0),1))*BD2/365),"")) -> 1255.4702 | BJ2: =IF($AX2="Cancelled","",IFERROR(IF(AS2="","",F2-AS2),"")) -> 0 | BK2: =IF($AX2="Cancelled","",IFERROR(IF(BJ2="","",(W2*INDEX(Variables!$B$7:$D$7,IFERROR(MATCH(IF($B2="Robusta","Robusta",(IF($B2="","Arabica",$B2))&" - "&(IF($C2="","Commercial",$C2))),Variables!$B$1:$D$1,0),1))*(BJ2/365))+(W2*INDEX(Variables!$B$9:$D$9,IFERROR(MATCH(IF($B2="Robusta","Robusta",(IF($B2="","Arabica",$B2))&" - "&(IF($C2="","Commercial",$C2))),Variables!$B$1:$D$1,0),1))*(BJ2/365))+(INDEX(Variables!$B$8:$D$8,IFERROR(MATCH(IF($B2="Robusta","Robusta",(IF($B2="","Arabica",$B2))&" - "&(IF($C2="","Commercial",$C2))),Variables!$B$1:$D$1,0),1))*L2/16.67)),"")) -> 64
A3: Kenya | B3: Arabica | C3: Commercial | D3: 45531 | E3: 45658 | F3: 45688 | G3: 3786486 | H3: 01-92282 | J3: BR | K3: 5139 | L3: 360 | M3: 1 | N3: JDE AB FAQ EUDR Aligned | O3: AB FAQ | P3: 10080 | Q3: EUDR | R3: Bulk Bag | S3: Fos Sur Mer | T3: France | U3: Europe | V3: 20 | W3: =IF($AX3="Cancelled","",IFERROR(((V3+INDEX(Variables!$B$6:$D$6,IFERROR(MATCH(IF($B3="Robusta","Robusta",(IF($B3="","Arabica",$B3))&" - "&(IF($C3="","Commercial",$C3))),Variables!$B$1:$D$1,0),1)))*22.0462)*(L3/16.67),"")) -> 147972.72 | X3: SAS | Y3: =IF($AX3="Cancelled","",IF(X3="","",IFERROR(IF(INDEX(Variables!$B$38:$B$47,MATCH(X3,Variables!$A$38:$A$47,0))="Yes","Yes","No"),"No"))) -> Yes | Z3: 45616 | AB3: 45628 | AC3: =IF($AX3="Cancelled","",IF(ISNUMBER(AB3),"Approved","")) -> Approved | AF3: 45666 | AG3: =IF($AX3="Cancelled","",IFERROR(IF(F3="","",F3-Variables!$B$13),"")) -> 45673 | AH3: =IF($AX3="Cancelled","",IFERROR(IF(AB3="","",(AVERAGE(E3:F3)-AB3)-Variables!$B$14),"")) -> 15 | AJ3: 45667 | AK3: =IF($AX3="Cancelled","",IFERROR(IF(AJ3="","",IF(AND(AB3="",AF3=""),"",IF(AF3>AB3,AF3+Variables!$B$15+Variables!$B$16+Variables!$B$17-AJ3,AB3+Variables!$B$16+Variables!$B$17-AJ3))),"")) -> 14 | AL3: Iceberg | AM3: Maersk FCL/FCL | AN3: Marathopolis | AP3: 45674 | AR3: 248898555 | AS3: 45674 | AU3: 45677 | AV3: Email | AW3: 45677 | AX3: =IF(ISNUMBER(SEARCH("cancel",#REF!)),"Cancelled",IF(AND(AS3<>"",AU3<>"",AW3<>""),"Closed","Open")) -> Closed | AY3: =IF($AX3="Cancelled","",IF(AND(AS3<>"",AU3<>"",AW3<>""),"All dates received",_xlfn.TEXTJOIN(" and ",TRUE(),IF(AS3="","No sailing date",""),IF(AU3="","No shipping advice sent",""),IF(AW3="","No docs dispatch date","")))) -> All dates received | BD3: =IF($AX3="Cancelled","",IFERROR(IF(OR(AS3="",AJ3=""),"",(AJ3+Variables!$B$18-AS3)),"")) -> 8 | BE3: =IF($AX3="Cancelled","",IFERROR(IF(OR(AW3="",AS3=""),"",(AS3+Variables!$B$19)-AW3),"")) -> 2 | BF3: =IF($AX3="Cancelled","",IFERROR(W3*INDEX(Variables!$B$7:$D$7,IFERROR(MATCH(IF($B3="Robusta","Robusta",(IF($B3="","Arabica",$B3))&" - "&(IF($C3="","Commercial",$C3))),Variables!$B$1:$D$1,0),1))*(BE3/365),"")) -> 52.282775 | BG3: =IF($AX3="Cancelled","",IFERROR((W3*INDEX(Variables!$B$7:$D$7,IFERROR(MATCH(IF($B3="Robusta","Robusta",(IF($B3="","Arabica",$B3))&" - "&(IF($C3="","Commercial",$C3))),Variables!$B$1:$D$1,0),1))*IFERROR(IF(AB3="","",(AVERAGE(E3:F3)-AB3)-Variables!$B$14),"")/365)+(L3/16.67*INDEX(Variables!$B$8:$D$8,IFERROR(MATCH(IF($B3="Robusta","Robusta",(IF($B3="","Arabica",$B3))&" - "&(IF($C3="","Commercial",$C3))),Variables!$B$1:$D$1,0),1))*IFERROR(IF(AB3="","",(AVERAGE(E3:F3)-AB3)-Variables!$B$14),""))+(W3*INDEX(Variables!$B$9:$D$9,IFERROR(MATCH(IF($B3="Robusta","Robusta",(IF($B3="","Arabica",$B3))&" - "&(IF($C3="","Commercial",$C3))),Variables!$B$1:$D$1,0),1))*IFERROR(IF(AB3="","",(AVERAGE(E3:F3)-AB3)-Variables!$B$14),"")/365),"")) -> 667.17601 | BH3: =IF($AX3="Cancelled","",IFERROR((W3*INDEX(Variables!$B$7:$D$7,IFERROR(MATCH(IF($B3="Robusta","Robusta",(IF($B3="","Arabica",$B3))&" - "&(IF($C3="","Commercial",$C3))),Variables!$B$1:$D$1,0),1))*AK3/365)+(L3/16.67*INDEX(Variables!$B$8:$D$8,IFERROR(MATCH(IF($B3="Robusta","Robusta",(IF($B3="","Arabica",$B3))&" - "&(IF($C3="","Commercial",$C3))),Variables!$B$1:$D$1,0),1))*AK3)+(W3*INDEX(Variables!$B$9:$D$9,IFERROR(MATCH(IF($B3="Robusta","Robusta",(IF($B3="","Arabica",$B3))&" - "&(IF($C3="","Commercial",$C3))),Variables!$B$1:$D$1,0),1))*AK3/365),"")) -> 622.69761 | BI3: =IF($AX3="Cancelled","",IFERROR((W3*INDEX(Variables!$B$7:$D$7,IFERROR(MATCH(IF($B3="Robusta","Robusta",(IF($B3="","Arabica",$B3))&" - "&(IF($C3="","Commercial",$C3))),Variables!$B$1:$D$1,0),1))*BD3/365)+(L3/16.67*INDEX(Variables!$B$8:$D$8,IFERROR(MATCH(IF($B3="Robusta","Robusta",(IF($B3="","Arabica",$B3))&" - "&(IF($C3="","Commercial",$C3))),Variables!$B$1:$D$1,0),1))*BD3)+(W3*INDEX(Variables!$B$9:$D$9,IFERROR(MATCH(IF($B3="Robusta","Robusta",(IF($B3="","Arabica",$B3))&" - "&(IF($C3="","Commercial",$C3))),Variables!$B$1:$D$1,0),1))*BD3/365),"")) -> 355.8272 | BJ3: =IF($AX3="Cancelled","",IFERROR(IF(AS3="","",F3-AS3),"")) -> 14 | BK3: =IF($AX3="Cancelled","",IFERROR(IF(BJ3="","",(W3*INDEX(Variables!$B$7:$D$7,IFERROR(MATCH(IF($B3="Robusta","Robusta",(IF($B3="","Arabica",$B3))&" - "&(IF($C3="","Commercial",$C3))),Variables!$B$1:$D$1,0),1))*(BJ3/365))+(W3*INDEX(Variables!$B$9:$D$9,IFERROR(MATCH(IF($B3="Robusta","Robusta",(IF($B3="","Arabica",$B3))&" - "&(IF($C3="","Commercial",$C3))),Variables!$B$1:$D$1,0),1))*(BJ3/365))+(INDEX(Variables!$B$8:$D$8,IFERROR(MATCH(IF($B3="Robusta","Robusta",(IF($B3="","Arabica",$B3))&" - "&(IF($C3="","Commercial",$C3))),Variables!$B$1:$D$1,0),1))*L3/16.67)),"")) -> 388.69761
A4: Kenya | B4: Arabica | C4: Commercial | D4: 45531 | E4: 45717 | F4: 45747 | G4: 3786487 | H4: 01-92283 | J4: BR | K4: 5183 | L4: 360 | M4: 1 | N4: JDE AB FAQ EUDR Aligned | O4: AB FAQ | P4: 10080 | Q4: EUDR | R4: Bulk Bag | S4: Fos Sur Mer | T4: France | U4: Europe | V4: 20 | W4: =IF($AX4="Cancelled","",IFERROR(((V4+INDEX(Variables!$B$6:$D$6,IFERROR(MATCH(IF($B4="Robusta","Robusta",(IF($B4="","Arabica",$B4))&" - "&(IF($C4="","Commercial",$C4))),Variables!$B$1:$D$1,0),1)))*22.0462)*(L4/16.67),"")) -> 147972.72 | X4: SAS | Y4: =IF($AX4="Cancelled","",IF(X4="","",IFERROR(IF(INDEX(Variables!$B$38:$B$47,MATCH(X4,Variables!$A$38:$A$47,0))="Yes","Yes","No"),"No"))) -> Yes | Z4: 45677 | AB4: 45692 | AC4: =IF($AX4="Cancelled","",IF(ISNUMBER(AB4),"Approved","")) -> Approved | AF4: 45716 | AG4: =IF($AX4="Cancelled","",IFERROR(IF(F4="","",F4-Variables!$B$13),"")) -> 45732 | AH4: =IF($AX4="Cancelled","",IFERROR(IF(AB4="","",(AVERAGE(E4:F4)-AB4)-Variables!$B$14),"")) -> 10 | AJ4: 45717 | AK4: =IF($AX4="Cancelled","",IFERROR(IF(AJ4="","",IF(AND(AB4="",AF4=""),"",IF(AF4>AB4,AF4+Variables!$B$15+Variables!$B$16+Variables!$B$17-AJ4,AB4+Variables!$B$16+Variables!$B$17-AJ4))),"")) -> 14 | AL4: Iceberg | AM4: Maersk FCL/FCL | AN4: Marathopolis | AP4: 45730 | AR4: 250667662 | AS4: 45730 | AU4: 45734 | AV4: Email | AW4: 45734 | AX4: =IF(ISNUMBER(SEARCH("cancel",#REF!)),"Cancelled",IF(AND(AS4<>"",AU4<>"",AW4<>""),"Closed","Open")) -> Closed | AY4: =IF($AX4="Cancelled","",IF(AND(AS4<>"",AU4<>"",AW4<>""),"All dates received",_xlfn.TEXTJOIN(" and ",TRUE(),IF(AS4="","No sailing date",""),IF(AU4="","No shipping advice sent",""),IF(AW4="","No docs dispatch date","")))) -> All dates received | BD4: =IF($AX4="Cancelled","",IFERROR(IF(OR(AS4="",AJ4=""),"",(AJ4+Variables!$B$18-AS4)),"")) -> 2 | BE4: =IF($AX4="Cancelled","",IFERROR(IF(OR(AW4="",AS4=""),"",(AS4+Variables!$B$19)-AW4),"")) -> 1 | BF4: =IF($AX4="Cancelled","",IFERROR(W4*INDEX(Variables!$B$7:$D$7,IFERROR(MATCH(IF($B4="Robusta","Robusta",(IF($B4="","Arabica",$B4))&" - "&(IF($C4="","Commercial",$C4))),Variables!$B$1:$D$1,0),1))*(BE4/365),"")) -> 26.141388 | BG4: =IF($AX4="Cancelled","",IFERROR((W4*INDEX(Variables!$B$7:$D$7,IFERROR(MATCH(IF($B4="Robusta","Robusta",(IF($B4="","Arabica",$B4))&" - "&(IF($C4="","Commercial",$C4))),Variables!$B$1:$D$1,0),1))*IFERROR(IF(AB4="","",(AVERAGE(E4:F4)-AB4)-Variables!$B$14),"")/365)+(L4/16.67*INDEX(Variables!$B$8:$D$8,IFERROR(MATCH(IF($B4="Robusta","Robusta",(IF($B4="","Arabica",$B4))&" - "&(IF($C4="","Commercial",$C4))),Variables!$B$1:$D$1,0),1))*IFERROR(IF(AB4="","",(AVERAGE(E4:F4)-AB4)-Variables!$B$14),""))+(W4*INDEX(Variables!$B$9:$D$9,IFERROR(MATCH(IF($B4="Robusta","Robusta",(IF($B4="","Arabica",$B4))&" - "&(IF($C4="","Commercial",$C4))),Variables!$B$1:$D$1,0),1))*IFERROR(IF(AB4="","",(AVERAGE(E4:F4)-AB4)-Variables!$B$14),"")/365),"")) -> 444.784 | BH4: =IF($AX4="Cancelled","",IFERROR((W4*INDEX(Variables!$B$7:$D$7,IFERROR(MATCH(IF($B4="Robusta","Robusta",(IF($B4="","Arabica",$B4))&" - "&(IF($C4="","Commercial",$C4))),Variables!$B$1:$D$1,0),1))*AK4/365)+(L4/16.67*INDEX(Variables!$B$8:$D$8,IFERROR(MATCH(IF($B4="Robusta","Robusta",(IF($B4="","Arabica",$B4))&" - "&(IF($C4="","Commercial",$C4))),Variables!$B$1:$D$1,0),1))*AK4)+(W4*INDEX(Variables!$B$9:$D$9,IFERROR(MATCH(IF($B4="Robusta","Robusta",(IF($B4="","Arabica",$B4))&" - "&(IF($C4="","Commercial",$C4))),Variables!$B$1:$D$1,0),1))*AK4/365),"")) -> 622.69761 | BI4: =IF($AX4="Cancelled","",IFERROR((W4*INDEX(Variables!$B$7:$D$7,IFERROR(MATCH(IF($B4="Robusta","Robusta",(IF($B4="","Arabica",$B4))&" - "&(IF($C4="","Commercial",$C4))),Variables!$B$1:$D$1,0),1))*BD4/365)+(L4/16.67*INDEX(Variables!$B$8:$D$8,IFERROR(MATCH(IF($B4="Robusta","Robusta",(IF($B4="","Arabica",$B4))&" - "&(IF($C4="","Commercial",$C4))),Variables!$B$1:$D$1,0),1))*BD4)+(W4*INDEX(Variables!$B$9:$D$9,IFERROR(MATCH(IF($B4="Robusta","Robusta",(IF($B4="","Arabica",$B4))&" - "&(IF($C4="","Commercial",$C4))),Variables!$B$1:$D$1,0),1))*BD4/365),"")) -> 88.956801 | BJ4: =IF($AX4="Cancelled","",IFERROR(IF(AS4="","",F4-AS4),"")) -> 17 | BK4: =IF($AX4="Cancelled","",IFERROR(IF(BJ4="","",(W4*INDEX(Variables!$B$7:$D$7,IFERROR(MATCH(IF($B4="Robusta","Robusta",(IF($B4="","Arabica",$B4))&" - "&(IF($C4="","Commercial",$C4))),Variables!$B$1:$D$1,0),1))*(BJ4/365))+(W4*INDEX(Variables!$B$9:$D$9,IFERROR(MATCH(IF($B4="Robusta","Robusta",(IF($B4="","Arabica",$B4))&" - "&(IF($C4="","Commercial",$C4))),Variables!$B$1:$D$1,0),1))*(BJ4/365))+(INDEX(Variables!$B$8:$D$8,IFERROR(MATCH(IF($B4="Robusta","Robusta",(IF($B4="","Arabica",$B4))&" - "&(IF($C4="","Commercial",$C4))),Variables!$B$1:$D$1,0),1))*L4/16.67)),"")) -> 468.13281
A5: Kenya | B5: Arabica | C5: Commercial | D5: 45531 | E5: 45658 | F5: 45688 | G5: 3786489 | H5: 01-92285 | J5: BR | K5: 5140A | L5: 1080 | M5: 3 | N5: JDE Grinders EUDR Aligned | O5: Grinder plus | P5: 10120 | Q5: EUDR | R5: Bulk Bag | S5: Gavle | T5: Sweden | U5: Europe | V5: -26 | W5: =IF($AX5="Cancelled","",IFERROR(((V5+INDEX(Variables!$B$6:$D$6,IFERROR(MATCH(IF($B5="Robusta","Robusta",(IF($B5="","Arabica",$B5))&" - "&(IF($C5="","Commercial",$C5))),Variables!$B$1:$D$1,0),1)))*22.0462)*(L5/16.67),"")) -> 378215.98 | X5: SAS | Y5: =IF($AX5="Cancelled","",IF(X5="","",IFERROR(IF(INDEX(Variables!$B$38:$B$47,MATCH(X5,Variables!$A$38:$A$47,0))="Yes","Yes","No"),"No"))) -> Yes | Z5: 45667 | AB5: 45673 | AC5: =IF($AX5="Cancelled","",IF(ISNUMBER(AB5),"Approved","")) -> Approved | AF5: 45674 | AG5: =IF($AX5="Cancelled","",IFERROR(IF(F5="","",F5-Variables!$B$13),"")) -> 45673 | AH5: =IF($AX5="Cancelled","",IFERROR(IF(AB5="","",(AVERAGE(E5:F5)-AB5)-Variables!$B$14),"")) -> -30 | AJ5: 45675 | AK5: =IF($AX5="Cancelled","",IFERROR(IF(AJ5="","",IF(AND(AB5="",AF5=""),"",IF(AF5>AB5,AF5+Variables!$B$15+Variables!$B$16+Variables!$B$17-AJ5,AB5+Variables!$B$16+Variables!$B$17-AJ5))),"")) -> 14 | AL5: Iceberg | AM5: CMA-CGM FCL/FCL | AN5: CMA-CGM Gulf Express | AP5: 45688 | AR5: MOB0148600 | AS5: 45688 | AU5: 45692 | AV5: Email | AW5: 45695 | AX5: =IF(ISNUMBER(SEARCH("cancel",#REF!)),"Cancelled",IF(AND(AS5<>"",AU5<>"",AW5<>""),"Closed","Open")) -> Closed | AY5: =IF($AX5="Cancelled","",IF(AND(AS5<>"",AU5<>"",AW5<>""),"All dates received",_xlfn.TEXTJOIN(" and ",TRUE(),IF(AS5="","No sailing date",""),IF(AU5="","No shipping advice sent",""),IF(AW5="","No docs dispatch date","")))) -> All dates received | BD5: =IF($AX5="Cancelled","",IFERROR(IF(OR(AS5="",AJ5=""),"",(AJ5+Variables!$B$18-AS5)),"")) -> 2 | BE5: =IF($AX5="Cancelled","",IFERROR(IF(OR(AW5="",AS5=""),"",(AS5+Variables!$B$19)-AW5),"")) -> -2 | BF5: =IF($AX5="Cancelled","",IFERROR(W5*INDEX(Variables!$B$7:$D$7,IFERROR(MATCH(IF($B5="Robusta","Robusta",(IF($B5="","Arabica",$B5))&" - "&(IF($C5="","Commercial",$C5))),Variables!$B$1:$D$1,0),1))*(BE5/365),"")) -> -133.63397 | BG5: =IF($AX5="Cancelled","",IFERROR((W5*INDEX(Variables!$B$7:$D$7,IFERROR(MATCH(IF($B5="Robusta","Robusta",(IF($B5="","Arabica",$B5))&" - "&(IF($C5="","Commercial",$C5))),Variables!$B$1:$D$1,0),1))*IFERROR(IF(AB5="","",(AVERAGE(E5:F5)-AB5)-Variables!$B$14),"")/365)+(L5/16.67*INDEX(Variables!$B$8:$D$8,IFERROR(MATCH(IF($B5="Robusta","Robusta",(IF($B5="","Arabica",$B5))&" - "&(IF($C5="","Commercial",$C5))),Variables!$B$1:$D$1,0),1))*IFERROR(IF(AB5="","",(AVERAGE(E5:F5)-AB5)-Variables!$B$14),""))+(W5*INDEX(Variables!$B$9:$D$9,IFERROR(MATCH(IF($B5="Robusta","Robusta",(IF($B5="","Arabica",$B5))&" - "&(IF($C5="","Commercial",$C5))),Variables!$B$1:$D$1,0),1))*IFERROR(IF(AB5="","",(AVERAGE(E5:F5)-AB5)-Variables!$B$14),"")/365),"")) -> -3650.3515 | BH5: =IF($AX5="Cancelled","",IFERROR((W5*INDEX(Variables!$B$7:$D$7,IFERROR(MATCH(IF($B5="Robusta","Robusta",(IF($B5="","Arabica",$B5))&" - "&(IF($C5="","Commercial",$C5))),Variables!$B$1:$D$1,0),1))*AK5/365)+(L5/16.67*INDEX(Variables!$B$8:$D$8,IFERROR(MATCH(IF($B5="Robusta","Robusta",(IF($B5="","Arabica",$B5))&" - "&(IF($C5="","Commercial",$C5))),Variables!$B$1:$D$1,0),1))*AK5)+(W5*INDEX(Variables!$B$9:$D$9,IFERROR(MATCH(IF($B5="Robusta","Robusta",(IF($B5="","Arabica",$B5))&" - "&(IF($C5="","Commercial",$C5))),Variables!$B$1:$D$1,0),1))*AK5/365),"")) -> 1703.4974 | BI5: =IF($AX5="Cancelled","",IFERROR((W5*INDEX(Variables!$B$7:$D$7,IFERROR(MATCH(IF($B5="Robusta","Robusta",(IF($B5="","Arabica",$B5))&" - "&(IF($C5="","Commercial",$C5))),Variables!$B$1:$D$1,0),1))*BD5/365)+(L5/16.67*INDEX(Variables!$B$8:$D$8,IFERROR(MATCH(IF($B5="Robusta","Robusta",(IF($B5="","Arabica",$B5))&" - "&(IF($C5="","Commercial",$C5))),Variables!$B$1:$D$1,0),1))*BD5)+(W5*INDEX(Variables!$B$9:$D$9,IFERROR(MATCH(IF($B5="Robusta","Robusta",(IF($B5="","Arabica",$B5))&" - "&(IF($C5="","Commercial",$C5))),Variables!$B$1:$D$1,0),1))*BD5/365),"")) -> 243.35677 | BJ5: =IF($AX5="Cancelled","",IFERROR(IF(AS5="","",F5-AS5),"")) -> 0 | BK5: =IF($AX5="Cancelled","",IFERROR(IF(BJ5="","",(W5*INDEX(Variables!$B$7:$D$7,IFERROR(MATCH(IF($B5="Robusta","Robusta",(IF($B5="","Arabica",$B5))&" - "&(IF($C5="","Commercial",$C5))),Variables!$B$1:$D$1,0),1))*(BJ5/365))+(W5*INDEX(Variables!$B$9:$D$9,IFERROR(MATCH(IF($B5="Robusta","Robusta",(IF($B5="","Arabica",$B5))&" - "&(IF($C5="","Commercial",$C5))),Variables!$B$1:$D$1,0),1))*(BJ5/365))+(INDEX(Variables!$B$8:$D$8,IFERROR(MATCH(IF($B5="Robusta","Robusta",(IF($B5="","Arabica",$B5))&" - "&(IF($C5="","Commercial",$C5))),Variables!$B$1:$D$1,0),1))*L5/16.67)),"")) -> 54
A6: Kenya | B6: Arabica | C6: Commercial | D6: 45531 | E6: 45658 | F6: 45688 | G6: 3786489 | H6: 01-92285 | J6: BR | K6: 5140B | L6: 360 | M6: 1 | N6: JDE Grinders EUDR Aligned | O6: Grinder plus | P6: 10120 | Q6: EUDR | R6: Bulk Bag | S6: Rotterdam | T6: Netherlands | U6: Europe | V6: -26 | W6: =IF($AX6="Cancelled","",IFERROR(((V6+INDEX(Variables!$B$6:$D$6,IFERROR(MATCH(IF($B6="Robusta","Robusta",(IF($B6="","Arabica",$B6))&" - "&(IF($C6="","Commercial",$C6))),Variables!$B$1:$D$1,0),1)))*22.0462)*(L6/16.67),"")) -> 126071.99 | X6: SAS | Y6: =IF($AX6="Cancelled","",IF(X6="","",IFERROR(IF(INDEX(Variables!$B$38:$B$47,MATCH(X6,Variables!$A$38:$A$47,0))="Yes","Yes","No"),"No"))) -> Yes | Z6: 45667 | AB6: 45673 | AC6: =IF($AX6="Cancelled","",IF(ISNUMBER(AB6),"Approved","")) -> Approved | AF6: 45674 | AG6: =IF($AX6="Cancelled","",IFERROR(IF(F6="","",F6-Variables!$B$13),"")) -> 45673 | AH6: =IF($AX6="Cancelled","",IFERROR(IF(AB6="","",(AVERAGE(E6:F6)-AB6)-Variables!$B$14),"")) -> -30 | AJ6: 45675 | AK6: =IF($AX6="Cancelled","",IFERROR(IF(AJ6="","",IF(AND(AB6="",AF6=""),"",IF(AF6>AB6,AF6+Variables!$B$15+Variables!$B$16+Variables!$B$17-AJ6,AB6+Variables!$B$16+Variables!$B$17-AJ6))),"")) -> 14 | AL6: Iceberg | AM6: CMA-CGM FCL/FCL | AN6: CMA-CGM Gulf Express | AP6: 45688 | AR6: MOB0148600 | AS6: 45688 | AU6: 45692 | AV6: Email | AW6: 45695 | AX6: =IF(ISNUMBER(SEARCH("cancel",#REF!)),"Cancelled",IF(AND(AS6<>"",AU6<>"",AW6<>""),"Closed","Open")) -> Closed | AY6: =IF($AX6="Cancelled","",IF(AND(AS6<>"",AU6<>"",AW6<>""),"All dates received",_xlfn.TEXTJOIN(" and ",TRUE(),IF(AS6="","No sailing date",""),IF(AU6="","No shipping advice sent",""),IF(AW6="","No docs dispatch date","")))) -> All dates received | BD6: =IF($AX6="Cancelled","",IFERROR(IF(OR(AS6="",AJ6=""),"",(AJ6+Variables!$B$18-AS6)),"")) -> 2 | BE6: =IF($AX6="Cancelled","",IFERROR(IF(OR(AW6="",AS6=""),"",(AS6+Variables!$B$19)-AW6),"")) -> -2 | BF6: =IF($AX6="Cancelled","",IFERROR(W6*INDEX(Variables!$B$7:$D$7,IFERROR(MATCH(IF($B6="Robusta","Robusta",(IF($B6="","Arabica",$B6))&" - "&(IF($C6="","Commercial",$C6))),Variables!$B$1:$D$1,0),1))*(BE6/365),"")) -> -44.544655 | BG6: =IF($AX6="Cancelled","",IFERROR((W6*INDEX(Variables!$B$7:$D$7,IFERROR(MATCH(IF($B6="Robusta","Robusta",(IF($B6="","Arabica",$B6))&" - "&(IF($C6="","Commercial",$C6))),Variables!$B$1:$D$1,0),1))*IFERROR(IF(AB6="","",(AVERAGE(E6:F6)-AB6)-Variables!$B$14),"")/365)+(L6/16.67*INDEX(Variables!$B$8:$D$8,IFERROR(MATCH(IF($B6="Robusta","Robusta",(IF($B6="","Arabica",$B6))&" - "&(IF($C6="","Commercial",$C6))),Variables!$B$1:$D$1,0),1))*IFERROR(IF(AB6="","",(AVERAGE(E6:F6)-AB6)-Variables!$B$14),""))+(W6*INDEX(Variables!$B$9:$D$9,IFERROR(MATCH(IF($B6="Robusta","Robusta",(IF($B6="","Arabica",$B6))&" - "&(IF($C6="","Commercial",$C6))),Variables!$B$1:$D$1,0),1))*IFERROR(IF(AB6="","",(AVERAGE(E6:F6)-AB6)-Variables!$B$14),"")/365),"")) -> -1216.7838 | BH6: =IF($AX6="Cancelled","",IFERROR((W6*INDEX(Variables!$B$7:$D$7,IFERROR(MATCH(IF($B6="Robusta","Robusta",(IF($B6="","Arabica",$B6))&" - "&(IF($C6="","Commercial",$C6))),Variables!$B$1:$D$1,0),1))*AK6/365)+(L6/16.67*INDEX(Variables!$B$8:$D$8,IFERROR(MATCH(IF($B6="Robusta","Robusta",(IF($B6="","Arabica",$B6))&" - "&(IF($C6="","Commercial",$C6))),Variables!$B$1:$D$1,0),1))*AK6)+(W6*INDEX(Variables!$B$9:$D$9,IFERROR(MATCH(IF($B6="Robusta","Robusta",(IF($B6="","Arabica",$B6))&" - "&(IF($C6="","Commercial",$C6))),Variables!$B$1:$D$1,0),1))*AK6/365),"")) -> 567.83245 | BI6: =IF($AX6="Cancelled","",IFERROR((W6*INDEX(Variables!$B$7:$D$7,IFERROR(MATCH(IF($B6="Robusta","Robusta",(IF($B6="","Arabica",$B6))&" - "&(IF($C6="","Commercial",$C6))),Variables!$B$1:$D$1,0),1))*BD6/365)+(L6/16.67*INDEX(Variables!$B$8:$D$8,IFERROR(MATCH(IF($B6="Robusta","Robusta",(IF($B6="","Arabica",$B6))&" - "&(IF($C6="","Commercial",$C6))),Variables!$B$1:$D$1,0),1))*BD6)+(W6*INDEX(Variables!$B$9:$D$9,IFERROR(MATCH(IF($B6="Robusta","Robusta",(IF($B6="","Arabica",$B6))&" - "&(IF($C6="","Commercial",$C6))),Variables!$B$1:$D$1,0),1))*BD6/365),"")) -> 81.118922 | BJ6: =IF($AX6="Cancelled","",IFERROR(IF(AS6="","",F6-AS6),"")) -> 0 | BK6: =IF($AX6="Cancelled","",IFERROR(IF(BJ6="","",(W6*INDEX(Variables!$B$7:$D$7,IFERROR(MATCH(IF($B6="Robusta","Robusta",(IF($B6="","Arabica",$B6))&" - "&(IF($C6="","Commercial",$C6))),Variables!$B$1:$D$1,0),1))*(BJ6/365))+(W6*INDEX(Variables!$B$9:$D$9,IFERROR(MATCH(IF($B6="Robusta","Robusta",(IF($B6="","Arabica",$B6))&" - "&(IF($C6="","Commercial",$C6))),Variables!$B$1:$D$1,0),1))*(BJ6/365))+(INDEX(Variables!$B$8:$D$8,IFERROR(MATCH(IF($B6="Robusta","Robusta",(IF($B6="","Arabica",$B6))&" - "&(IF($C6="","Commercial",$C6))),Variables!$B$1:$D$1,0),1))*L6/16.67)),"")) -> 18
A7: Kenya | B7: Arabica | C7: Commercial | D7: 45531 | E7: 45689 | F7: 45716 | G7: 3786490 | H7: 01-92286 | J7: BR | K7: 5158 | L7: 1440 | M7: 4 | N7: JDE Grinders EUDR Aligned | O7: Grinder plus | P7: 10120 | Q7: EUDR | R7: Bulk Bag | S7: Rotterdam | T7: Netherlands | U7: Europe | V7: -26 | W7: =IF($AX7="Cancelled","",IFERROR(((V7+INDEX(Variables!$B$6:$D$6,IFERROR(MATCH(IF($B7="Robusta","Robusta",(IF($B7="","Arabica",$B7))&" - "&(IF($C7="","Commercial",$C7))),Variables!$B$1:$D$1,0),1)))*22.0462)*(L7/16.67),"")) -> 504287.98 | X7: SAS | Y7: =IF($AX7="Cancelled","",IF(X7="","",IFERROR(IF(INDEX(Variables!$B$38:$B$47,MATCH(X7,Variables!$A$38:$A$47,0))="Yes","Yes","No"),"No"))) -> Yes | Z7: 45667 | AB7: 45673 | AC7: =IF($AX7="Cancelled","",IF(ISNUMBER(AB7),"Approved","")) -> Approved | AF7: 45688 | AG7: =IF($AX7="Cancelled","",IFERROR(IF(F7="","",F7-Variables!$B$13),"")) -> 45701 | AH7: =IF($AX7="Cancelled","",IFERROR(IF(AB7="","",(AVERAGE(E7:F7)-AB7)-Variables!$B$14),"")) -> -0.5 | AJ7: 45691 | AK7: =IF($AX7="Cancelled","",IFERROR(IF(AJ7="","",IF(AND(AB7="",AF7=""),"",IF(AF7>AB7,AF7+Variables!$B$15+Variables!$B$16+Variables!$B$17-AJ7,AB7+Variables!$B$16+Variables!$B$17-AJ7))),"")) -> 12 | AL7: Iceberg | AM7: WEC FCL/FCL | AN7: MSC Love V | AP7: 45708 | AR7: WECC2588RTM1041 | AS7: 45708 | AU7: 45714 | AV7: Email | AW7: 45714 | AX7: =IF(ISNUMBER(SEARCH("cancel",#REF!)),"Cancelled",IF(AND(AS7<>"",AU7<>"",AW7<>""),"Closed","Open")) -> Closed | AY7: =IF($AX7="Cancelled","",IF(AND(AS7<>"",AU7<>"",AW7<>""),"All dates received",_xlfn.TEXTJOIN(" and ",TRUE(),IF(AS7="","No sailing date",""),IF(AU7="","No shipping advice sent",""),IF(AW7="","No docs dispatch date","")))) -> All dates received | BD7: =IF($AX7="Cancelled","",IFERROR(IF(OR(AS7="",AJ7=""),"",(AJ7+Variables!$B$18-AS7)),"")) -> -2 | BE7: =IF($AX7="Cancelled","",IFERROR(IF(OR(AW7="",AS7=""),"",(AS7+Variables!$B$19)-AW7),"")) -> -1 | BF7: =IF($AX7="Cancelled","",IFERROR(W7*INDEX(Variables!$B$7:$D$7,IFERROR(MATCH(IF($B7="Robusta","Robusta",(IF($B7="","Arabica",$B7))&" - "&(IF($C7="","Commercial",$C7))),Variables!$B$1:$D$1,0),1))*(BE7/365),"")) -> -89.089311 | BG7: =IF($AX7="Cancelled","",IFERROR((W7*INDEX(Variables!$B$7:$D$7,IFERROR(MATCH(IF($B7="Robusta","Robusta",(IF($B7="","Arabica",$B7))&" - "&(IF($C7="","Commercial",$C7))),Variables!$B$1:$D$1,0),1))*IFERROR(IF(AB7="","",(AVERAGE(E7:F7)-AB7)-Variables!$B$14),"")/365)+(L7/16.67*INDEX(Variables!$B$8:$D$8,IFERROR(MATCH(IF($B7="Robusta","Robusta",(IF($B7="","Arabica",$B7))&" - "&(IF($C7="","Commercial",$C7))),Variables!$B$1:$D$1,0),1))*IFERROR(IF(AB7="","",(AVERAGE(E7:F7)-AB7)-Variables!$B$14),""))+(W7*INDEX(Variables!$B$9:$D$9,IFERROR(MATCH(IF($B7="Robusta","Robusta",(IF($B7="","Arabica",$B7))&" - "&(IF($C7="","Commercial",$C7))),Variables!$B$1:$D$1,0),1))*IFERROR(IF(AB7="","",(AVERAGE(E7:F7)-AB7)-Variables!$B$14),"")/365),"")) -> -81.118922 | BH7: =IF($AX7="Cancelled","",IFERROR((W7*INDEX(Variables!$B$7:$D$7,IFERROR(MATCH(IF($B7="Robusta","Robusta",(IF($B7="","Arabica",$B7))&" - "&(IF($C7="","Commercial",$C7))),Variables!$B$1:$D$1,0),1))*AK7/365)+(L7/16.67*INDEX(Variables!$B$8:$D$8,IFERROR(MATCH(IF($B7="Robusta","Robusta",(IF($B7="","Arabica",$B7))&" - "&(IF($C7="","Commercial",$C7))),Variables!$B$1:$D$1,0),1))*AK7)+(W7*INDEX(Variables!$B$9:$D$9,IFERROR(MATCH(IF($B7="Robusta","Robusta",(IF($B7="","Arabica",$B7))&" - "&(IF($C7="","Commercial",$C7))),Variables!$B$1:$D$1,0),1))*AK7/365),"")) -> 1946.8541 | BI7: =IF($AX7="Cancelled","",IFERROR((W7*INDEX(Variables!$B$7:$D$7,IFERROR(MATCH(IF($B7="Robusta","Robusta",(IF($B7="","Arabica",$B7))&" - "&(IF($C7="","Commercial",$C7))),Variables!$B$1:$D$1,0),1))*BD7/365)+(L7/16.67*INDEX(Variables!$B$8:$D$8,IFERROR(MATCH(IF($B7="Robusta","Robusta",(IF($B7="","Arabica",$B7))&" - "&(IF($C7="","Commercial",$C7))),Variables!$B$1:$D$1,0),1))*BD7)+(W7*INDEX(Variables!$B$9:$D$9,IFERROR(MATCH(IF($B7="Robusta","Robusta",(IF($B7="","Arabica",$B7))&" - "&(IF($C7="","Commercial",$C7))),Variables!$B$1:$D$1,0),1))*BD7/365),"")) -> -324.47569 | BJ7: =IF($AX7="Cancelled","",IFERROR(IF(AS7="","",F7-AS7),"")) -> 8 | BK7: =IF($AX7="Cancelled","",IFERROR(IF(BJ7="","",(W7*INDEX(Variables!$B$7:$D$7,IFERROR(MATCH(IF($B7="Robusta","Robusta",(IF($B7="","Arabica",$B7))&" - "&(IF($C7="","Commercial",$C7))),Variables!$B$1:$D$1,0),1))*(BJ7/365))+(W7*INDEX(Variables!$B$9:$D$9,IFERROR(MATCH(IF($B7="Robusta","Robusta",(IF($B7="","Arabica",$B7))&" - "&(IF($C7="","Commercial",$C7))),Variables!$B$1:$D$1,0),1))*(BJ7/365))+(INDEX(Variables!$B$8:$D$8,IFERROR(MATCH(IF($B7="Robusta","Robusta",(IF($B7="","Arabica",$B7))&" - "&(IF($C7="","Commercial",$C7))),Variables!$B$1:$D$1,0),1))*L7/16.67)),"")) -> 793.90275
A8: Kenya | B8: Arabica | C8: Commercial | D8: 45531 | E8: 45717 | F8: 45747 | G8: 3786491 | H8: 01-92287 | J8: BR | K8: 5195A | L8: 360 | M8: 1 | N8: JDE Grinders EUDR Aligned | O8: Grinder plus | P8: 10120 | Q8: EUDR | R8: Bulk Bag | S8: Fos Sur Mer | T8: France | U8: Europe | V8: -26 | W8: =IF($AX8="Cancelled","",IFERROR(((V8+INDEX(Variables!$B$6:$D$6,IFERROR(MATCH(IF($B8="Robusta","Robusta",(IF($B8="","Arabica",$B8))&" - "&(IF($C8="","Commercial",$C8))),Variables!$B$1:$D$1,0),1)))*22.0462)*(L8/16.67),"")) -> 126071.99 | X8: SAS | Y8: =IF($AX8="Cancelled","",IF(X8="","",IFERROR(IF(INDEX(Variables!$B$38:$B$47,MATCH(X8,Variables!$A$38:$A$47,0))="Yes","Yes","No"),"No"))) -> Yes | Z8: 45698 | AB8: 45714 | AC8: =IF($AX8="Cancelled","",IF(ISNUMBER(AB8),"Approved","")) -> Approved | AF8: 45721 | AG8: =IF($AX8="Cancelled","",IFERROR(IF(F8="","",F8-Variables!$B$13),"")) -> 45732 | AH8: =IF($AX8="Cancelled","",IFERROR(IF(AB8="","",(AVERAGE(E8:F8)-AB8)-Variables!$B$14),"")) -> -12 | AJ8: 45721 | AK8: =IF($AX8="Cancelled","",IFERROR(IF(AJ8="","",IF(AND(AB8="",AF8=""),"",IF(AF8>AB8,AF8+Variables!$B$15+Variables!$B$16+Variables!$B$17-AJ8,AB8+Variables!$B$16+Variables!$B$17-AJ8))),"")) -> 15 | AL8: Iceberg | AM8: WEC FCL/FCL | AN8: MSC Nuria | AP8: 45732 | AR8: WECC2588FOS1022 | AS8: 45732 | AU8: 45734 | AV8: Email | AW8: 45735 | AX8: =IF(ISNUMBER(SEARCH("cancel",#REF!)),"Cancelled",IF(AND(AS8<>"",AU8<>"",AW8<>""),"Closed","Open")) -> Closed | AY8: =IF($AX8="Cancelled","",IF(AND(AS8<>"",AU8<>"",AW8<>""),"All dates received",_xlfn.TEXTJOIN(" and ",TRUE(),IF(AS8="","No sailing date",""),IF(AU8="","No shipping advice sent",""),IF(AW8="","No docs dispatch date","")))) -> All dates received | BD8: =IF($AX8="Cancelled","",IFERROR(IF(OR(AS8="",AJ8=""),"",(AJ8+Variables!$B$18-AS8)),"")) -> 4 | BE8: =IF($AX8="Cancelled","",IFERROR(IF(OR(AW8="",AS8=""),"",(AS8+Variables!$B$19)-AW8),"")) -> 2 | BF8: =IF($AX8="Cancelled","",IFERROR(W8*INDEX(Variables!$B$7:$D$7,IFERROR(MATCH(IF($B8="Robusta","Robusta",(IF($B8="","Arabica",$B8))&" - "&(IF($C8="","Commercial",$C8))),Variables!$B$1:$D$1,0),1))*(BE8/365),"")) -> 44.544655 | BG8: =IF($AX8="Cancelled","",IFERROR((W8*INDEX(Variables!$B$7:$D$7,IFERROR(MATCH(IF($B8="Robusta","Robusta",(IF($B8="","Arabica",$B8))&" - "&(IF($C8="","Commercial",$C8))),Variables!$B$1:$D$1,0),1))*IFERROR(IF(AB8="","",(AVERAGE(E8:F8)-AB8)-Variables!$B$14),"")/365)+(L8/16.67*INDEX(Variables!$B$8:$D$8,IFERROR(MATCH(IF($B8="Robusta","Robusta",(IF($B8="","Arabica",$B8))&" - "&(IF($C8="","Commercial",$C8))),Variables!$B$1:$D$1,0),1))*IFERROR(IF(AB8="","",(AVERAGE(E8:F8)-AB8)-Variables!$B$14),""))+(W8*INDEX(Variables!$B$9:$D$9,IFERROR(MATCH(IF($B8="Robusta","Robusta",(IF($B8="","Arabica",$B8))&" - "&(IF($C8="","Commercial",$C8))),Variables!$B$1:$D$1,0),1))*IFERROR(IF(AB8="","",(AVERAGE(E8:F8)-AB8)-Variables!$B$14),"")/365),"")) -> -486.71353 | BH8: =IF($AX8="Cancelled","",IFERROR((W8*INDEX(Variables!$B$7:$D$7,IFERROR(MATCH(IF($B8="Robusta","Robusta",(IF($B8="","Arabica",$B8))&" - "&(IF($C8="","Commercial",$C8))),Variables!$B$1:$D$1,0),1))*AK8/365)+(L8/16.67*INDEX(Variables!$B$8:$D$8,IFERROR(MATCH(IF($B8="Robusta","Robusta",(IF($B8="","Arabica",$B8))&" - "&(IF($C8="","Commercial",$C8))),Variables!$B$1:$D$1,0),1))*AK8)+(W8*INDEX(Variables!$B$9:$D$9,IFERROR(MATCH(IF($B8="Robusta","Robusta",(IF($B8="","Arabica",$B8))&" - "&(IF($C8="","Commercial",$C8))),Variables!$B$1:$D$1,0),1))*AK8/365),"")) -> 608.39191 | BI8: =IF($AX8="Cancelled","",IFERROR((W8*INDEX(Variables!$B$7:$D$7,IFERROR(MATCH(IF($B8="Robusta","Robusta",(IF($B8="","Arabica",$B8))&" - "&(IF($C8="","Commercial",$C8))),Variables!$B$1:$D$1,0),1))*BD8/365)+(L8/16.67*INDEX(Variables!$B$8:$D$8,IFERROR(MATCH(IF($B8="Robusta","Robusta",(IF($B8="","Arabica",$B8))&" - "&(IF($C8="","Commercial",$C8))),Variables!$B$1:$D$1,0),1))*BD8)+(W8*INDEX(Variables!$B$9:$D$9,IFERROR(MATCH(IF($B8="Robusta","Robusta",(IF($B8="","Arabica",$B8))&" - "&(IF($C8="","Commercial",$C8))),Variables!$B$1:$D$1,0),1))*BD8/365),"")) -> 162.23784 | BJ8: =IF($AX8="Cancelled","",IFERROR(IF(AS8="","",F8-AS8),"")) -> 15 | BK8: =IF($AX8="Cancelled","",IFERROR(IF(BJ8="","",(W8*INDEX(Variables!$B$7:$D$7,IFERROR(MATCH(IF($B8="Robusta","Robusta",(IF($B8="","Arabica",$B8))&" - "&(IF($C8="","Commercial",$C8))),Variables!$B$1:$D$1,0),1))*(BJ8/365))+(W8*INDEX(Variables!$B$9:$D$9,IFERROR(MATCH(IF($B8="Robusta","Robusta",(IF($B8="","Arabica",$B8))&" - "&(IF($C8="","Commercial",$C8))),Variables!$B$1:$D$1,0),1))*(BJ8/365))+(INDEX(Variables!$B$8:$D$8,IFERROR(MATCH(IF($B8="Robusta","Robusta",(IF($B8="","Arabica",$B8))&" - "&(IF($C8="","Commercial",$C8))),Variables!$B$1:$D$1,0),1))*L8/16.67)),"")) -> 356.39191
A9: Kenya | B9: Arabica | C9: Commercial | D9: 45531 | E9: 45717 | F9: 45747 | G9: 3786491 | H9: 01-92287 | J9: BR | K9: 5195C | L9: 360 | M9: 1 | N9: JDE Grinders EUDR Aligned | O9: Grinder plus | P9: 10120 | Q9: EUDR | R9: Bulk Bag | S9: Gavle | T9: Sweden | U9: Europe | V9: -26 | W9: =IF($AX9="Cancelled","",IFERROR(((V9+INDEX(Variables!$B$6:$D$6,IFERROR(MATCH(IF($B9="Robusta","Robusta",(IF($B9="","Arabica",$B9))&" - "&(IF($C9="","Commercial",$C9))),Variables!$B$1:$D$1,0),1)))*22.0462)*(L9/16.67),"")) -> 126071.99 | X9: SAS | Y9: =IF($AX9="Cancelled","",IF(X9="","",IFERROR(IF(INDEX(Variables!$B$38:$B$47,MATCH(X9,Variables!$A$38:$A$47,0))="Yes","Yes","No"),"No"))) -> Yes | Z9: 45698 | AB9: 45714 | AC9: =IF($AX9="Cancelled","",IF(ISNUMBER(AB9),"Approved","")) -> Approved | AF9: 45721 | AG9: =IF($AX9="Cancelled","",IFERROR(IF(F9="","",F9-Variables!$B$13),"")) -> 45732 | AH9: =IF($AX9="Cancelled","",IFERROR(IF(AB9="","",(AVERAGE(E9:F9)-AB9)-Variables!$B$14),"")) -> -12 | AJ9: 45721 | AK9: =IF($AX9="Cancelled","",IFERROR(IF(AJ9="","",IF(AND(AB9="",AF9=""),"",IF(AF9>AB9,AF9+Variables!$B$15+Variables!$B$16+Variables!$B$17-AJ9,AB9+Variables!$B$16+Variables!$B$17-AJ9))),"")) -> 15 | AL9: Iceberg | AM9: WEC FCL/FCL | AN9: MSC Nuria | AP9: 45732 | AR9: WECC2588FOS1022 | AS9: 45738 | AU9: 45744 | AV9: Email | AW9: 45751 | AX9: =IF(ISNUMBER(SEARCH("cancel",#REF!)),"Cancelled",IF(AND(AS9<>"",AU9<>"",AW9<>""),"Closed","Open")) -> Closed | AY9: =IF($AX9="Cancelled","",IF(AND(AS9<>"",AU9<>"",AW9<>""),"All dates received",_xlfn.TEXTJOIN(" and ",TRUE(),IF(AS9="","No sailing date",""),IF(AU9="","No shipping advice sent",""),IF(AW9="","No docs dispatch date","")))) -> All dates received | BD9: =IF($AX9="Cancelled","",IFERROR(IF(OR(AS9="",AJ9=""),"",(AJ9+Variables!$B$18-AS9)),"")) -> -2 | BE9: =IF($AX9="Cancelled","",IFERROR(IF(OR(AW9="",AS9=""),"",(AS9+Variables!$B$19)-AW9),"")) -> -8 | BF9: =IF($AX9="Cancelled","",IFERROR(W9*INDEX(Variables!$B$7:$D$7,IFERROR(MATCH(IF($B9="Robusta","Robusta",(IF($B9="","Arabica",$B9))&" - "&(IF($C9="","Commercial",$C9))),Variables!$B$1:$D$1,0),1))*(BE9/365),"")) -> -178.17862 | BG9: =IF($AX9="Cancelled","",IFERROR((W9*INDEX(Variables!$B$7:$D$7,IFERROR(MATCH(IF($B9="Robusta","Robusta",(IF($B9="","Arabica",$B9))&" - "&(IF($C9="","Commercial",$C9))),Variables!$B$1:$D$1,0),1))*IFERROR(IF(AB9="","",(AVERAGE(E9:F9)-AB9)-Variables!$B$14),"")/365)+(L9/16.67*INDEX(Variables!$B$8:$D$8,IFERROR(MATCH(IF($B9="Robusta","Robusta",(IF($B9="","Arabica",$B9))&" - "&(IF($C9="","Commercial",$C9))),Variables!$B$1:$D$1,0),1))*IFERROR(IF(AB9="","",(AVERAGE(E9:F9)-AB9)-Variables!$B$14),""))+(W9*INDEX(Variables!$B$9:$D$9,IFERROR(MATCH(IF($B9="Robusta","Robusta",(IF($B9="","Arabica",$B9))&" - "&(IF($C9="","Commercial",$C9))),Variables!$B$1:$D$1,0),1))*IFERROR(IF(AB9="","",(AVERAGE(E9:F9)-AB9)-Variables!$B$14),"")/365),"")) -> -486.71353 | BH9: =IF($AX9="Cancelled","",IFERROR((W9*INDEX(Variables!$B$7:$D$7,IFERROR(MATCH(IF($B9="Robusta","Robusta",(IF($B9="","Arabica",$B9))&" - "&(IF($C9="","Commercial",$C9))),Variables!$B$1:$D$1,0),1))*AK9/365)+(L9/16.67*INDEX(Variables!$B$8:$D$8,IFERROR(MATCH(IF($B9="Robusta","Robusta",(IF($B9="","Arabica",$B9))&" - "&(IF($C9="","Commercial",$C9))),Variables!$B$1:$D$1,0),1))*AK9)+(W9*INDEX(Variables!$B$9:$D$9,IFERROR(MATCH(IF($B9="Robusta","Robusta",(IF($B9="","Arabica",$B9))&" - "&(IF($C9="","Commercial",$C9))),Variables!$B$1:$D$1,0),1))*AK9/365),"")) -> 608.39191 | BI9: =IF($AX9="Cancelled","",IFERROR((W9*INDEX(Variables!$B$7:$D$7,IFERROR(MATCH(IF($B9="Robusta","Robusta",(IF($B9="","Arabica",$B9))&" - "&(IF($C9="","Commercial",$C9))),Variables!$B$1:$D$1,0),1))*BD9/365)+(L9/16.67*INDEX(Variables!$B$8:$D$8,IFERROR(MATCH(IF($B9="Robusta","Robusta",(IF($B9="","Arabica",$B9))&" - "&(IF($C9="","Commercial",$C9))),Variables!$B$1:$D$1,0),1))*BD9)+(W9*INDEX(Variables!$B$9:$D$9,IFERROR(MATCH(IF($B9="Robusta","Robusta",(IF($B9="","Arabica",$B9))&" - "&(IF($C9="","Commercial",$C9))),Variables!$B$1:$D$1,0),1))*BD9/365),"")) -> -81.118922 | BJ9: =IF($AX9="Cancelled","",IFERROR(IF(AS9="","",F9-AS9),"")) -> 9 | BK9: =IF($AX9="Cancelled","",IFERROR(IF(BJ9="","",(W9*INDEX(Variables!$B$7:$D$7,IFERROR(MATCH(IF($B9="Robusta","Robusta",(IF($B9="","Arabica",$B9))&" - "&(IF($C9="","Commercial",$C9))),Variables!$B$1:$D$1,0),1))*(BJ9/365))+(W9*INDEX(Variables!$B$9:$D$9,IFERROR(MATCH(IF($B9="Robusta","Robusta",(IF($B9="","Arabica",$B9))&" - "&(IF($C9="","Commercial",$C9))),Variables!$B$1:$D$1,0),1))*(BJ9/365))+(INDEX(Variables!$B$8:$D$8,IFERROR(MATCH(IF($B9="Robusta","Robusta",(IF($B9="","Arabica",$B9))&" - "&(IF($C9="","Commercial",$C9))),Variables!$B$1:$D$1,0),1))*L9/16.67)),"")) -> 221.03515
A10: Kenya | B10: Arabica | C10: Commercial | D10: 45531 | E10: 45717 | F10: 45747 | G10: 3786491 | H10: 01-92287 | J10: BR | K10: 5195B | L10: 720 | M10: 2 | N10: JDE Grinders EUDR Aligned | O10: Grinder plus | P10: 10120 | Q10: EUDR | R10: Bulk Bag | S10: Rotterdam | T10: Netherlands | U10: Europe | V10: -26 | W10: =IF($AX10="Cancelled","",IFERROR(((V10+INDEX(Variables!$B$6:$D$6,IFERROR(MATCH(IF($B10="Robusta","Robusta",(IF($B10="","Arabica",$B10))&" - "&(IF($C10="","Commercial",$C10))),Variables!$B$1:$D$1,0),1)))*22.0462)*(L10/16.67),"")) -> 252143.99 | X10: SAS | Y10: =IF($AX10="Cancelled","",IF(X10="","",IFERROR(IF(INDEX(Variables!$B$38:$B$47,MATCH(X10,Variables!$A$38:$A$47,0))="Yes","Yes","No"),"No"))) -> Yes | Z10: 45698 | AB10: 45714 | AC10: =IF($AX10="Cancelled","",IF(ISNUMBER(AB10),"Approved","")) -> Approved | AF10: 45721 | AG10: =IF($AX10="Cancelled","",IFERROR(IF(F10="","",F10-Variables!$B$13),"")) -> 45732 | AH10: =IF($AX10="Cancelled","",IFERROR(IF(AB10="","",(AVERAGE(E10:F10)-AB10)-Variables!$B$14),"")) -> -12 | AJ10: 45723 | AK10: =IF($AX10="Cancelled","",IFERROR(IF(AJ10="","",IF(AND(AB10="",AF10=""),"",IF(AF10>AB10,AF10+Variables!$B$15+Variables!$B$16+Variables!$B$17-AJ10,AB10+Variables!$B$16+Variables!$B$17-AJ10))),"")) -> 13 | AL10: Iceberg | AM10: WEC FCL/FCL | AN10: MSC Nuria | AP10: 45732 | AR10: WECC2588FOS1022 | AS10: 45739 | AU10: 45744 | AV10: Email | AW10: 45751 | AX10: =IF(ISNUMBER(SEARCH("cancel",#REF!)),"Cancelled",IF(AND(AS10<>"",AU10<>"",AW10<>""),"Closed","Open")) -> Closed | AY10: =IF($AX10="Cancelled","",IF(AND(AS10<>"",AU10<>"",AW10<>""),"All dates received",_xlfn.TEXTJOIN(" and ",TRUE(),IF(AS10="","No sailing date",""),IF(AU10="","No shipping advice sent",""),IF(AW10="","No docs dispatch date","")))) -> All dates received | BD10: =IF($AX10="Cancelled","",IFERROR(IF(OR(AS10="",AJ10=""),"",(AJ10+Variables!$B$18-AS10)),"")) -> -1 | BE10: =IF($AX10="Cancelled","",IFERROR(IF(OR(AW10="",AS10=""),"",(AS10+Variables!$B$19)-AW10),"")) -> -7 | BF10: =IF($AX10="Cancelled","",IFERROR(W10*INDEX(Variables!$B$7:$D$7,IFERROR(MATCH(IF($B10="Robusta","Robusta",(IF($B10="","Arabica",$B10))&" - "&(IF($C10="","Commercial",$C10))),Variables!$B$1:$D$1,0),1))*(BE10/365),"")) -> -311.81259 | BG10: =IF($AX10="Cancelled","",IFERROR((W10*INDEX(Variables!$B$7:$D$7,IFERROR(MATCH(IF($B10="Robusta","Robusta",(IF($B10="","Arabica",$B10))&" - "&(IF($C10="","Commercial",$C10))),Variables!$B$1:$D$1,0),1))*IFERROR(IF(AB10="","",(AVERAGE(E10:F10)-AB10)-Variables!$B$14),"")/365)+(L10/16.67*INDEX(Variables!$B$8:$D$8,IFERROR(MATCH(IF($B10="Robusta","Robusta",(IF($B10="","Arabica",$B10))&" - "&(IF($C10="","Commercial",$C10))),Variables!$B$1:$D$1,0),1))*IFERROR(IF(AB10="","",(AVERAGE(E10:F10)-AB10)-Variables!$B$14),""))+(W10*INDEX(Variables!$B$9:$D$9,IFERROR(MATCH(IF($B10="Robusta","Robusta",(IF($B10="","Arabica",$B10))&" - "&(IF($C10="","Commercial",$C10))),Variables!$B$1:$D$1,0),1))*IFERROR(IF(AB10="","",(AVERAGE(E10:F10)-AB10)-Variables!$B$14),"")/365),"")) -> -973.42706 | BH10: =IF($AX10="Cancelled","",IFERROR((W10*INDEX(Variables!$B$7:$D$7,IFERROR(MATCH(IF($B10="Robusta","Robusta",(IF($B10="","Arabica",$B10))&" - "&(IF($C10="","Commercial",$C10))),Variables!$B$1:$D$1,0),1))*AK10/365)+(L10/16.67*INDEX(Variables!$B$8:$D$8,IFERROR(MATCH(IF($B10="Robusta","Robusta",(IF($B10="","Arabica",$B10))&" - "&(IF($C10="","Commercial",$C10))),Variables!$B$1:$D$1,0),1))*AK10)+(W10*INDEX(Variables!$B$9:$D$9,IFERROR(MATCH(IF($B10="Robusta","Robusta",(IF($B10="","Arabica",$B10))&" - "&(IF($C10="","Commercial",$C10))),Variables!$B$1:$D$1,0),1))*AK10/365),"")) -> 1054.546 | BI10: =IF($AX10="Cancelled","",IFERROR((W10*INDEX(Variables!$B$7:$D$7,IFERROR(MATCH(IF($B10="Robusta","Robusta",(IF($B10="","Arabica",$B10))&" - "&(IF($C10="","Commercial",$C10))),Variables!$B$1:$D$1,0),1))*BD10/365)+(L10/16.67*INDEX(Variables!$B$8:$D$8,IFERROR(MATCH(IF($B10="Robusta","Robusta",(IF($B10="","Arabica",$B10))&" - "&(IF($C10="","Commercial",$C10))),Variables!$B$1:$D$1,0),1))*BD10)+(W10*INDEX(Variables!$B$9:$D$9,IFERROR(MATCH(IF($B10="Robusta","Robusta",(IF($B10="","Arabica",$B10))&" - "&(IF($C10="","Commercial",$C10))),Variables!$B$1:$D$1,0),1))*BD10/365),"")) -> -81.118922 | BJ10: =IF($AX10="Cancelled","",IFERROR(IF(AS10="","",F10-AS10),"")) -> 8 | BK10: =IF($AX10="Cancelled","",IFERROR(IF(BJ10="","",(W10*INDEX(Variables!$B$7:$D$7,IFERROR(MATCH(IF($B10="Robusta","Robusta",(IF($B10="","Arabica",$B10))&" - "&(IF($C10="","Commercial",$C10))),Variables!$B$1:$D$1,0),1))*(BJ10/365))+(W10*INDEX(Variables!$B$9:$D$9,IFERROR(MATCH(IF($B10="Robusta","Robusta",(IF($B10="","Arabica",$B10))&" - "&(IF($C10="","Commercial",$C10))),Variables!$B$1:$D$1,0),1))*(BJ10/365))+(INDEX(Variables!$B$8:$D$8,IFERROR(MATCH(IF($B10="Robusta","Robusta",(IF($B10="","Arabica",$B10))&" - "&(IF($C10="","Commercial",$C10))),Variables!$B$1:$D$1,0),1))*L10/16.67)),"")) -> 396.95137
A11: Kenya | B11: Arabica | C11: Commercial | D11: 45531 | E11: 45658 | F11: 45688 | G11: 3786493 | H11: 01-92289 | J11: BR | K11: 5141B | L11: 360 | M11: 1 | N11: JDE SAFI A EUDR ALIGNED | O11: ABC MINUS | P11: 10110 | Q11: EUDR | R11: Bulk Bag | S11: Hamburg | T11: Germany | U11: Europe | V11: 7 | W11: =IF($AX11="Cancelled","",IFERROR(((V11+INDEX(Variables!$B$6:$D$6,IFERROR(MATCH(IF($B11="Robusta","Robusta",(IF($B11="","Arabica",$B11))&" - "&(IF($C11="","Commercial",$C11))),Variables!$B$1:$D$1,0),1)))*22.0462)*(L11/16.67),"")) -> 141783.38 | X11: SAS | Y11: =IF($AX11="Cancelled","",IF(X11="","",IFERROR(IF(INDEX(Variables!$B$38:$B$47,MATCH(X11,Variables!$A$38:$A$47,0))="Yes","Yes","No"),"No"))) -> Yes | Z11: 45616 | AB11: 45630 | AC11: =IF($AX11="Cancelled","",IF(ISNUMBER(AB11),"Approved","")) -> Approved | AF11: 45671 | AG11: =IF($AX11="Cancelled","",IFERROR(IF(F11="","",F11-Variables!$B$13),"")) -> 45673 | AH11: =IF($AX11="Cancelled","",IFERROR(IF(AB11="","",(AVERAGE(E11:F11)-AB11)-Variables!$B$14),"")) -> 13 | AJ11: 45673 | AK11: =IF($AX11="Cancelled","",IFERROR(IF(AJ11="","",IF(AND(AB11="",AF11=""),"",IF(AF11>AB11,AF11+Variables!$B$15+Variables!$B$16+Variables!$B$17-AJ11,AB11+Variables!$B$16+Variables!$B$17-AJ11))),"")) -> 13 | AL11: Iceberg | AM11: CMA-CGM FCL/FCL | AN11: CMA CGM Gulf Express | AP11: 45688 | AR11: MOB0148506 | AS11: 45688 | AU11: 45692 | AV11: Email | AW11: 45695 | AX11: =IF(ISNUMBER(SEARCH("cancel",#REF!)),"Cancelled",IF(AND(AS11<>"",AU11<>"",AW11<>""),"Closed","Open")) -> Closed | AY11: =IF($AX11="Cancelled","",IF(AND(AS11<>"",AU11<>"",AW11<>""),"All dates received",_xlfn.TEXTJOIN(" and ",TRUE(),IF(AS11="","No sailing date",""),IF(AU11="","No shipping advice sent",""),IF(AW11="","No docs dispatch date","")))) -> All dates received | BD11: =IF($AX11="Cancelled","",IFERROR(IF(OR(AS11="",AJ11=""),"",(AJ11+Variables!$B$18-AS11)),"")) -> 0 | BE11: =IF($AX11="Cancelled","",IFERROR(IF(OR(AW11="",AS11=""),"",(AS11+Variables!$B$19)-AW11),"")) -> -2 | BF11: =IF($AX11="Cancelled","",IFERROR(W11*INDEX(Variables!$B$7:$D$7,IFERROR(MATCH(IF($B11="Robusta","Robusta",(IF($B11="","Arabica",$B11))&" - "&(IF($C11="","Commercial",$C11))),Variables!$B$1:$D$1,0),1))*(BE11/365),"")) -> -50.095915 | BG11: =IF($AX11="Cancelled","",IFERROR((W11*INDEX(Variables!$B$7:$D$7,IFERROR(MATCH(IF($B11="Robusta","Robusta",(IF($B11="","Arabica",$B11))&" - "&(IF($C11="","Commercial",$C11))),Variables!$B$1:$D$1,0),1))*IFERROR(IF(AB11="","",(AVERAGE(E11:F11)-AB11)-Variables!$B$14),"")/365)+(L11/16.67*INDEX(Variables!$B$8:$D$8,IFERROR(MATCH(IF($B11="Robusta","Robusta",(IF($B11="","Arabica",$B11))&" - "&(IF($C11="","Commercial",$C11))),Variables!$B$1:$D$1,0),1))*IFERROR(IF(AB11="","",(AVERAGE(E11:F11)-AB11)-Variables!$B$14),""))+(W11*INDEX(Variables!$B$9:$D$9,IFERROR(MATCH(IF($B11="Robusta","Robusta",(IF($B11="","Arabica",$B11))&" - "&(IF($C11="","Commercial",$C11))),Variables!$B$1:$D$1,0),1))*IFERROR(IF(AB11="","",(AVERAGE(E11:F11)-AB11)-Variables!$B$14),"")/365),"")) -> 563.82136 | BH11: =IF($AX11="Cancelled","",IFERROR((W11*INDEX(Variables!$B$7:$D$7,IFERROR(MATCH(IF($B11="Robusta","Robusta",(IF($B11="","Arabica",$B11))&" - "&(IF($C11="","Commercial",$C11))),Variables!$B$1:$D$1,0),1))*AK11/365)+(L11/16.67*INDEX(Variables!$B$8:$D$8,IFERROR(MATCH(IF($B11="Robusta","Robusta",(IF($B11="","Arabica",$B11))&" - "&(IF($C11="","Commercial",$C11))),Variables!$B$1:$D$1,0),1))*AK11)+(W11*INDEX(Variables!$B$9:$D$9,IFERROR(MATCH(IF($B11="Robusta","Robusta",(IF($B11="","Arabica",$B11))&" - "&(IF($C11="","Commercial",$C11))),Variables!$B$1:$D$1,0),1))*AK11/365),"")) -> 563.82136 | BI11: =IF($AX11="Cancelled","",IFERROR((W11*INDEX(Variables!$B$7:$D$7,IFERROR(MATCH(IF($B11="Robusta","Robusta",(IF($B11="","Arabica",$B11))&" - "&(IF($C11="","Commercial",$C11))),Variables!$B$1:$D$1,0),1))*BD11/365)+(L11/16.67*INDEX(Variables!$B$8:$D$8,IFERROR(MATCH(IF($B11="Robusta","Robusta",(IF($B11="","Arabica",$B11))&" - "&(IF($C11="","Commercial",$C11))),Variables!$B$1:$D$1,0),1))*BD11)+(W11*INDEX(Variables!$B$9:$D$9,IFERROR(MATCH(IF($B11="Robusta","Robusta",(IF($B11="","Arabica",$B11))&" - "&(IF($C11="","Commercial",$C11))),Variables!$B$1:$D$1,0),1))*BD11/365),"")) -> 0 | BJ11: =IF($AX11="Cancelled","",IFERROR(IF(AS11="","",F11-AS11),"")) -> 0 | BK11: =IF($AX11="Cancelled","",IFERROR(IF(BJ11="","",(W11*INDEX(Variables!$B$7:$D$7,IFERROR(MATCH(IF($B11="Robusta","Robusta",(IF($B11="","Arabica",$B11))&" - "&(IF($C11="","Commercial",$C11))),Variables!$B$1:$D$1,0),1))*(BJ11/365))+(W11*INDEX(Variables!$B$9:$D$9,IFERROR(MATCH(IF($B11="Robusta","Robusta",(IF($B11="","Arabica",$B11))&" - "&(IF($C11="","Commercial",$C11))),Variables!$B$1:$D$1,0),1))*(BJ11/365))+(INDEX(Variables!$B$8:$D$8,IFERROR(MATCH(IF($B11="Robusta","Robusta",(IF($B11="","Arabica",$B11))&" - "&(IF($C11="","Commercial",$C11))),Variables!$B$1:$D$1,0),1))*L11/16.67)),"")) -> 18
A12: Kenya | B12: Arabica | C12: Commercial | D12: 45531 | E12: 45658 | F12: 45688 | G12: 3786493 | H12: 01-92289 | J12: BR | K12: 5141A | L12: 720 | M12: 2 | N12: JDE SAFI A EUDR ALIGNED | O12: ABC MINUS | P12: 10110 | Q12: EUDR | R12: Bulk Bag | S12: Fos Sur Mer | T12: France | U12: Europe | V12: 7 | W12: =IF($AX12="Cancelled","",IFERROR(((V12+INDEX(Variables!$B$6:$D$6,IFERROR(MATCH(IF($B12="Robusta","Robusta",(IF($B12="","Arabica",$B12))&" - "&(IF($C12="","Commercial",$C12))),Variables!$B$1:$D$1,0),1)))*22.0462)*(L12/16.67),"")) -> 283566.77 | X12: SAS | Y12: =IF($AX12="Cancelled","",IF(X12="","",IFERROR(IF(INDEX(Variables!$B$38:$B$47,MATCH(X12,Variables!$A$38:$A$47,0))="Yes","Yes","No"),"No"))) -> Yes | Z12: 45616 | AB12: 45630 | AC12: =IF($AX12="Cancelled","",IF(ISNUMBER(AB12),"Approved","")) -> Approved | AF12: 45671 | AG12: =IF($AX12="Cancelled","",IFERROR(IF(F12="","",F12-Variables!$B$13),"")) -> 45673 | AH12: =IF($AX12="Cancelled","",IFERROR(IF(AB12="","",(AVERAGE(E12:F12)-AB12)-Variables!$B$14),"")) -> 13 | AJ12: 45671 | AK12: =IF($AX12="Cancelled","",IFERROR(IF(AJ12="","",IF(AND(AB12="",AF12=""),"",IF(AF12>AB12,AF12+Variables!$B$15+Variables!$B$16+Variables!$B$17-AJ12,AB12+Variables!$B$16+Variables!$B$17-AJ12))),"")) -> 15 | AL12: Iceberg | AM12: CMA-CGM FCL/FCL | AN12: CMA CGM Gulf Express | AP12: 45688 | AR12: MOB0148506 | AS12: 45682 | AU12: 45685 | AV12: Email | AW12: 45685 | AX12: =IF(ISNUMBER(SEARCH("cancel",#REF!)),"Cancelled",IF(AND(AS12<>"",AU12<>"",AW12<>""),"Closed","Open")) -> Closed | AY12: =IF($AX12="Cancelled","",IF(AND(AS12<>"",AU12<>"",AW12<>""),"All dates received",_xlfn.TEXTJOIN(" and ",TRUE(),IF(AS12="","No sailing date",""),IF(AU12="","No shipping advice sent",""),IF(AW12="","No docs dispatch date","")))) -> All dates received | BD12: =IF($AX12="Cancelled","",IFERROR(IF(OR(AS12="",AJ12=""),"",(AJ12+Variables!$B$18-AS12)),"")) -> 4 | BE12: =IF($AX12="Cancelled","",IFERROR(IF(OR(AW12="",AS12=""),"",(AS12+Variables!$B$19)-AW12),"")) -> 2 | BF12: =IF($AX12="Cancelled","",IFERROR(W12*INDEX(Variables!$B$7:$D$7,IFERROR(MATCH(IF($B12="Robusta","Robusta",(IF($B12="","Arabica",$B12))&" - "&(IF($C12="","Commercial",$C12))),Variables!$B$1:$D$1,0),1))*(BE12/365),"")) -> 100.19183 | BG12: =IF($AX12="Cancelled","",IFERROR((W12*INDEX(Variables!$B$7:$D$7,IFERROR(MATCH(IF($B12="Robusta","Robusta",(IF($B12="","Arabica",$B12))&" - "&(IF($C12="","Commercial",$C12))),Variables!$B$1:$D$1,0),1))*IFERROR(IF(AB12="","",(AVERAGE(E12:F12)-AB12)-Variables!$B$14),"")/365)+(L12/16.67*INDEX(Variables!$B$8:$D$8,IFERROR(MATCH(IF($B12="Robusta","Robusta",(IF($B12="","Arabica",$B12))&" - "&(IF($C12="","Commercial",$C12))),Variables!$B$1:$D$1,0),1))*IFERROR(IF(AB12="","",(AVERAGE(E12:F12)-AB12)-Variables!$B$14),""))+(W12*INDEX(Variables!$B$9:$D$9,IFERROR(MATCH(IF($B12="Robusta","Robusta",(IF($B12="","Arabica",$B12))&" - "&(IF($C12="","Commercial",$C12))),Variables!$B$1:$D$1,0),1))*IFERROR(IF(AB12="","",(AVERAGE(E12:F12)-AB12)-Variables!$B$14),"")/365),"")) -> 1127.6427 | BH12: =IF($AX12="Cancelled","",IFERROR((W12*INDEX(Variables!$B$7:$D$7,IFERROR(MATCH(IF($B12="Robusta","Robusta",(IF($B12="","Arabica",$B12))&" - "&(IF($C12="","Commercial",$C12))),Variables!$B$1:$D$1,0),1))*AK12/365)+(L12/16.67*INDEX(Variables!$B$8:$D$8,IFERROR(MATCH(IF($B12="Robusta","Robusta",(IF($B12="","Arabica",$B12))&" - "&(IF($C12="","Commercial",$C12))),Variables!$B$1:$D$1,0),1))*AK12)+(W12*INDEX(Variables!$B$9:$D$9,IFERROR(MATCH(IF($B12="Robusta","Robusta",(IF($B12="","Arabica",$B12))&" - "&(IF($C12="","Commercial",$C12))),Variables!$B$1:$D$1,0),1))*AK12/365),"")) -> 1301.1262 | BI12: =IF($AX12="Cancelled","",IFERROR((W12*INDEX(Variables!$B$7:$D$7,IFERROR(MATCH(IF($B12="Robusta","Robusta",(IF($B12="","Arabica",$B12))&" - "&(IF($C12="","Commercial",$C12))),Variables!$B$1:$D$1,0),1))*BD12/365)+(L12/16.67*INDEX(Variables!$B$8:$D$8,IFERROR(MATCH(IF($B12="Robusta","Robusta",(IF($B12="","Arabica",$B12))&" - "&(IF($C12="","Commercial",$C12))),Variables!$B$1:$D$1,0),1))*BD12)+(W12*INDEX(Variables!$B$9:$D$9,IFERROR(MATCH(IF($B12="Robusta","Robusta",(IF($B12="","Arabica",$B12))&" - "&(IF($C12="","Commercial",$C12))),Variables!$B$1:$D$1,0),1))*BD12/365),"")) -> 346.96699 | BJ12: =IF($AX12="Cancelled","",IFERROR(IF(AS12="","",F12-AS12),"")) -> 6 | BK12: =IF($AX12="Cancelled","",IFERROR(IF(BJ12="","",(W12*INDEX(Variables!$B$7:$D$7,IFERROR(MATCH(IF($B12="Robusta","Robusta",(IF($B12="","Arabica",$B12))&" - "&(IF($C12="","Commercial",$C12))),Variables!$B$1:$D$1,0),1))*(BJ12/365))+(W12*INDEX(Variables!$B$9:$D$9,IFERROR(MATCH(IF($B12="Robusta","Robusta",(IF($B12="","Arabica",$B12))&" - "&(IF($C12="","Commercial",$C12))),Variables!$B$1:$D$1,0),1))*(BJ12/365))+(INDEX(Variables!$B$8:$D$8,IFERROR(MATCH(IF($B12="Robusta","Robusta",(IF($B12="","Arabica",$B12))&" - "&(IF($C12="","Commercial",$C12))),Variables!$B$1:$D$1,0),1))*L12/16.67)),"")) -> 340.45049
