Workbook
Name _AOC2: [0]!_AOC2
Name _DAT1: #REF!
Name _DAT10: [1]Sheet1!$I$2:$I$40
Name _DAT11: #REF!
Name _DAT12: #REF!
Name _DAT2: #REF!
Name _DAT3: #REF!
Name _DAT4: #REF!
Name _DAT5: #REF!
Name _DAT6: #REF!
Name _DAT7: #REF!
Name _DAT8: [2]SAP!#REF!
Name _DAT9: [1]Sheet1!$H$2:$H$40
Name _SHR1: #REF!
Name _SHR2: #REF!
Name _tax1: #REF!
Name _tax2: #REF!
Name _tax3: #REF!
Name _tax4: #REF!
Name Beg_Bal: #REF!
Name bhg: #REF!
Name boxes: #REF!
Name button_area_1: #REF!
Name CC: #REF!
Name CCT: #REF!
Name CDB: #REF!
Name celltips_area: #REF!
Name CS: #REF!
Name Data: #REF!
Name DATA1: #REF!
Name DATA10: #REF!
Name DATA11: #REF!
Name DATA12: #REF!
Name DATA13: #REF!
Name DATA14: #REF!
Name DATA15: [3]Sheet3!$O$3:$O$3
Name data16: #REF!
Name data17: #REF!
Name data18: #REF!
Name data19: #REF!
Name DATA2: #REF!
Name data20: #REF!
Name data21: #REF!
Name data22: #REF!
Name data23: #REF!
Name data24: #REF!
Name data25: #REF!
Name data26: #REF!
Name data27: #REF!
Name data28: #REF!
Name data29: #REF!
Name DATA3: #REF!
Name data30: #REF!
Name data31: #REF!
Name data32: #REF!
Name data33: #REF!
Name data34: #REF!
Name data35: #REF!
Name data36: #REF!
Name data37: #REF!

Sheet  General Stock Summary View  
B2: XBS -Total Stocks | G2: IBERO EXPORT WAREHOUSE | J2: IBERO MILL EXPORT | M2: Ibero Export + Mill | P2: AGL | S2: NEW KPCU | V2: MITCHEL COTTS FREIGHT KENYA LIMITED | Y2: MAXA AFRICA LOGISTICS LTD | AB2: KENYA CO-OPERATIVE COFFEE EXPORTERS
B3: Outturn No. | C3: Grade | D3: Total XBS Stocks | E3: Blocked for Processing (BFP) | F3: Sum XBS+BFP | G3: Ibero XBS Stocks (Unt) | H3: Ibero Physical count (Unit) | I3: Ibero Variance (Unit) | J3: Ibero XBS Stocks (Unt) | K3: Ibero Physical count (Unit) | L3: Ibero Variance (Unit) | M3: Ibero XBS Stocks (Unt) | N3: Ibero Physical count (Unit) | O3: Ibero Variance (Unit) | P3: AGL XBS Stocks (Unit) | Q3: AGL Physical count (Unit) | R3: AGL Variance (Unit) | S3: KPCU XBS Stocks (Unit) | T3: KPCU Physical count (Unit) | U3: KPCU Variance (UnIt) | V3: MCF XBS Stocks (Unit) | W3: MCF Physical count (Unit) | X3: MCF Variance (Unit) | Y3: Maxa XBS Stocks (Unit) | Z3: Maxa Physical count (Unit) | AA3: Maxa Variance (Unit) | AB3: KCC XBS Stocks (Unit) | AC3: KCC Physical count (Unit) | AD3: KCC Variance (Unit) | AE3: Total Physical Count | AF3: Total Variance | AG3: Comment
B4: 09SM0019 | C4: AA | D4: =SUMIFS('XBS '!T:T,'XBS '!C:C,' General Stock Summary View '!C4,'XBS '!L:L,' General Stock Summary View '!B4) -> 53.89 | E4: =SUMIFS('Blocked for Processing'!P:P,'Blocked for Processing'!I:I,' General Stock Summary View '!B4,'Blocked for Processing'!C:C,' General Stock Summary View '!C4) -> 0 | F4: =SUM(D4:E4) -> 53.89 | G4: =SUMIFS('XBS '!T:T,'XBS '!H:H,' General Stock Summary View '!$G$2,'XBS '!L:L,' General Stock Summary View '!B4,'XBS '!C:C,' General Stock Summary View '!C4) -> 53.89 | H4: =SUMIFS('PowerApp_Physical count'!H:H,'PowerApp_Physical count'!B:B,' General Stock Summary View '!$G$2,'PowerApp_Physical count'!C:C,' General Stock Summary View '!C4,'PowerApp_Physical count'!A:A,' General Stock Summary View '!B4) -> 53.716667 | I4: =H4-G4 -> -0.17333333 | J4: =SUMIFS('XBS '!T:T,'XBS '!H:H,' General Stock Summary View '!$J$2,'XBS '!L:L,' General Stock Summary View '!B4,'XBS '!C:C,' General Stock Summary View '!C4) -> 0 | K4: =SUMIFS('PowerApp_Physical count'!H:H,'PowerApp_Physical count'!B:B,' General Stock Summary View '!$J$2,'PowerApp_Physical count'!C:C,' General Stock Summary View '!C4,'PowerApp_Physical count'!A:A,' General Stock Summary View '!B4) -> 0 | L4: =K4-J4 -> 0 | M4: =J4+G4+E4 -> 53.89 | N4: =K4+H4 -> 53.716667 | O4: =N4-M4 -> -0.17333333 | P4: =SUMIFS('XBS '!T:T,'XBS '!H:H,' General Stock Summary View '!$P$2,'XBS '!L:L,' General Stock Summary View '!B4,'XBS '!C:C,' General Stock Summary View '!C4) -> 0 | Q4: =SUMIFS('PowerApp_Physical count'!H:H,'PowerApp_Physical count'!B:B,' General Stock Summary View '!$P$2,'PowerApp_Physical count'!C:C,' General Stock Summary View '!C4,'PowerApp_Physical count'!A:A,' General Stock Summary View '!B4) -> 0 | R4: =Q4-P4 -> 0 | S4: =SUMIFS('XBS '!T:T,'XBS '!L:L,' General Stock Summary View '!B4,'XBS '!H:H,' General Stock Summary View '!$S$2,'XBS '!C:C,' General Stock Summary View '!C4) -> 0 | T4: =SUMIFS('PowerApp_Physical count'!H:H,'PowerApp_Physical count'!B:B,' General Stock Summary View '!$S$2,'PowerApp_Physical count'!C:C,' General Stock Summary View '!C4,'PowerApp_Physical count'!A:A,' General Stock Summary View '!B4) -> 0 | U4: =T4-S4 -> 0 | V4: =SUMIFS('XBS '!T:T,'XBS '!H:H,' General Stock Summary View '!$V$2,'XBS '!B:B,' General Stock Summary View '!C4,'XBS '!L:L,' General Stock Summary View '!B4) -> 0 | W4: =SUMIFS('PowerApp_Physical count'!H:H,'PowerApp_Physical count'!B:B,' General Stock Summary View '!$V$2,'PowerApp_Physical count'!C:C,' General Stock Summary View '!C4,'PowerApp_Physical count'!A:A,' General Stock Summary View '!B4) -> 0 | X4: =W4-V4 -> 0 | Y4: =SUMIFS('XBS '!T:T,'XBS '!H:H,' General Stock Summary View '!$Y$2,'XBS '!B:B,' General Stock Summary View '!C4,'XBS '!L:L,' General Stock Summary View '!B4) -> 0 | Z4: =SUMIFS('PowerApp_Physical count'!H:H,'PowerApp_Physical count'!B:B,' General Stock Summary View '!$Y$2,'PowerApp_Physical count'!C:C,' General Stock Summary View '!C4,'PowerApp_Physical count'!A:A,' General Stock Summary View '!B4) -> 0 | AA4: =Z4-Y4 -> 0 | AB4: =SUMIFS('XBS '!T:T,'XBS '!H:H,' General Stock Summary View '!$AB$2,'XBS '!B:B,' General Stock Summary View '!C4,'XBS '!L:L,' General Stock Summary View '!B4) -> 0 | AC4: =SUMIFS('PowerApp_Physical count'!H:H,'PowerApp_Physical count'!B:B,' General Stock Summary View '!$AB$2,'PowerApp_Physical count'!C:C,' General Stock Summary View '!C4,'PowerApp_Physical count'!A:A,' General Stock Summary View '!B4) -> 0 | AD4: =AC4-AB4 -> 0 | AE4: =SUM(H4,Q4,T4,W4,Z4,AC4+K4) -> 53.716667 | AF4: =AE4-F4 -> -0.17333333
B5: 48KN0006 | C5: AA | D5: =SUMIFS('XBS '!T:T,'XBS '!C:C,' General Stock Summary View '!C5,'XBS '!L:L,' General Stock Summary View '!B5) -> 18.665 | E5: =SUMIFS('Blocked for Processing'!P:P,'Blocked for Processing'!I:I,' General Stock Summary View '!B5,'Blocked for Processing'!C:C,' General Stock Summary View '!C5) -> 0 | F5: =SUM(D5:E5) -> 18.665 | G5: =SUMIFS('XBS '!T:T,'XBS '!H:H,' General Stock Summary View '!$G$2,'XBS '!L:L,' General Stock Summary View '!B5,'XBS '!C:C,' General Stock Summary View '!C5) -> 18.665 | H5: =SUMIFS('PowerApp_Physical count'!H:H,'PowerApp_Physical count'!B:B,' General Stock Summary View '!$G$2,'PowerApp_Physical count'!C:C,' General Stock Summary View '!C5,'PowerApp_Physical count'!A:A,' General Stock Summary View '!B5) -> 18.683333 | I5: =H5-G5 -> 0.018333333 | J5: =SUMIFS('XBS '!T:T,'XBS '!H:H,' General Stock Summary View '!$J$2,'XBS '!L:L,' General Stock Summary View '!B5,'XBS '!C:C,' General Stock Summary View '!C5) -> 0 | K5: =SUMIFS('PowerApp_Physical count'!H:H,'PowerApp_Physical count'!B:B,' General Stock Summary View '!$J$2,'PowerApp_Physical count'!C:C,' General Stock Summary View '!C5,'PowerApp_Physical count'!A:A,' General Stock Summary View '!B5) -> 0 | L5: =K5-J5 -> 0 | M5: =J5+G5+E5 -> 18.665 | N5: =K5+H5 -> 18.683333 | O5: =N5-M5 -> 0.018333333 | P5: =SUMIFS('XBS '!T:T,'XBS '!H:H,' General Stock Summary View '!$P$2,'XBS '!L:L,' General Stock Summary View '!B5,'XBS '!C:C,' General Stock Summary View '!C5) -> 0 | Q5: =SUMIFS('PowerApp_Physical count'!H:H,'PowerApp_Physical count'!B:B,' General Stock Summary View '!$P$2,'PowerApp_Physical count'!C:C,' General Stock Summary View '!C5,'PowerApp_Physical count'!A:A,' General Stock Summary View '!B5) -> 0 | R5: =Q5-P5 -> 0 | S5: =SUMIFS('XBS '!T:T,'XBS '!L:L,' General Stock Summary View '!B5,'XBS '!H:H,' General Stock Summary View '!$S$2,'XBS '!C:C,' General Stock Summary View '!C5) -> 0 | T5: =SUMIFS('PowerApp_Physical count'!H:H,'PowerApp_Physical count'!B:B,' General Stock Summary View '!$S$2,'PowerApp_Physical count'!C:C,' General Stock Summary View '!C5,'PowerApp_Physical count'!A:A,' General Stock Summary View '!B5) -> 0 | U5: =T5-S5 -> 0 | V5: =SUMIFS('XBS '!T:T,'XBS '!H:H,' General Stock Summary View '!$V$2,'XBS '!B:B,' General Stock Summary View '!C5,'XBS '!L:L,' General Stock Summary View '!B5) -> 0 | W5: =SUMIFS('PowerApp_Physical count'!H:H,'PowerApp_Physical count'!B:B,' General Stock Summary View '!$V$2,'PowerApp_Physical count'!C:C,' General Stock Summary View '!C5,'PowerApp_Physical count'!A:A,' General Stock Summary View '!B5) -> 0 | X5: =W5-V5 -> 0 | Y5: =SUMIFS('XBS '!T:T,'XBS '!H:H,' General Stock Summary View '!$Y$2,'XBS '!B:B,' General Stock Summary View '!C5,'XBS '!L:L,' General Stock Summary View '!B5) -> 0 | Z5: =SUMIFS('PowerApp_Physical count'!H:H,'PowerApp_Physical count'!B:B,' General Stock Summary View '!$Y$2,'PowerApp_Physical count'!C:C,' General Stock Summary View '!C5,'PowerApp_Physical count'!A:A,' General Stock Summary View '!B5) -> 0 | AA5: =Z5-Y5 -> 0 | AB5: =SUMIFS('XBS '!T:T,'XBS '!H:H,' General Stock Summary View '!$AB$2,'XBS '!B:B,' General Stock Summary View '!C5,'XBS '!L:L,' General Stock Summary View '!B5) -> 0 | AC5: =SUMIFS('PowerApp_Physical count'!H:H,'PowerApp_Physical count'!B:B,' General Stock Summary View '!$AB$2,'PowerApp_Physical count'!C:C,' General Stock Summary View '!C5,'PowerApp_Physical count'!A:A,' General Stock Summary View '!B5) -> 0 | AD5: =AC5-AB5 -> 0 | AE5: =SUM(H5,Q5,T5,W5,Z5,AC5+K5) -> 18.683333 | AF5: =AE5-F5 -> 0.018333333
B6: 48KN0001 | C6: AA | D6: =SUMIFS('XBS '!T:T,'XBS '!C:C,' General Stock Summary View '!C6,'XBS '!L:L,' General Stock Summary View '!B6) -> 12.038333 | E6: =SUMIFS('Blocked for Processing'!P:P,'Blocked for Processing'!I:I,' General Stock Summary View '!B6,'Blocked for Processing'!C:C,' General Stock Summary View '!C6) -> 0 | F6: =SUM(D6:E6) -> 12.038333 | G6: =SUMIFS('XBS '!T:T,'XBS '!H:H,' General Stock Summary View '!$G$2,'XBS '!L:L,' General Stock Summary View '!B6,'XBS '!C:C,' General Stock Summary View '!C6) -> 12.038333 | H6: =SUMIFS('PowerApp_Physical count'!H:H,'PowerApp_Physical count'!B:B,' General Stock Summary View '!$G$2,'PowerApp_Physical count'!C:C,' General Stock Summary View '!C6,'PowerApp_Physical count'!A:A,' General Stock Summary View '!B6) -> 12.116667 | I6: =H6-G6 -> 0.078333333 | J6: =SUMIFS('XBS '!T:T,'XBS '!H:H,' General Stock Summary View '!$J$2,'XBS '!L:L,' General Stock Summary View '!B6,'XBS '!C:C,' General Stock Summary View '!C6) -> 0 | K6: =SUMIFS('PowerApp_Physical count'!H:H,'PowerApp_Physical count'!B:B,' General Stock Summary View '!$J$2,'PowerApp_Physical count'!C:C,' General Stock Summary View '!C6,'PowerApp_Physical count'!A:A,' General Stock Summary View '!B6) -> 0 | L6: =K6-J6 -> 0 | M6: =J6+G6+E6 -> 12.038333 | N6: =K6+H6 -> 12.116667 | O6: =N6-M6 -> 0.078333333 | P6: =SUMIFS('XBS '!T:T,'XBS '!H:H,' General Stock Summary View '!$P$2,'XBS '!L:L,' General Stock Summary View '!B6,'XBS '!C:C,' General Stock Summary View '!C6) -> 0 | Q6: =SUMIFS('PowerApp_Physical count'!H:H,'PowerApp_Physical count'!B:B,' General Stock Summary View '!$P$2,'PowerApp_Physical count'!C:C,' General Stock Summary View '!C6,'PowerApp_Physical count'!A:A,' General Stock Summary View '!B6) -> 0 | R6: =Q6-P6 -> 0 | S6: =SUMIFS('XBS '!T:T,'XBS '!L:L,' General Stock Summary View '!B6,'XBS '!H:H,' General Stock Summary View '!$S$2,'XBS '!C:C,' General Stock Summary View '!C6) -> 0 | T6: =SUMIFS('PowerApp_Physical count'!H:H,'PowerApp_Physical count'!B:B,' General Stock Summary View '!$S$2,'PowerApp_Physical count'!C:C,' General Stock Summary View '!C6,'PowerApp_Physical count'!A:A,' General Stock Summary View '!B6) -> 0 | U6: =T6-S6 -> 0 | V6: =SUMIFS('XBS '!T:T,'XBS '!H:H,' General Stock Summary View '!$V$2,'XBS '!B:B,' General Stock Summary View '!C6,'XBS '!L:L,' General Stock Summary View '!B6) -> 0 | W6: =SUMIFS('PowerApp_Physical count'!H:H,'PowerApp_Physical count'!B:B,' General Stock Summary View '!$V$2,'PowerApp_Physical count'!C:C,' General Stock Summary View '!C6,'PowerApp_Physical count'!A:A,' General Stock Summary View '!B6) -> 0 | X6: =W6-V6 -> 0 | Y6: =SUMIFS('XBS '!T:T,'XBS '!H:H,' General Stock Summary View '!$Y$2,'XBS '!B:B,' General Stock Summary View '!C6,'XBS '!L:L,' General Stock Summary View '!B6) -> 0 | Z6: =SUMIFS('PowerApp_Physical count'!H:H,'PowerApp_Physical count'!B:B,' General Stock Summary View '!$Y$2,'PowerApp_Physical count'!C:C,' General Stock Summary View '!C6,'PowerApp_Physical count'!A:A,' General Stock Summary View '!B6) -> 0 | AA6: =Z6-Y6 -> 0 | AB6: =SUMIFS('XBS '!T:T,'XBS '!H:H,' General Stock Summary View '!$AB$2,'XBS '!B:B,' General Stock Summary View '!C6,'XBS '!L:L,' General Stock Summary View '!B6) -> 0 | AC6: =SUMIFS('PowerApp_Physical count'!H:H,'PowerApp_Physical count'!B:B,' General Stock Summary View '!$AB$2,'PowerApp_Physical count'!C:C,' General Stock Summary View '!C6,'PowerApp_Physical count'!A:A,' General Stock Summary View '!B6) -> 0 | AD6: =AC6-AB6 -> 0 | AE6: =SUM(H6,Q6,T6,W6,Z6,AC6+K6) -> 12.116667 | AF6: =AE6-F6 -> 0.078333333
B7: 48KN0005 | C7: AA | D7: =SUMIFS('XBS '!T:T,'XBS '!C:C,' General Stock Summary View '!C7,'XBS '!L:L,' General Stock Summary View '!B7) -> 13.656667 | E7: =SUMIFS('Blocked for Processing'!P:P,'Blocked for Processing'!I:I,' General Stock Summary View '!B7,'Blocked for Processing'!C:C,' General Stock Summary View '!C7) -> 0 | F7: =SUM(D7:E7) -> 13.656667 | G7: =SUMIFS('XBS '!T:T,'XBS '!H:H,' General Stock Summary View '!$G$2,'XBS '!L:L,' General Stock Summary View '!B7,'XBS '!C:C,' General Stock Summary View '!C7) -> 13.656667 | H7: =SUMIFS('PowerApp_Physical count'!H:H,'PowerApp_Physical count'!B:B,' General Stock Summary View '!$G$2,'PowerApp_Physical count'!C:C,' General Stock Summary View '!C7,'PowerApp_Physical count'!A:A,' General Stock Summary View '!B7) -> 13.716667 | I7: =H7-G7 -> 0.06 | J7: =SUMIFS('XBS '!T:T,'XBS '!H:H,' General Stock Summary View '!$J$2,'XBS '!L:L,' General Stock Summary View '!B7,'XBS '!C:C,' General Stock Summary View '!C7) -> 0 | K7: =SUMIFS('PowerApp_Physical count'!H:H,'PowerApp_Physical count'!B:B,' General Stock Summary View '!$J$2,'PowerApp_Physical count'!C:C,' General Stock Summary View '!C7,'PowerApp_Physical count'!A:A,' General Stock Summary View '!B7) -> 0 | L7: =K7-J7 -> 0 | M7: =J7+G7+E7 -> 13.656667 | N7: =K7+H7 -> 13.716667 | O7: =N7-M7 -> 0.06 | P7: =SUMIFS('XBS '!T:T,'XBS '!H:H,' General Stock Summary View '!$P$2,'XBS '!L:L,' General Stock Summary View '!B7,'XBS '!C:C,' General Stock Summary View '!C7) -> 0 | Q7: =SUMIFS('PowerApp_Physical count'!H:H,'PowerApp_Physical count'!B:B,' General Stock Summary View '!$P$2,'PowerApp_Physical count'!C:C,' General Stock Summary View '!C7,'PowerApp_Physical count'!A:A,' General Stock Summary View '!B7) -> 0 | R7: =Q7-P7 -> 0 | S7: =SUMIFS('XBS '!T:T,'XBS '!L:L,' General Stock Summary View '!B7,'XBS '!H:H,' General Stock Summary View '!$S$2,'XBS '!C:C,' General Stock Summary View '!C7) -> 0 | T7: =SUMIFS('PowerApp_Physical count'!H:H,'PowerApp_Physical count'!B:B,' General Stock Summary View '!$S$2,'PowerApp_Physical count'!C:C,' General Stock Summary View '!C7,'PowerApp_Physical count'!A:A,' General Stock Summary View '!B7) -> 0 | U7: =T7-S7 -> 0 | V7: =SUMIFS('XBS '!T:T,'XBS '!H:H,' General Stock Summary View '!$V$2,'XBS '!B:B,' General Stock Summary View '!C7,'XBS '!L:L,' General Stock Summary View '!B7) -> 0 | W7: =SUMIFS('PowerApp_Physical count'!H:H,'PowerApp_Physical count'!B:B,' General Stock Summary View '!$V$2,'PowerApp_Physical count'!C:C,' General Stock Summary View '!C7,'PowerApp_Physical count'!A:A,' General Stock Summary View '!B7) -> 0 | X7: =W7-V7 -> 0 | Y7: =SUMIFS('XBS '!T:T,'XBS '!H:H,' General Stock Summary View '!$Y$2,'XBS '!B:B,' General Stock Summary View '!C7,'XBS '!L:L,' General Stock Summary View '!B7) -> 0 | Z7: =SUMIFS('PowerApp_Physical count'!H:H,'PowerApp_Physical count'!B:B,' General Stock Summary View '!$Y$2,'PowerApp_Physical count'!C:C,' General Stock Summary View '!C7,'PowerApp_Physical count'!A:A,' General Stock Summary View '!B7) -> 0 | AA7: =Z7-Y7 -> 0 | AB7: =SUMIFS('XBS '!T:T,'XBS '!H:H,' General Stock Summary View '!$AB$2,'XBS '!B:B,' General Stock Summary View '!C7,'XBS '!L:L,' General Stock Summary View '!B7) -> 0 | AC7: =SUMIFS('PowerApp_Physical count'!H:H,'PowerApp_Physical count'!B:B,' General Stock Summary View '!$AB$2,'PowerApp_Physical count'!C:C,' General Stock Summary View '!C7,'PowerApp_Physical count'!A:A,' General Stock Summary View '!B7) -> 0 | AD7: =AC7-AB7 -> 0 | AE7: =SUM(H7,Q7,T7,W7,Z7,AC7+K7) -> 13.716667 | AF7: =AE7-F7 -> 0.06
B8: 16FH0014 | C8: AA | D8: =SUMIFS('XBS '!T:T,'XBS '!C:C,' General Stock Summary View '!C8,'XBS '!L:L,' General Stock Summary View '!B8) -> 1 | E8: =SUMIFS('Blocked for Processing'!P:P,'Blocked for Processing'!I:I,' General Stock Summary View '!B8,'Blocked for Processing'!C:C,' General Stock Summary View '!C8) -> 0 | F8: =SUM(D8:E8) -> 1 | G8: =SUMIFS('XBS '!T:T,'XBS '!H:H,' General Stock Summary View '!$G$2,'XBS '!L:L,' General Stock Summary View '!B8,'XBS '!C:C,' General Stock Summary View '!C8) -> 0 | H8: =SUMIFS('PowerApp_Physical count'!H:H,'PowerApp_Physical count'!B:B,' General Stock Summary View '!$G$2,'PowerApp_Physical count'!C:C,' General Stock Summary View '!C8,'PowerApp_Physical count'!A:A,' General Stock Summary View '!B8) -> 0 | I8: =H8-G8 -> 0 | J8: =SUMIFS('XBS '!T:T,'XBS '!H:H,' General Stock Summary View '!$J$2,'XBS '!L:L,' General Stock Summary View '!B8,'XBS '!C:C,' General Stock Summary View '!C8) -> 0 | K8: =SUMIFS('PowerApp_Physical count'!H:H,'PowerApp_Physical count'!B:B,' General Stock Summary View '!$J$2,'PowerApp_Physical count'!C:C,' General Stock Summary View '!C8,'PowerApp_Physical count'!A:A,' General Stock Summary View '!B8) -> 0 | L8: =K8-J8 -> 0 | M8: =J8+G8+E8 -> 0 | N8: =K8+H8 -> 0 | O8: =N8-M8 -> 0 | P8: =SUMIFS('XBS '!T:T,'XBS '!H:H,' General Stock Summary View '!$P$2,'XBS '!L:L,' General Stock Summary View '!B8,'XBS '!C:C,' General Stock Summary View '!C8) -> 1 | Q8: =SUMIFS('PowerApp_Physical count'!H:H,'PowerApp_Physical count'!B:B,' General Stock Summary View '!$P$2,'PowerApp_Physical count'!C:C,' General Stock Summary View '!C8,'PowerApp_Physical count'!A:A,' General Stock Summary View '!B8) -> 0 | R8: =Q8-P8 -> -1 | S8: =SUMIFS('XBS '!T:T,'XBS '!L:L,' General Stock Summary View '!B8,'XBS '!H:H,' General Stock Summary View '!$S$2,'XBS '!C:C,' General Stock Summary View '!C8) -> 0 | T8: =SUMIFS('PowerApp_Physical count'!H:H,'PowerApp_Physical count'!B:B,' General Stock Summary View '!$S$2,'PowerApp_Physical count'!C:C,' General Stock Summary View '!C8,'PowerApp_Physical count'!A:A,' General Stock Summary View '!B8) -> 0 | U8: =T8-S8 -> 0 | V8: =SUMIFS('XBS '!T:T,'XBS '!H:H,' General Stock Summary View '!$V$2,'XBS '!B:B,' General Stock Summary View '!C8,'XBS '!L:L,' General Stock Summary View '!B8) -> 0 | W8: =SUMIFS('PowerApp_Physical count'!H:H,'PowerApp_Physical count'!B:B,' General Stock Summary View '!$V$2,'PowerApp_Physical count'!C:C,' General Stock Summary View '!C8,'PowerApp_Physical count'!A:A,' General Stock Summary View '!B8) -> 0 | X8: =W8-V8 -> 0 | Y8: =SUMIFS('XBS '!T:T,'XBS '!H:H,' General Stock Summary View '!$Y$2,'XBS '!B:B,' General Stock Summary View '!C8,'XBS '!L:L,' General Stock Summary View '!B8) -> 0 | Z8: =SUMIFS('PowerApp_Physical count'!H:H,'PowerApp_Physical count'!B:B,' General Stock Summary View '!$Y$2,'PowerApp_Physical count'!C:C,' General Stock Summary View '!C8,'PowerApp_Physical count'!A:A,' General Stock Summary View '!B8) -> 0 | AA8: =Z8-Y8 -> 0 | AB8: =SUMIFS('XBS '!T:T,'XBS '!H:H,' General Stock Summary View '!$AB$2,'XBS '!B:B,' General Stock Summary View '!C8,'XBS '!L:L,' General Stock Summary View '!B8) -> 0 | AC8: =SUMIFS('PowerApp_Physical count'!H:H,'PowerApp_Physical count'!B:B,' General Stock Summary View '!$AB$2,'PowerApp_Physical count'!C:C,' General Stock Summary View '!C8,'PowerApp_Physical count'!A:A,' General Stock Summary View '!B8) -> 0 | AD8: =AC8-AB8 -> 0 | AE8: =SUM(H8,Q8,T8,W8,Z8,AC8+K8) -> 0 | AF8: =AE8-F8 -> -1
B9: 49KK0006 | C9: AA | D9: =SUMIFS('XBS '!T:T,'XBS '!C:C,' General Stock Summary View '!C9,'XBS '!L:L,' General Stock Summary View '!B9) -> 3.4333333 | E9: =SUMIFS('Blocked for Processing'!P:P,'Blocked for Processing'!I:I,' General Stock Summary View '!B9,'Blocked for Processing'!C:C,' General Stock Summary View '!C9) -> 0 | F9: =SUM(D9:E9) -> 3.4333333 | G9: =SUMIFS('XBS '!T:T,'XBS '!H:H,' General Stock Summary View '!$G$2,'XBS '!L:L,' General Stock Summary View '!B9,'XBS '!C:C,' General Stock Summary View '!C9) -> 0 | H9: =SUMIFS('PowerApp_Physical count'!H:H,'PowerApp_Physical count'!B:B,' General Stock Summary View '!$G$2,'PowerApp_Physical count'!C:C,' General Stock Summary View '!C9,'PowerApp_Physical count'!A:A,' General Stock Summary View '!B9) -> 0 | I9: =H9-G9 -> 0 | J9: =SUMIFS('XBS '!T:T,'XBS '!H:H,' General Stock Summary View '!$J$2,'XBS '!L:L,' General Stock Summary View '!B9,'XBS '!C:C,' General Stock Summary View '!C9) -> 0 | K9: =SUMIFS('PowerApp_Physical count'!H:H,'PowerApp_Physical count'!B:B,' General Stock Summary View '!$J$2,'PowerApp_Physical count'!C:C,' General Stock Summary View '!C9,'PowerApp_Physical count'!A:A,' General Stock Summary View '!B9) -> 0 | L9: =K9-J9 -> 0 | M9: =J9+G9+E9 -> 0 | N9: =K9+H9 -> 0 | O9: =N9-M9 -> 0 | P9: =SUMIFS('XBS '!T:T,'XBS '!H:H,' General Stock Summary View '!$P$2,'XBS '!L:L,' General Stock Summary View '!B9,'XBS '!C:C,' General Stock Summary View '!C9) -> 3.4333333 | Q9: =SUMIFS('PowerApp_Physical count'!H:H,'PowerApp_Physical count'!B:B,' General Stock Summary View '!$P$2,'PowerApp_Physical count'!C:C,' General Stock Summary View '!C9,'PowerApp_Physical count'!A:A,' General Stock Summary View '!B9) -> 0 | R9: =Q9-P9 -> -3.4333333 | S9: =SUMIFS('XBS '!T:T,'XBS '!L:L,' General Stock Summary View '!B9,'XBS '!H:H,' General Stock Summary View '!$S$2,'XBS '!C:C,' General Stock Summary View '!C9) -> 0 | T9: =SUMIFS('PowerApp_Physical count'!H:H,'PowerApp_Physical count'!B:B,' General Stock Summary View '!$S$2,'PowerApp_Physical count'!C:C,' General Stock Summary View '!C9,'PowerApp_Physical count'!A:A,' General Stock Summary View '!B9) -> 0 | U9: =T9-S9 -> 0 | V9: =SUMIFS('XBS '!T:T,'XBS '!H:H,' General Stock Summary View '!$V$2,'XBS '!B:B,' General Stock Summary View '!C9,'XBS '!L:L,' General Stock Summary View '!B9) -> 0 | W9: =SUMIFS('PowerApp_Physical count'!H:H,'PowerApp_Physical count'!B:B,' General Stock Summary View '!$V$2,'PowerApp_Physical count'!C:C,' General Stock Summary View '!C9,'PowerApp_Physical count'!A:A,' General Stock Summary View '!B9) -> 0 | X9: =W9-V9 -> 0 | Y9: =SUMIFS('XBS '!T:T,'XBS '!H:H,' General Stock Summary View '!$Y$2,'XBS '!B:B,' General Stock Summary View '!C9,'XBS '!L:L,' General Stock Summary View '!B9) -> 0 | Z9: =SUMIFS('PowerApp_Physical count'!H:H,'PowerApp_Physical count'!B:B,' General Stock Summary View '!$Y$2,'PowerApp_Physical count'!C:C,' General Stock Summary View '!C9,'PowerApp_Physical count'!A:A,' General Stock Summary View '!B9) -> 0 | AA9: =Z9-Y9 -> 0 | AB9: =SUMIFS('XBS '!T:T,'XBS '!H:H,' General Stock Summary View '!$AB$2,'XBS '!B:B,' General Stock Summary View '!C9,'XBS '!L:L,' General Stock Summary View '!B9) -> 0 | AC9: =SUMIFS('PowerApp_Physical count'!H:H,'PowerApp_Physical count'!B:B,' General Stock Summary View '!$AB$2,'PowerApp_Physical count'!C:C,' General Stock Summary View '!C9,'PowerApp_Physical count'!A:A,' General Stock Summary View '!B9) -> 0 | AD9: =AC9-AB9 -> 0 | AE9: =SUM(H9,Q9,T9,W9,Z9,AC9+K9) -> 0 | AF9: =AE9-F9 -> -3.4333333
B10: 48KK2015 | C10: AA | D10: =SUMIFS('XBS '!T:T,'XBS '!C:C,' General Stock Summary View '!C10,'XBS '!L:L,' General Stock Summary View '!B10) -> 10.466667 | E10: =SUMIFS('Blocked for Processing'!P:P,'Blocked for Processing'!I:I,' General Stock Summary View '!B10,'Blocked for Processing'!C:C,' General Stock Summary View '!C10) -> 0 | F10: =SUM(D10:E10) -> 10.466667 | G10: =SUMIFS('XBS '!T:T,'XBS '!H:H,' General Stock Summary View '!$G$2,'XBS '!L:L,' General Stock Summary View '!B10,'XBS '!C:C,' General Stock Summary View '!C10) -> 0 | H10: =SUMIFS('PowerApp_Physical count'!H:H,'PowerApp_Physical count'!B:B,' General Stock Summary View '!$G$2,'PowerApp_Physical count'!C:C,' General Stock Summary View '!C10,'PowerApp_Physical count'!A:A,' General Stock Summary View '!B10) -> 0 | I10: =H10-G10 -> 0 | J10: =SUMIFS('XBS '!T:T,'XBS '!H:H,' General Stock Summary View '!$J$2,'XBS '!L:L,' General Stock Summary View '!B10,'XBS '!C:C,' General Stock Summary View '!C10) -> 0 | K10: =SUMIFS('PowerApp_Physical count'!H:H,'PowerApp_Physical count'!B:B,' General Stock Summary View '!$J$2,'PowerApp_Physical count'!C:C,' General Stock Summary View '!C10,'PowerApp_Physical count'!A:A,' General Stock Summary View '!B10) -> 0 | L10: =K10-J10 -> 0 | M10: =J10+G10+E10 -> 0 | N10: =K10+H10 -> 0 | O10: =N10-M10 -> 0 | P10: =SUMIFS('XBS '!T:T,'XBS '!H:H,' General Stock Summary View '!$P$2,'XBS '!L:L,' General Stock Summary View '!B10,'XBS '!C:C,' General Stock Summary View '!C10) -> 10.466667 | Q10: =SUMIFS('PowerApp_Physical count'!H:H,'PowerApp_Physical count'!B:B,' General Stock Summary View '!$P$2,'PowerApp_Physical count'!C:C,' General Stock Summary View '!C10,'PowerApp_Physical count'!A:A,' General Stock Summary View '!B10) -> 0 | R10: =Q10-P10 -> -10.466667 | S10: =SUMIFS('XBS '!T:T,'XBS '!L:L,' General Stock Summary View '!B10,'XBS '!H:H,' General Stock Summary View '!$S$2,'XBS '!C:C,' General Stock Summary View '!C10) -> 0 | T10: =SUMIFS('PowerApp_Physical count'!H:H,'PowerApp_Physical count'!B:B,' General Stock Summary View '!$S$2,'PowerApp_Physical count'!C:C,' General Stock Summary View '!C10,'PowerApp_Physical count'!A:A,' General Stock Summary View '!B10) -> 0 | U10: =T10-S10 -> 0 | V10: =SUMIFS('XBS '!T:T,'XBS '!H:H,' General Stock Summary View '!$V$2,'XBS '!B:B,' General Stock Summary View '!C10,'XBS '!L:L,' General Stock Summary View '!B10) -> 0 | W10: =SUMIFS('PowerApp_Physical count'!H:H,'PowerApp_Physical count'!B:B,' General Stock Summary View '!$V$2,'PowerApp_Physical count'!C:C,' General Stock Summary View '!C10,'PowerApp_Physical count'!A:A,' General Stock Summary View '!B10) -> 0 | X10: =W10-V10 -> 0 | Y10: =SUMIFS('XBS '!T:T,'XBS '!H:H,' General Stock Summary View '!$Y$2,'XBS '!B:B,' General Stock Summary View '!C10,'XBS '!L:L,' General Stock Summary View '!B10) -> 0 | Z10: =SUMIFS('PowerApp_Physical count'!H:H,'PowerApp_Physical count'!B:B,' General Stock Summary View '!$Y$2,'PowerApp_Physical count'!C:C,' General Stock Summary View '!C10,'PowerApp_Physical count'!A:A,' General Stock Summary View '!B10) -> 0 | AA10: =Z10-Y10 -> 0 | AB10: =SUMIFS('XBS '!T:T,'XBS '!H:H,' General Stock Summary View '!$AB$2,'XBS '!B:B,' General Stock Summary View '!C10,'XBS '!L:L,' General Stock Summary View '!B10) -> 0 | AC10: =SUMIFS('PowerApp_Physical count'!H:H,'PowerApp_Physical count'!B:B,' General Stock Summary View '!$AB$2,'PowerApp_Physical count'!C:C,' General Stock Summary View '!C10,'PowerApp_Physical count'!A:A,' General Stock Summary View '!B10) -> 0 | AD10: =AC10-AB10 -> 0 | AE10: =SUM(H10,Q10,T10,W10,Z10,AC10+K10) -> 0 | AF10: =AE10-F10 -> -10.466667
B11: 49KK0041 | C11: AA | D11: =SUMIFS('XBS '!T:T,'XBS '!C:C,' General Stock Summary View '!C11,'XBS '!L:L,' General Stock Summary View '!B11) -> 4.4833333 | E11: =SUMIFS('Blocked for Processing'!P:P,'Blocked for Processing'!I:I,' General Stock Summary View '!B11,'Blocked for Processing'!C:C,' General Stock Summary View '!C11) -> 0 | F11: =SUM(D11:E11) -> 4.4833333 | G11: =SUMIFS('XBS '!T:T,'XBS '!H:H,' General Stock Summary View '!$G$2,'XBS '!L:L,' General Stock Summary View '!B11,'XBS '!C:C,' General Stock Summary View '!C11) -> 0 | H11: =SUMIFS('PowerApp_Physical count'!H:H,'PowerApp_Physical count'!B:B,' General Stock Summary View '!$G$2,'PowerApp_Physical count'!C:C,' General Stock Summary View '!C11,'PowerApp_Physical count'!A:A,' General Stock Summary View '!B11) -> 0 | I11: =H11-G11 -> 0 | J11: =SUMIFS('XBS '!T:T,'XBS '!H:H,' General Stock Summary View '!$J$2,'XBS '!L:L,' General Stock Summary View '!B11,'XBS '!C:C,' General Stock Summary View '!C11) -> 0 | K11: =SUMIFS('PowerApp_Physical count'!H:H,'PowerApp_Physical count'!B:B,' General Stock Summary View '!$J$2,'PowerApp_Physical count'!C:C,' General Stock Summary View '!C11,'PowerApp_Physical count'!A:A,' General Stock Summary View '!B11) -> 0 | L11: =K11-J11 -> 0 | M11: =J11+G11+E11 -> 0 | N11: =K11+H11 -> 0 | O11: =N11-M11 -> 0 | P11: =SUMIFS('XBS '!T:T,'XBS '!H:H,' General Stock Summary View '!$P$2,'XBS '!L:L,' General Stock Summary View '!B11,'XBS '!C:C,' General Stock Summary View '!C11) -> 4.4833333 | Q11: =SUMIFS('PowerApp_Physical count'!H:H,'PowerApp_Physical count'!B:B,' General Stock Summary View '!$P$2,'PowerApp_Physical count'!C:C,' General Stock Summary View '!C11,'PowerApp_Physical count'!A:A,' General Stock Summary View '!B11) -> 0 | R11: =Q11-P11 -> -4.4833333 | S11: =SUMIFS('XBS '!T:T,'XBS '!L:L,' General Stock Summary View '!B11,'XBS '!H:H,' General Stock Summary View '!$S$2,'XBS '!C:C,' General Stock Summary View '!C11) -> 0 | T11: =SUMIFS('PowerApp_Physical count'!H:H,'PowerApp_Physical count'!B:B,' General Stock Summary View '!$S$2,'PowerApp_Physical count'!C:C,' General Stock Summary View '!C11,'PowerApp_Physical count'!A:A,' General Stock Summary View '!B11) -> 0 | U11: =T11-S11 -> 0 | V11: =SUMIFS('XBS '!T:T,'XBS '!H:H,' General Stock Summary View '!$V$2,'XBS '!B:B,' General Stock Summary View '!C11,'XBS '!L:L,' General Stock Summary View '!B11) -> 0 | W11: =SUMIFS('PowerApp_Physical count'!H:H,'PowerApp_Physical count'!B:B,' General Stock Summary View '!$V$2,'PowerApp_Physical count'!C:C,' General Stock Summary View '!C11,'PowerApp_Physical count'!A:A,' General Stock Summary View '!B11) -> 0 | X11: =W11-V11 -> 0 | Y11: =SUMIFS('XBS '!T:T,'XBS '!H:H,' General Stock Summary View '!$Y$2,'XBS '!B:B,' General Stock Summary View '!C11,'XBS '!L:L,' General Stock Summary View '!B11) -> 0 | Z11: =SUMIFS('PowerApp_Physical count'!H:H,'PowerApp_Physical count'!B:B,' General Stock Summary View '!$Y$2,'PowerApp_Physical count'!C:C,' General Stock Summary View '!C11,'PowerApp_Physical count'!A:A,' General Stock Summary View '!B11) -> 0 | AA11: =Z11-Y11 -> 0 | AB11: =SUMIFS('XBS '!T:T,'XBS '!H:H,' General Stock Summary View '!$AB$2,'XBS '!B:B,' General Stock Summary View '!C11,'XBS '!L:L,' General Stock Summary View '!B11) -> 0 | AC11: =SUMIFS('PowerApp_Physical count'!H:H,'PowerApp_Physical count'!B:B,' General Stock Summary View '!$AB$2,'PowerApp_Physical count'!C:C,' General Stock Summary View '!C11,'PowerApp_Physical count'!A:A,' General Stock Summary View '!B11) -> 0 | AD11: =AC11-AB11 -> 0 | AE11: =SUM(H11,Q11,T11,W11,Z11,AC11+K11) -> 0 | AF11: =AE11-F11 -> -4.4833333
B12: 48KK2003 | C12: AA | D12: =SUMIFS('XBS '!T:T,'XBS '!C:C,' General Stock Summary View '!C12,'XBS '!L:L,' General Stock Summary View '!B12) -> 6.6 | E12: =SUMIFS('Blocked for Processing'!P:P,'Blocked for Processing'!I:I,' General Stock Summary View '!B12,'Blocked for Processing'!C:C,' General Stock Summary View '!C12) -> 0 | F12: =SUM(D12:E12) -> 6.6 | G12: =SUMIFS('XBS '!T:T,'XBS '!H:H,' General Stock Summary View '!$G$2,'XBS '!L:L,' General Stock Summary View '!B12,'XBS '!C:C,' General Stock Summary View '!C12) -> 0 | H12: =SUMIFS('PowerApp_Physical count'!H:H,'PowerApp_Physical count'!B:B,' General Stock Summary View '!$G$2,'PowerApp_Physical count'!C:C,' General Stock Summary View '!C12,'PowerApp_Physical count'!A:A,' General Stock Summary View '!B12) -> 0 | I12: =H12-G12 -> 0 | J12: =SUMIFS('XBS '!T:T,'XBS '!H:H,' General Stock Summary View '!$J$2,'XBS '!L:L,' General Stock Summary View '!B12,'XBS '!C:C,' General Stock Summary View '!C12) -> 0 | K12: =SUMIFS('PowerApp_Physical count'!H:H,'PowerApp_Physical count'!B:B,' General Stock Summary View '!$J$2,'PowerApp_Physical count'!C:C,' General Stock Summary View '!C12,'PowerApp_Physical count'!A:A,' General Stock Summary View '!B12) -> 0 | L12: =K12-J12 -> 0 | M12: =J12+G12+E12 -> 0 | N12: =K12+H12 -> 0 | O12: =N12-M12 -> 0 | P12: =SUMIFS('XBS '!T:T,'XBS '!H:H,' General Stock Summary View '!$P$2,'XBS '!L:L,' General Stock Summary View '!B12,'XBS '!C:C,' General Stock Summary View '!C12) -> 6.6 | Q12: =SUMIFS('PowerApp_Physical count'!H:H,'PowerApp_Physical count'!B:B,' General Stock Summary View '!$P$2,'PowerApp_Physical count'!C:C,' General Stock Summary View '!C12,'PowerApp_Physical count'!A:A,' General Stock Summary View '!B12) -> 0 | R12: =Q12-P12 -> -6.6 | S12: =SUMIFS('XBS '!T:T,'XBS '!L:L,' General Stock Summary View '!B12,'XBS '!H:H,' General Stock Summary View '!$S$2,'XBS '!C:C,' General Stock Summary View '!C12) -> 0 | T12: =SUMIFS('PowerApp_Physical count'!H:H,'PowerApp_Physical count'!B:B,' General Stock Summary View '!$S$2,'PowerApp_Physical count'!C:C,' General Stock Summary View '!C12,'PowerApp_Physical count'!A:A,' General Stock Summary View '!B12) -> 0 | U12: =T12-S12 -> 0 | V12: =SUMIFS('XBS '!T:T,'XBS '!H:H,' General Stock Summary View '!$V$2,'XBS '!B:B,' General Stock Summary View '!C12,'XBS '!L:L,' General Stock Summary View '!B12) -> 0 | W12: =SUMIFS('PowerApp_Physical count'!H:H,'PowerApp_Physical count'!B:B,' General Stock Summary View '!$V$2,'PowerApp_Physical count'!C:C,' General Stock Summary View '!C12,'PowerApp_Physical count'!A:A,' General Stock Summary View '!B12) -> 0 | X12: =W12-V12 -> 0 | Y12: =SUMIFS('XBS '!T:T,'XBS '!H:H,' General Stock Summary View '!$Y$2,'XBS '!B:B,' General Stock Summary View '!C12,'XBS '!L:L,' General Stock Summary View '!B12) -> 0 | Z12: =SUMIFS('PowerApp_Physical count'!H:H,'PowerApp_Physical count'!B:B,' General Stock Summary View '!$Y$2,'PowerApp_Physical count'!C:C,' General Stock Summary View '!C12,'PowerApp_Physical count'!A:A,' General Stock Summary View '!B12) -> 0 | AA12: =Z12-Y12 -> 0 | AB12: =SUMIFS('XBS '!T:T,'XBS '!H:H,' General Stock Summary View '!$AB$2,'XBS '!B:B,' General Stock Summary View '!C12,'XBS '!L:L,' General Stock Summary View '!B12) -> 0 | AC12: =SUMIFS('PowerApp_Physical count'!H:H,'PowerApp_Physical count'!B:B,' General Stock Summary View '!$AB$2,'PowerApp_Physical count'!C:C,' General Stock Summary View '!C12,'PowerApp_Physical count'!A:A,' General Stock Summary View '!B12) -> 0 | AD12: =AC12-AB12 -> 0 | AE12: =SUM(H12,Q12,T12,W12,Z12,AC12+K12) -> 0 | AF12: =AE12-F12 -> -6.6
B13: 49KK0020 | C13: AA | D13: =SUMIFS('XBS '!T:T,'XBS '!C:C,' General Stock Summary View '!C13,'XBS '!L:L,' General Stock Summary View '!B13) -> 25.15 | E13: =SUMIFS('Blocked for Processing'!P:P,'Blocked for Processing'!I:I,' General Stock Summary View '!B13,'Blocked for Processing'!C:C,' General Stock Summary View '!C13) -> 0 | F13: =SUM(D13:E13) -> 25.15 | G13: =SUMIFS('XBS '!T:T,'XBS '!H:H,' General Stock Summary View '!$G$2,'XBS '!L:L,' General Stock Summary View '!B13,'XBS '!C:C,' General Stock Summary View '!C13) -> 0 | H13: =SUMIFS('PowerApp_Physical count'!H:H,'PowerApp_Physical count'!B:B,' General Stock Summary View '!$G$2,'PowerApp_Physical count'!C:C,' General Stock Summary View '!C13,'PowerApp_Physical count'!A:A,' General Stock Summary View '!B13) -> 0 | I13: =H13-G13 -> 0 | J13: =SUMIFS('XBS '!T:T,'XBS '!H:H,' General Stock Summary View '!$J$2,'XBS '!L:L,' General Stock Summary View '!B13,'XBS '!C:C,' General Stock Summary View '!C13) -> 0 | K13: =SUMIFS('PowerApp_Physical count'!H:H,'PowerApp_Physical count'!B:B,' General Stock Summary View '!$J$2,'PowerApp_Physical count'!C:C,' General Stock Summary View '!C13,'PowerApp_Physical count'!A:A,' General Stock Summary View '!B13) -> 0 | L13: =K13-J13 -> 0 | M13: =J13+G13+E13 -> 0 | N13: =K13+H13 -> 0 | O13: =N13-M13 -> 0 | P13: =SUMIFS('XBS '!T:T,'XBS '!H:H,' General Stock Summary View '!$P$2,'XBS '!L:L,' General Stock Summary View '!B13,'XBS '!C:C,' General Stock Summary View '!C13) -> 25.15 | Q13: =SUMIFS('PowerApp_Physical count'!H:H,'PowerApp_Physical count'!B:B,' General Stock Summary View '!$P$2,'PowerApp_Physical count'!C:C,' General Stock Summary View '!C13,'PowerApp_Physical count'!A:A,' General Stock Summary View '!B13) -> 0 | R13: =Q13-P13 -> -25.15 | S13: =SUMIFS('XBS '!T:T,'XBS '!L:L,' General Stock Summary View '!B13,'XBS '!H:H,' General Stock Summary View '!$S$2,'XBS '!C:C,' General Stock Summary View '!C13) -> 0 | T13: =SUMIFS('PowerApp_Physical count'!H:H,'PowerApp_Physical count'!B:B,' General Stock Summary View '!$S$2,'PowerApp_Physical count'!C:C,' General Stock Summary View '!C13,'PowerApp_Physical count'!A:A,' General Stock Summary View '!B13) -> 0 | U13: =T13-S13 -> 0 | V13: =SUMIFS('XBS '!T:T,'XBS '!H:H,' General Stock Summary View '!$V$2,'XBS '!B:B,' General Stock Summary View '!C13,'XBS '!L:L,' General Stock Summary View '!B13) -> 0 | W13: =SUMIFS('PowerApp_Physical count'!H:H,'PowerApp_Physical count'!B:B,' General Stock Summary View '!$V$2,'PowerApp_Physical count'!C:C,' General Stock Summary View '!C13,'PowerApp_Physical count'!A:A,' General Stock Summary View '!B13) -> 0 | X13: =W13-V13 -> 0 | Y13: =SUMIFS('XBS '!T:T,'XBS '!H:H,' General Stock Summary View '!$Y$2,'XBS '!B:B,' General Stock Summary View '!C13,'XBS '!L:L,' General Stock Summary View '!B13) -> 0 | Z13: =SUMIFS('PowerApp_Physical count'!H:H,'PowerApp_Physical count'!B:B,' General Stock Summary View '!$Y$2,'PowerApp_Physical count'!C:C,' General Stock Summary View '!C13,'PowerApp_Physical count'!A:A,' General Stock Summary View '!B13) -> 0 | AA13: =Z13-Y13 -> 0 | AB13: =SUMIFS('XBS '!T:T,'XBS '!H:H,' General Stock Summary View '!$AB$2,'XBS '!B:B,' General Stock Summary View '!C13,'XBS '!L:L,' General Stock Summary View '!B13) -> 0 | AC13: =SUMIFS('PowerApp_Physical count'!H:H,'PowerApp_Physical count'!B:B,' General Stock Summary View '!$AB$2,'PowerApp_Physical count'!C:C,' General Stock Summary View '!C13,'PowerApp_Physical count'!A:A,' General Stock Summary View '!B13) -> 0 | AD13: =AC13-AB13 -> 0 | AE13: =SUM(H13,Q13,T13,W13,Z13,AC13+K13) -> 0 | AF13: =AE13-F13 -> -25.15
B14: 49MG0040 | C14: AA | D14: =SUMIFS('XBS '!T:T,'XBS '!C:C,' General Stock Summary View '!C14,'XBS '!L:L,' General Stock Summary View '!B14) -> 21.4 | E14: =SUMIFS('Blocked for Processing'!P:P,'Blocked for Processing'!I:I,' General Stock Summary View '!B14,'Blocked for Processing'!C:C,' General Stock Summary View '!C14) -> 0 | F14: =SUM(D14:E14) -> 21.4 | G14: =SUMIFS('XBS '!T:T,'XBS '!H:H,' General Stock Summary View '!$G$2,'XBS '!L:L,' General Stock Summary View '!B14,'XBS '!C:C,' General Stock Summary View '!C14) -> 0 | H14: =SUMIFS('PowerApp_Physical count'!H:H,'PowerApp_Physical count'!B:B,' General Stock Summary View '!$G$2,'PowerApp_Physical count'!C:C,' General Stock Summary View '!C14,'PowerApp_Physical count'!A:A,' General Stock Summary View '!B14) -> 0 | I14: =H14-G14 -> 0 | J14: =SUMIFS('XBS '!T:T,'XBS '!H:H,' General Stock Summary View '!$J$2,'XBS '!L:L,' General Stock Summary View '!B14,'XBS '!C:C,' General Stock Summary View '!C14) -> 0 | K14: =SUMIFS('PowerApp_Physical count'!H:H,'PowerApp_Physical count'!B:B,' General Stock Summary View '!$J$2,'PowerApp_Physical count'!C:C,' General Stock Summary View '!C14,'PowerApp_Physical count'!A:A,' General Stock Summary View '!B14) -> 0 | L14: =K14-J14 -> 0 | M14: =J14+G14+E14 -> 0 | N14: =K14+H14 -> 0 | O14: =N14-M14 -> 0 | P14: =SUMIFS('XBS '!T:T,'XBS '!H:H,' General Stock Summary View '!$P$2,'XBS '!L:L,' General Stock Summary View '!B14,'XBS '!C:C,' General Stock Summary View '!C14) -> 21.4 | Q14: =SUMIFS('PowerApp_Physical count'!H:H,'PowerApp_Physical count'!B:B,' General Stock Summary View '!$P$2,'PowerApp_Physical count'!C:C,' General Stock Summary View '!C14,'PowerApp_Physical count'!A:A,' General Stock Summary View '!B14) -> 0 | R14: =Q14-P14 -> -21.4 | S14: =SUMIFS('XBS '!T:T,'XBS '!L:L,' General Stock Summary View '!B14,'XBS '!H:H,' General Stock Summary View '!$S$2,'XBS '!C:C,' General Stock Summary View '!C14) -> 0 | T14: =SUMIFS('PowerApp_Physical count'!H:H,'PowerApp_Physical count'!B:B,' General Stock Summary View '!$S$2,'PowerApp_Physical count'!C:C,' General Stock Summary View '!C14,'PowerApp_Physical count'!A:A,' General Stock Summary View '!B14) -> 0 | U14: =T14-S14 -> 0 | V14: =SUMIFS('XBS '!T:T,'XBS '!H:H,' General Stock Summary View '!$V$2,'XBS '!B:B,' General Stock Summary View '!C14,'XBS '!L:L,' General Stock Summary View '!B14) -> 0 | W14: =SUMIFS('PowerApp_Physical count'!H:H,'PowerApp_Physical count'!B:B,' General Stock Summary View '!$V$2,'PowerApp_Physical count'!C:C,' General Stock Summary View '!C14,'PowerApp_Physical count'!A:A,' General Stock Summary View '!B14) -> 0 | X14: =W14-V14 -> 0 | Y14: =SUMIFS('XBS '!T:T,'XBS '!H:H,' General Stock Summary View '!$Y$2,'XBS '!B:B,' General Stock Summary View '!C14,'XBS '!L:L,' General Stock Summary View '!B14) -> 0 | Z14: =SUMIFS('PowerApp_Physical count'!H:H,'PowerApp_Physical count'!B:B,' General Stock Summary View '!$Y$2,'PowerApp_Physical count'!C:C,' General Stock Summary View '!C14,'PowerApp_Physical count'!A:A,' General Stock Summary View '!B14) -> 0 | AA14: =Z14-Y14 -> 0 | AB14: =SUMIFS('XBS '!T:T,'XBS '!H:H,' General Stock Summary View '!$AB$2,'XBS '!B:B,' General Stock Summary View '!C14,'XBS '!L:L,' General Stock Summary View '!B14) -> 0 | AC14: =SUMIFS('PowerApp_Physical count'!H:H,'PowerApp_Physical count'!B:B,' General Stock Summary View '!$AB$2,'PowerApp_Physical count'!C:C,' General Stock Summary View '!C14,'PowerApp_Physical count'!A:A,' General Stock Summary View '!B14) -> 0 | AD14: =AC14-AB14 -> 0 | AE14: =SUM(H14,Q14,T14,W14,Z14,AC14+K14) -> 0 | AF14: =AE14-F14 -> -21.4
B15: 49KN1007 | C15: AA | D15: =SUMIFS('XBS '!T:T,'XBS '!C:C,' General Stock Summary View '!C15,'XBS '!L:L,' General Stock Summary View '!B15) -> 6.4833333 | E15: =SUMIFS('Blocked for Processing'!P:P,'Blocked for Processing'!I:I,' General Stock Summary View '!B15,'Blocked for Processing'!C:C,' General Stock Summary View '!C15) -> 0 | F15: =SUM(D15:E15) -> 6.4833333 | G15: =SUMIFS('XBS '!T:T,'XBS '!H:H,' General Stock Summary View '!$G$2,'XBS '!L:L,' General Stock Summary View '!B15,'XBS '!C:C,' General Stock Summary View '!C15) -> 0 | H15: =SUMIFS('PowerApp_Physical count'!H:H,'PowerApp_Physical count'!B:B,' General Stock Summary View '!$G$2,'PowerApp_Physical count'!C:C,' General Stock Summary View '!C15,'PowerApp_Physical count'!A:A,' General Stock Summary View '!B15) -> 0 | I15: =H15-G15 -> 0 | J15: =SUMIFS('XBS '!T:T,'XBS '!H:H,' General Stock Summary View '!$J$2,'XBS '!L:L,' General Stock Summary View '!B15,'XBS '!C:C,' General Stock Summary View '!C15) -> 0 | K15: =SUMIFS('PowerApp_Physical count'!H:H,'PowerApp_Physical count'!B:B,' General Stock Summary View '!$J$2,'PowerApp_Physical count'!C:C,' General Stock Summary View '!C15,'PowerApp_Physical count'!A:A,' General Stock Summary View '!B15) -> 0 | L15: =K15-J15 -> 0 | M15: =J15+G15+E15 -> 0 | N15: =K15+H15 -> 0 | O15: =N15-M15 -> 0 | P15: =SUMIFS('XBS '!T:T,'XBS '!H:H,' General Stock Summary View '!$P$2,'XBS '!L:L,' General Stock Summary View '!B15,'XBS '!C:C,' General Stock Summary View '!C15) -> 6.4833333 | Q15: =SUMIFS('PowerApp_Physical count'!H:H,'PowerApp_Physical count'!B:B,' General Stock Summary View '!$P$2,'PowerApp_Physical count'!C:C,' General Stock Summary View '!C15,'PowerApp_Physical count'!A:A,' General Stock Summary View '!B15) -> 0 | R15: =Q15-P15 -> -6.4833333 | S15: =SUMIFS('XBS '!T:T,'XBS '!L:L,' General Stock Summary View '!B15,'XBS '!H:H,' General Stock Summary View '!$S$2,'XBS '!C:C,' General Stock Summary View '!C15) -> 0 | T15: =SUMIFS('PowerApp_Physical count'!H:H,'PowerApp_Physical count'!B:B,' General Stock Summary View '!$S$2,'PowerApp_Physical count'!C:C,' General Stock Summary View '!C15,'PowerApp_Physical count'!A:A,' General Stock Summary View '!B15) -> 0 | U15: =T15-S15 -> 0 | V15: =SUMIFS('XBS '!T:T,'XBS '!H:H,' General Stock Summary View '!$V$2,'XBS '!B:B,' General Stock Summary View '!C15,'XBS '!L:L,' General Stock Summary View '!B15) -> 0 | W15: =SUMIFS('PowerApp_Physical count'!H:H,'PowerApp_Physical count'!B:B,' General Stock Summary View '!$V$2,'PowerApp_Physical count'!C:C,' General Stock Summary View '!C15,'PowerApp_Physical count'!A:A,' General Stock Summary View '!B15) -> 0 | X15: =W15-V15 -> 0 | Y15: =SUMIFS('XBS '!T:T,'XBS '!H:H,' General Stock Summary View '!$Y$2,'XBS '!B:B,' General Stock Summary View '!C15,'XBS '!L:L,' General Stock Summary View '!B15) -> 0 | Z15: =SUMIFS('PowerApp_Physical count'!H:H,'PowerApp_Physical count'!B:B,' General Stock Summary View '!$Y$2,'PowerApp_Physical count'!C:C,' General Stock Summary View '!C15,'PowerApp_Physical count'!A:A,' General Stock Summary View '!B15) -> 0 | AA15: =Z15-Y15 -> 0 | AB15: =SUMIFS('XBS '!T:T,'XBS '!H:H,' General Stock Summary View '!$AB$2,'XBS '!B:B,' General Stock Summary View '!C15,'XBS '!L:L,' General Stock Summary View '!B15) -> 0 | AC15: =SUMIFS('PowerApp_Physical count'!H:H,'PowerApp_Physical count'!B:B,' General Stock Summary View '!$AB$2,'PowerApp_Physical count'!C:C,' General Stock Summary View '!C15,'PowerApp_Physical count'!A:A,' General Stock Summary View '!B15) -> 0 | AD15: =AC15-AB15 -> 0 | AE15: =SUM(H15,Q15,T15,W15,Z15,AC15+K15) -> 0 | AF15: =AE15-F15 -> -6.4833333
... B171: 49KK0075 | C171: C | D171: =SUMIFS('XBS '!T:T,'XBS '!C:C,' General Stock Summary View '!C171,'XBS '!L:L,' General Stock Summary View '!B171) -> 13.15 | E171: =SUMIFS('Blocked for Processing'!P:P,'Blocked for Processing'!I:I,' General Stock Summary View '!B171,'Blocked for Processing'!C:C,' General Stock Summary View '!C171) -> 0 | F171: =SUM(D171:E171) -> 13.15 | G171: =SUMIFS('XBS '!T:T,'XBS '!H:H,' General Stock Summary View '!$G$2,'XBS '!L:L,' General Stock Summary View '!B171,'XBS '!C:C,' General Stock Summary View '!C171) -> 0 | H171: =SUMIFS('PowerApp_Physical count'!H:H,'PowerApp_Physical count'!B:B,' General Stock Summary View '!$G$2,'PowerApp_Physical count'!C:C,' General Stock Summary View '!C171,'PowerApp_Physical count'!A:A,' General Stock Summary View '!B171) -> 0 | I171: =H171-G171 -> 0 | J171: =SUMIFS('XBS '!T:T,'XBS '!H:H,' General Stock Summary View '!$J$2,'XBS '!L:L,' General Stock Summary View '!B171,'XBS '!C:C,' General Stock Summary View '!C171) -> 0 | K171: =SUMIFS('PowerApp_Physical count'!H:H,'PowerApp_Physical count'!B:B,' General Stock Summary View '!$J$2,'PowerApp_Physical count'!C:C,' General Stock Summary View '!C171,'PowerApp_Physical count'!A:A,' General Stock Summary View '!B171) -> 0 | L171: =K171-J171 -> 0 | M171: =J171+G171+E171 -> 0 | N171: =K171+H171 -> 0 | O171: =N171-M171 -> 0 | P171: =SUMIFS('XBS '!T:T,'XBS '!H:H,' General Stock Summary View '!$P$2,'XBS '!L:L,' General Stock Summary View '!B171,'XBS '!C:C,' General Stock Summary View '!C171) -> 13.15 | Q171: =SUMIFS('PowerApp_Physical count'!H:H,'PowerApp_Physical count'!B:B,' General Stock Summary View '!$P$2,'PowerApp_Physical count'!C:C,' General Stock Summary View '!C171,'PowerApp_Physical count'!A:A,' General Stock Summary View '!B171) -> 0 | R171: =Q171-P171 -> -13.15 | S171: =SUMIFS('XBS '!T:T,'XBS '!L:L,' General Stock Summary View '!B171,'XBS '!H:H,' General Stock Summary View '!$S$2,'XBS '!C:C,' General Stock Summary View '!C171) -> 0 | T171: =SUMIFS('PowerApp_Physical count'!H:H,'PowerApp_Physical count'!B:B,' General Stock Summary View '!$S$2,'PowerApp_Physical count'!C:C,' General Stock Summary View '!C171,'PowerApp_Physical count'!A:A,' General Stock Summary View '!B171) -> 0 | U171: =T171-S171 -> 0 | V171: =SUMIFS('XBS '!T:T,'XBS '!H:H,' General Stock Summary View '!$V$2,'XBS '!B:B,' General Stock Summary View '!C171,'XBS '!L:L,' General Stock Summary View '!B171) -> 0 | W171: =SUMIFS('PowerApp_Physical count'!H:H,'PowerApp_Physical count'!B:B,' General Stock Summary View '!$V$2,'PowerApp_Physical count'!C:C,' General Stock Summary View '!C171,'PowerApp_Physical count'!A:A,' General Stock Summary View '!B171) -> 0 | X171: =W171-V171 -> 0 | Y171: =SUMIFS('XBS '!T:T,'XBS '!H:H,' General Stock Summary View '!$Y$2,'XBS '!B:B,' General Stock Summary View '!C171,'XBS '!L:L,' General Stock Summary View '!B171) -> 0 | Z171: =SUMIFS('PowerApp_Physical count'!H:H,'PowerApp_Physical count'!B:B,' General Stock Summary View '!$Y$2,'PowerApp_Physical count'!C:C,' General Stock Summary View '!C171,'PowerApp_Physical count'!A:A,' General Stock Summary View '!B171) -> 0 | AA171: =Z171-Y171 -> 0 | AB171: =SUMIFS('XBS '!T:T,'XBS '!H:H,' General Stock Summary View '!$AB$2,'XBS '!B:B,' General Stock Summary View '!C171,'XBS '!L:L,' General Stock Summary View '!B171) -> 0 | AC171: =SUMIFS('PowerApp_Physical count'!H:H,'PowerApp_Physical count'!B:B,' General Stock Summary View '!$AB$2,'PowerApp_Physical count'!C:C,' General Stock Summary View '!C171,'PowerApp_Physical count'!A:A,' General Stock Summary View '!B171) -> 0 | AD171: =AC171-AB171 -> 0 | AE171: =SUM(H171,Q171,T171,W171,Z171,AC171+K171) -> 0 | AF171: =AE171-F171 -> -13.15
B172: 47TK0003 | C172: C | D172: =SUMIFS('XBS '!T:T,'XBS '!C:C,' General Stock Summary View '!C172,'XBS '!L:L,' General Stock Summary View '!B172) -> 1 | E172: =SUMIFS('Blocked for Processing'!P:P,'Blocked for Processing'!I:I,' General Stock Summary View '!B172,'Blocked for Processing'!C:C,' General Stock Summary View '!C172) -> 0 | F172: =SUM(D172:E172) -> 1 | L172: =K172-J172 -> 0 | M172: =J172+G172+E172 -> 0 | N172: =K172+H172 -> 0 | O172: =N172-M172 -> 0 | P172: =SUMIFS('XBS '!T:T,'XBS '!H:H,' General Stock Summary View '!$P$2,'XBS '!L:L,' General Stock Summary View '!B172,'XBS '!C:C,' General Stock Summary View '!C172) -> 1 | Q172: =SUMIFS('PowerApp_Physical count'!H:H,'PowerApp_Physical count'!B:B,' General Stock Summary View '!$P$2,'PowerApp_Physical count'!C:C,' General Stock Summary View '!C172,'PowerApp_Physical count'!A:A,' General Stock Summary View '!B172) -> 0 | R172: =Q172-P172 -> -1 | S172: =SUMIFS('XBS '!T:T,'XBS '!L:L,' General Stock Summary View '!B172,'XBS '!H:H,' General Stock Summary View '!$S$2,'XBS '!C:C,' General Stock Summary View '!C172) -> 0 | T172: =SUMIFS('PowerApp_Physical count'!H:H,'PowerApp_Physical count'!B:B,' General Stock Summary View '!$S$2,'PowerApp_Physical count'!C:C,' General Stock Summary View '!C172,'PowerApp_Physical count'!A:A,' General Stock Summary View '!B172) -> 0 | U172: =T172-S172 -> 0 | V172: =SUMIFS('XBS '!T:T,'XBS '!H:H,' General Stock Summary View '!$V$2,'XBS '!B:B,' General Stock Summary View '!C172,'XBS '!L:L,' General Stock Summary View '!B172) -> 0 | W172: =SUMIFS('PowerApp_Physical count'!H:H,'PowerApp_Physical count'!B:B,' General Stock Summary View '!$V$2,'PowerApp_Physical count'!C:C,' General Stock Summary View '!C172,'PowerApp_Physical count'!A:A,' General Stock Summary View '!B172) -> 0 | X172: =W172-V172 -> 0 | Y172: =SUMIFS('XBS '!T:T,'XBS '!H:H,' General Stock Summary View '!$Y$2,'XBS '!B:B,' General Stock Summary View '!C172,'XBS '!L:L,' General Stock Summary View '!B172) -> 0 | Z172: =SUMIFS('PowerApp_Physical count'!H:H,'PowerApp_Physical count'!B:B,' General Stock Summary View '!$Y$2,'PowerApp_Physical count'!C:C,' General Stock Summary View '!C172,'PowerApp_Physical count'!A:A,' General Stock Summary View '!B172) -> 0 | AA172: =Z172-Y172 -> 0 | AB172: =SUMIFS('XBS '!T:T,'XBS '!H:H,' General Stock Summary View '!$AB$2,'XBS '!B:B,' General Stock Summary View '!C172,'XBS '!L:L,' General Stock Summary View '!B172) -> 0 | AC172: =SUMIFS('PowerApp_Physical count'!H:H,'PowerApp_Physical count'!B:B,' General Stock Summary View '!$AB$2,'PowerApp_Physical count'!C:C,' General Stock Summary View '!C172,'PowerApp_Physical count'!A:A,' General Stock Summary View '!B172) -> 0 | AD172: =AC172-AB172 -> 0 | AE172: =SUM(H172,Q172,T172,W172,Z172,AC172+K172) -> 0 | AF172: =AE172-F172 -> -1
B173: 18IM1013 | C173: C | D173: =SUMIFS('XBS '!T:T,'XBS '!C:C,' General Stock Summary View '!C173,'XBS '!L:L,' General Stock Summary View '!B173) -> 0.2 | E173: =SUMIFS('Blocked for Processing'!P:P,'Blocked for Processing'!I:I,' General Stock Summary View '!B173,'Blocked for Processing'!C:C,' General Stock Summary View '!C173) -> 0 | F173: =SUM(D173:E173) -> 0.2 | L173: =K173-J173 -> 0 | M173: =J173+G173+E173 -> 0 | N173: =K173+H173 -> 0 | O173: =N173-M173 -> 0 | P173: =SUMIFS('XBS '!T:T,'XBS '!H:H,' General Stock Summary View '!$P$2,'XBS '!L:L,' General Stock Summary View '!B173,'XBS '!C:C,' General Stock Summary View '!C173) -> 0.2 | Q173: =SUMIFS('PowerApp_Physical count'!H:H,'PowerApp_Physical count'!B:B,' General Stock Summary View '!$P$2,'PowerApp_Physical count'!C:C,' General Stock Summary View '!C173,'PowerApp_Physical count'!A:A,' General Stock Summary View '!B173) -> 0 | R173: =Q173-P173 -> -0.2 | S173: =SUMIFS('XBS '!T:T,'XBS '!L:L,' General Stock Summary View '!B173,'XBS '!H:H,' General Stock Summary View '!$S$2,'XBS '!C:C,' General Stock Summary View '!C173) -> 0 | T173: =SUMIFS('PowerApp_Physical count'!H:H,'PowerApp_Physical count'!B:B,' General Stock Summary View '!$S$2,'PowerApp_Physical count'!C:C,' General Stock Summary View '!C173,'PowerApp_Physical count'!A:A,' General Stock Summary View '!B173) -> 0 | U173: =T173-S173 -> 0 | V173: =SUMIFS('XBS '!T:T,'XBS '!H:H,' General Stock Summary View '!$V$2,'XBS '!B:B,' General Stock Summary View '!C173,'XBS '!L:L,' General Stock Summary View '!B173) -> 0 | W173: =SUMIFS('PowerApp_Physical count'!H:H,'PowerApp_Physical count'!B:B,' General Stock Summary View '!$V$2,'PowerApp_Physical count'!C:C,' General Stock Summary View '!C173,'PowerApp_Physical count'!A:A,' General Stock Summary View '!B173) -> 0 | X173: =W173-V173 -> 0 | Y173: =SUMIFS('XBS '!T:T,'XBS '!H:H,' General Stock Summary View '!$Y$2,'XBS '!B:B,' General Stock Summary View '!C173,'XBS '!L:L,' General Stock Summary View '!B173) -> 0 | Z173: =SUMIFS('PowerApp_Physical count'!H:H,'PowerApp_Physical count'!B:B,' General Stock Summary View '!$Y$2,'PowerApp_Physical count'!C:C,' General Stock Summary View '!C173,'PowerApp_Physical count'!A:A,' General Stock Summary View '!B173) -> 0 | AA173: =Z173-Y173 -> 0 | AB173: =SUMIFS('XBS '!T:T,'XBS '!H:H,' General Stock Summary View '!$AB$2,'XBS '!B:B,' General Stock Summary View '!C173,'XBS '!L:L,' General Stock Summary View '!B173) -> 0 | AC173: =SUMIFS('PowerApp_Physical count'!H:H,'PowerApp_Physical count'!B:B,' General Stock Summary View '!$AB$2,'PowerApp_Physical count'!C:C,' General Stock Summary View '!C173,'PowerApp_Physical count'!A:A,' General Stock Summary View '!B173) -> 0 | AD173: =AC173-AB173 -> 0 | AE173: =SUM(H173,Q173,T173,W173,Z173,AC173+K173) -> 0 | AF173: =AE173-F173 -> -0.2
B174: 11FH0038 | C174: C | D174: =SUMIFS('XBS '!T:T,'XBS '!C:C,' General Stock Summary View '!C174,'XBS '!L:L,' General Stock Summary View '!B174) -> 0.31666667 | E174: =SUMIFS('Blocked for Processing'!P:P,'Blocked for Processing'!I:I,' General Stock Summary View '!B174,'Blocked for Processing'!C:C,' General Stock Summary View '!C174) -> 0 | F174: =SUM(D174:E174) -> 0.31666667 | L174: =K174-J174 -> 0 | M174: =J174+G174+E174 -> 0 | N174: =K174+H174 -> 0 | O174: =N174-M174 -> 0 | P174: =SUMIFS('XBS '!T:T,'XBS '!H:H,' General Stock Summary View '!$P$2,'XBS '!L:L,' General Stock Summary View '!B174,'XBS '!C:C,' General Stock Summary View '!C174) -> 0.31666667 | Q174: =SUMIFS('PowerApp_Physical count'!H:H,'PowerApp_Physical count'!B:B,' General Stock Summary View '!$P$2,'PowerApp_Physical count'!C:C,' General Stock Summary View '!C174,'PowerApp_Physical count'!A:A,' General Stock Summary View '!B174) -> 0 | R174: =Q174-P174 -> -0.31666667 | S174: =SUMIFS('XBS '!T:T,'XBS '!L:L,' General Stock Summary View '!B174,'XBS '!H:H,' General Stock Summary View '!$S$2,'XBS '!C:C,' General Stock Summary View '!C174) -> 0 | T174: =SUMIFS('PowerApp_Physical count'!H:H,'PowerApp_Physical count'!B:B,' General Stock Summary View '!$S$2,'PowerApp_Physical count'!C:C,' General Stock Summary View '!C174,'PowerApp_Physical count'!A:A,' General Stock Summary View '!B174) -> 0 | U174: =T174-S174 -> 0 | V174: =SUMIFS('XBS '!T:T,'XBS '!H:H,' General Stock Summary View '!$V$2,'XBS '!B:B,' General Stock Summary View '!C174,'XBS '!L:L,' General Stock Summary View '!B174) -> 0 | W174: =SUMIFS('PowerApp_Physical count'!H:H,'PowerApp_Physical count'!B:B,' General Stock Summary View '!$V$2,'PowerApp_Physical count'!C:C,' General Stock Summary View '!C174,'PowerApp_Physical count'!A:A,' General Stock Summary View '!B174) -> 0 | X174: =W174-V174 -> 0 | Y174: =SUMIFS('XBS '!T:T,'XBS '!H:H,' General Stock Summary View '!$Y$2,'XBS '!B:B,' General Stock Summary View '!C174,'XBS '!L:L,' General Stock Summary View '!B174) -> 0 | Z174: =SUMIFS('PowerApp_Physical count'!H:H,'PowerApp_Physical count'!B:B,' General Stock Summary View '!$Y$2,'PowerApp_Physical count'!C:C,' General Stock Summary View '!C174,'PowerApp_Physical count'!A:A,' General Stock Summary View '!B174) -> 0 | AA174: =Z174-Y174 -> 0 | AB174: =SUMIFS('XBS '!T:T,'XBS '!H:H,' General Stock Summary View '!$AB$2,'XBS '!B:B,' General Stock Summary View '!C174,'XBS '!L:L,' General Stock Summary View '!B174) -> 0 | AC174: =SUMIFS('PowerApp_Physical count'!H:H,'PowerApp_Physical count'!B:B,' General Stock Summary View '!$AB$2,'PowerApp_Physical count'!C:C,' General Stock Summary View '!C174,'PowerApp_Physical count'!A:A,' General Stock Summary View '!B174) -> 0 | AD174: =AC174-AB174 -> 0 | AE174: =SUM(H174,Q174,T174,W174,Z174,AC174+K174) -> 0 | AF174: =AE174-F174 -> -0.31666667
