Workbook

Sheet Variables
B1: Arabica - Commercial | C1: Arabica - Micro-Lots | D1: Robusta
A3: Parameter | B3: Arabica (Commercial) | C3: Arabica (Micro-Lots) | D3: Robusta | E3: Unit
A5: Avg value of Coffee | B5: =443*1000/60 -> 7383.3333 | C5: =505*16.67 -> 8418.35 | D5: N/A | E5: USD/MT
A6: Avg NY value | B6: 290.8 | C6: 290.8 | D6: N/A | E6: USD cents/lb
A7: Cost of financing per annum | B7: =(3.08+3.36822)/100 -> 0.0644822 | C7: =(3.08+3.36822)/100 -> 0.0644822 | D7: N/A | E7: % p.a.
A8: Cost of storage (USD/MT/Day) | B8: =0.05*16.67 -> 0.8335 | C8: =0.05*16.67 -> 0.8335 | D8: N/A | E8: USD/MT/day
A9: Cost of Insurance per annum | B9: 0.0008313 | C9: 0.0008313 | D9: N/A | E9: % p.a.
A11: Parameter | B11: Value | E11: Unit
A13: Days before shipment to ship contract | B13: 15 | E13: days
A14: Days before shipment for sample approval | B14: 30 | E14: days
A15: Days to move coffee to warehouse | B15: 7 | E15: days
A16: Days to process coffee | B16: 5 | E16: days
A17: Days to stuff coffee | B17: 3 | E17: days
A18: Days to ship after stuffing | B18: 7 | E18: days
A19: Days to dispatch docs after sailing | B19: 5 | E19: days

Sheet KENYA
A1: Origin Country | B1: Type (Arabica / Robusta) | C1: Subtype (Commercial / Micro-Lots) | D1: Contract Date | E1: Shipment Start Date | F1: Shipment End Date | G1: Sale Contract Ref | H1: Contract Status (Open / Cancelled / Closed) | I1: Reason for Open Contracts Status | J1: Buyer | K1: Parcel No | L1: Bags | M1: Description | N1: Quality Basket / Grade | O1: Certification | P1: Packaging Type | Q1: Differential | R1: Sample Type | S1: Destination | T1: USD Value of Shipment | U1: PSS Date | V1: PSS Status | W1: Sample Approval Date | X1: Sample Approval Status | Y1: Bulk Instruction Date | Z1: Expected Shipment Period | AA1: Trade & QC Days Lost | AB1: Stuffing Date | AC1: Operational Days Lost | AD1: Shipping Line | AE1: Vessel | AF1: ETD | AG1: ETA | AH1: Landing Port | AI1: B/L No | AJ1: Waybill No | AK1: Sailing Date | AL1: Shipping Advice Sent Date | AM1: Docs Dispatch Date | AN1: Shipment Status | AO1: Notes / Description | AP1: Inspection & Release Days Lost | AQ1: Traffic Days Lost | AR1: USD Loss/Gain from Docs | AS1: P&L Impact on Sample Approval | AT1: USD Saved/Lost on Processing | AU1: USD Saved/Lost on Shipping | AV1: Days Late / Early | AW1: Cost | AX1: C&F Agent | AY1: Estimated Flat Price | AZ1: Shipping Instructions Received | BA1: Bulk Ref | BB1: Samples Received from Warehouse | BC1: Payment Received | BD1: Purchase Ref | BE1: Client Ref | BF1: Ibero
A2: Kenya | B2: Arabica | C2: Commercial | D2: 44945 | E2: 45292 | F2: 45322 | G2: 3785573 | H2: =IF(ISNUMBER(SEARCH("cancel",AN2)),"Cancelled",IF(AND(AK2<>"",AL2<>"",AM2<>""),"Closed","Open")) -> Closed | I2: =IF(AND(AK2<>"",AL2<>"",AM2<>""),"All dates received",_xlfn.TEXTJOIN(" and ",TRUE(),IF(AK2="","No sailing date",""),IF(AL2="","No shipping advice sent",""),IF(AM2="","No docs dispatch date",""))) -> All dates received | J2: Thirty Second | K2: 4653 | L2: 320 | M2: AA/AB Highlands, SAS, Packed in 60kg Ecotact bags, CIF Sydney | N2: AA/AB TOP | R2: SAS | S2: Sydney | T2: =IF($H2="Cancelled","",IFERROR(((Q2+INDEX(Variables!$B$6:$D$6,IFERROR(MATCH(IF($B2="Robusta","Robusta",(IF($B2="","Arabica",$B2))&" - "&(IF($C2="","Commercial",$C2))),Variables!$B$1:$D$1,0),1)))*22.0462)*(L2/16.67),"")) -> 123067.26 | U2: 45203 | V2: =IF(ISNUMBER(U2),"Sent","") -> Sent | W2: 45212 | X2: =IF(ISNUMBER(W2),"Approved","") -> Approved | Z2: =IF($H2="Cancelled","",IFERROR(IF(F2="","",F2-Variables!$B$13),"")) -> 45307 | AA2: =IF($H2="Cancelled","",IFERROR(IF(W2="","",(AVERAGE(E2:F2)-W2)-Variables!$B$14),"")) -> 65 | AB2: 45070 | AC2: =IF($H2="Cancelled","",IFERROR(IF(AB2="","",IF(AND(W2="",Y2=""),"",IF(Y2>W2,Y2+Variables!$B$15+Variables!$B$16+Variables!$B$17-AB2,W2+Variables!$B$16+Variables!$B$17-AB2))),"")) -> 150 | AD2: ONE FCL/FCL | AE2: Kota Kamil | AI2: ONEYMBAE00007500 | AJ2: 3090318965 | AK2: 45317 | AL2: 45320 | AM2: 45328 | AN2: Documents dispatched | AP2: =IF($H2="Cancelled","",IFERROR(IF(OR(AK2="",AB2=""),"",(AB2+Variables!$B$18-AK2)),"")) -> -240 | AQ2: =IF($H2="Cancelled","",IFERROR(IF(OR(AM2="",AK2=""),"",(AK2+Variables!$B$19)-AM2),"")) -> -6 | AR2: =IF($H2="Cancelled","",IFERROR(T2*INDEX(Variables!$B$7:$D$7,IFERROR(MATCH(IF($B2="Robusta","Robusta",(IF($B2="","Arabica",$B2))&" - "&(IF($C2="","Commercial",$C2))),Variables!$B$1:$D$1,0),1))*(AQ2/365),"")) -> -130.449 | AS2: =IF($H2="Cancelled","",IFERROR((T2*INDEX(Variables!$B$7:$D$7,IFERROR(MATCH(IF($B2="Robusta","Robusta",(IF($B2="","Arabica",$B2))&" - "&(IF($C2="","Commercial",$C2))),Variables!$B$1:$D$1,0),1))*IFERROR(IF(W2="","",(AVERAGE(E2:F2)-W2)-Variables!$B$14),"")/365)+(L2/16.67*INDEX(Variables!$B$8:$D$8,IFERROR(MATCH(IF($B2="Robusta","Robusta",(IF($B2="","Arabica",$B2))&" - "&(IF($C2="","Commercial",$C2))),Variables!$B$1:$D$1,0),1))*IFERROR(IF(W2="","",(AVERAGE(E2:F2)-W2)-Variables!$B$14),""))+(T2*INDEX(Variables!$B$9:$D$9,IFERROR(MATCH(IF($B2="Robusta","Robusta",(IF($B2="","Arabica",$B2))&" - "&(IF($C2="","Commercial",$C2))),Variables!$B$1:$D$1,0),1))*IFERROR(IF(W2="","",(AVERAGE(E2:F2)-W2)-Variables!$B$14),"")/365),"")) -> 2471.4163 | AT2: =IF($H2="Cancelled","",IFERROR((T2*INDEX(Variables!$B$7:$D$7,IFERROR(MATCH(IF($B2="Robusta","Robusta",(IF($B2="","Arabica",$B2))&" - "&(IF($C2="","Commercial",$C2))),Variables!$B$1:$D$1,0),1))*AC2/365)+(L2/16.67*INDEX(Variables!$B$8:$D$8,IFERROR(MATCH(IF($B2="Robusta","Robusta",(IF($B2="","Arabica",$B2))&" - "&(IF($C2="","Commercial",$C2))),Variables!$B$1:$D$1,0),1))*AC2)+(T2*INDEX(Variables!$B$9:$D$9,IFERROR(MATCH(IF($B2="Robusta","Robusta",(IF($B2="","Arabica",$B2))&" - "&(IF($C2="","Commercial",$C2))),Variables!$B$1:$D$1,0),1))*AC2/365),"")) -> 5703.2685 | AU2: =IF($H2="Cancelled","",IFERROR((T2*INDEX(Variables!$B$7:$D$7,IFERROR(MATCH(IF($B2="Robusta","Robusta",(IF($B2="","Arabica",$B2))&" - "&(IF($C2="","Commercial",$C2))),Variables!$B$1:$D$1,0),1))*AP2/365)+(L2/16.67*INDEX(Variables!$B$8:$D$8,IFERROR(MATCH(IF($B2="Robusta","Robusta",(IF($B2="","Arabica",$B2))&" - "&(IF($C2="","Commercial",$C2))),Variables!$B$1:$D$1,0),1))*AP2)+(T2*INDEX(Variables!$B$9:$D$9,IFERROR(MATCH(IF($B2="Robusta","Robusta",(IF($B2="","Arabica",$B2))&" - "&(IF($C2="","Commercial",$C2))),Variables!$B$1:$D$1,0),1))*AP2/365),"")) -> -9125.2296 | AV2: =IF($H2="Cancelled","",IFERROR(IF(AK2="","",F2-AK2),"")) -> 5 | AW2: =IF($H2="Cancelled","",IFERROR(IF(AV2="","",(T2*INDEX(Variables!$B$7:$D$7,IFERROR(MATCH(IF($B2="Robusta","Robusta",(IF($B2="","Arabica",$B2))&" - "&(IF($C2="","Commercial",$C2))),Variables!$B$1:$D$1,0),1))*(AV2/365))+(T2*INDEX(Variables!$B$9:$D$9,IFERROR(MATCH(IF($B2="Robusta","Robusta",(IF($B2="","Arabica",$B2))&" - "&(IF($C2="","Commercial",$C2))),Variables!$B$1:$D$1,0),1))*(AV2/365))+(INDEX(Variables!$B$8:$D$8,IFERROR(MATCH(IF($B2="Robusta","Robusta",(IF($B2="","Arabica",$B2))&" - "&(IF($C2="","Commercial",$C2))),Variables!$B$1:$D$1,0),1))*L2/16.67)),"")) -> 126.10895
A3: Kenya | B3: Arabica | C3: Commercial | D3: 44945 | E3: 45292 | F3: 45322 | G3: 3785574 | H3: =IF(ISNUMBER(SEARCH("cancel",AN3)),"Cancelled",IF(AND(AK3<>"",AL3<>"",AM3<>""),"Closed","Open")) -> Closed | I3: =IF(AND(AK3<>"",AL3<>"",AM3<>""),"All dates received",_xlfn.TEXTJOIN(" and ",TRUE(),IF(AK3="","No sailing date",""),IF(AL3="","No shipping advice sent",""),IF(AM3="","No docs dispatch date",""))) -> All dates received | J3: Thirty Second | K3: 4654 | L3: 320 | M3: AA/AB Highlands, SAS, Packed in 60kg Ecotact bags, CIF Sydney | N3: AA/AB TOP | R3: SAS | S3: Sydney | T3: =IF($H3="Cancelled","",IFERROR(((Q3+INDEX(Variables!$B$6:$D$6,IFERROR(MATCH(IF($B3="Robusta","Robusta",(IF($B3="","Arabica",$B3))&" - "&(IF($C3="","Commercial",$C3))),Variables!$B$1:$D$1,0),1)))*22.0462)*(L3/16.67),"")) -> 123067.26 | U3: 45281 | V3: =IF(ISNUMBER(U3),"Sent","") -> Sent | W3: 45296 | X3: =IF(ISNUMBER(W3),"Approved","") -> Approved | Z3: =IF($H3="Cancelled","",IFERROR(IF(F3="","",F3-Variables!$B$13),"")) -> 45307 | AA3: =IF($H3="Cancelled","",IFERROR(IF(W3="","",(AVERAGE(E3:F3)-W3)-Variables!$B$14),"")) -> -19 | AB3: 45071 | AC3: =IF($H3="Cancelled","",IFERROR(IF(AB3="","",IF(AND(W3="",Y3=""),"",IF(Y3>W3,Y3+Variables!$B$15+Variables!$B$16+Variables!$B$17-AB3,W3+Variables!$B$16+Variables!$B$17-AB3))),"")) -> 233 | AD3: ONE FCL/FCL | AE3: Kota kamil | AI3: ONEYMBAE00008600 | AJ3: 3090318965 | AK3: 45317 | AL3: 45320 | AM3: 45328 | AN3: Documents dispatched | AP3: =IF($H3="Cancelled","",IFERROR(IF(OR(AK3="",AB3=""),"",(AB3+Variables!$B$18-AK3)),"")) -> -239 | AQ3: =IF($H3="Cancelled","",IFERROR(IF(OR(AM3="",AK3=""),"",(AK3+Variables!$B$19)-AM3),"")) -> -6 | AR3: =IF($H3="Cancelled","",IFERROR(T3*INDEX(Variables!$B$7:$D$7,IFERROR(MATCH(IF($B3="Robusta","Robusta",(IF($B3="","Arabica",$B3))&" - "&(IF($C3="","Commercial",$C3))),Variables!$B$1:$D$1,0),1))*(AQ3/365),"")) -> -130.449 | AS3: =IF($H3="Cancelled","",IFERROR((T3*INDEX(Variables!$B$7:$D$7,IFERROR(MATCH(IF($B3="Robusta","Robusta",(IF($B3="","Arabica",$B3))&" - "&(IF($C3="","Commercial",$C3))),Variables!$B$1:$D$1,0),1))*IFERROR(IF(W3="","",(AVERAGE(E3:F3)-W3)-Variables!$B$14),"")/365)+(L3/16.67*INDEX(Variables!$B$8:$D$8,IFERROR(MATCH(IF($B3="Robusta","Robusta",(IF($B3="","Arabica",$B3))&" - "&(IF($C3="","Commercial",$C3))),Variables!$B$1:$D$1,0),1))*IFERROR(IF(W3="","",(AVERAGE(E3:F3)-W3)-Variables!$B$14),""))+(T3*INDEX(Variables!$B$9:$D$9,IFERROR(MATCH(IF($B3="Robusta","Robusta",(IF($B3="","Arabica",$B3))&" - "&(IF($C3="","Commercial",$C3))),Variables!$B$1:$D$1,0),1))*IFERROR(IF(W3="","",(AVERAGE(E3:F3)-W3)-Variables!$B$14),"")/365),"")) -> -722.41401 | AT3: =IF($H3="Cancelled","",IFERROR((T3*INDEX(Variables!$B$7:$D$7,IFERROR(MATCH(IF($B3="Robusta","Robusta",(IF($B3="","Arabica",$B3))&" - "&(IF($C3="","Commercial",$C3))),Variables!$B$1:$D$1,0),1))*AC3/365)+(L3/16.67*INDEX(Variables!$B$8:$D$8,IFERROR(MATCH(IF($B3="Robusta","Robusta",(IF($B3="","Arabica",$B3))&" - "&(IF($C3="","Commercial",$C3))),Variables!$B$1:$D$1,0),1))*AC3)+(T3*INDEX(Variables!$B$9:$D$9,IFERROR(MATCH(IF($B3="Robusta","Robusta",(IF($B3="","Arabica",$B3))&" - "&(IF($C3="","Commercial",$C3))),Variables!$B$1:$D$1,0),1))*AC3/365),"")) -> 8859.0771 | AU3: =IF($H3="Cancelled","",IFERROR((T3*INDEX(Variables!$B$7:$D$7,IFERROR(MATCH(IF($B3="Robusta","Robusta",(IF($B3="","Arabica",$B3))&" - "&(IF($C3="","Commercial",$C3))),Variables!$B$1:$D$1,0),1))*AP3/365)+(L3/16.67*INDEX(Variables!$B$8:$D$8,IFERROR(MATCH(IF($B3="Robusta","Robusta",(IF($B3="","Arabica",$B3))&" - "&(IF($C3="","Commercial",$C3))),Variables!$B$1:$D$1,0),1))*AP3)+(T3*INDEX(Variables!$B$9:$D$9,IFERROR(MATCH(IF($B3="Robusta","Robusta",(IF($B3="","Arabica",$B3))&" - "&(IF($C3="","Commercial",$C3))),Variables!$B$1:$D$1,0),1))*AP3/365),"")) -> -9087.2078 | AV3: =IF($H3="Cancelled","",IFERROR(IF(AK3="","",F3-AK3),"")) -> 5 | AW3: =IF($H3="Cancelled","",IFERROR(IF(AV3="","",(T3*INDEX(Variables!$B$7:$D$7,IFERROR(MATCH(IF($B3="Robusta","Robusta",(IF($B3="","Arabica",$B3))&" - "&(IF($C3="","Commercial",$C3))),Variables!$B$1:$D$1,0),1))*(AV3/365))+(T3*INDEX(Variables!$B$9:$D$9,IFERROR(MATCH(IF($B3="Robusta","Robusta",(IF($B3="","Arabica",$B3))&" - "&(IF($C3="","Commercial",$C3))),Variables!$B$1:$D$1,0),1))*(AV3/365))+(INDEX(Variables!$B$8:$D$8,IFERROR(MATCH(IF($B3="Robusta","Robusta",(IF($B3="","Arabica",$B3))&" - "&(IF($C3="","Commercial",$C3))),Variables!$B$1:$D$1,0),1))*L3/16.67)),"")) -> 126.10895
A4: Kenya | B4: Arabica | C4: Commercial | D4: 44945 | E4: 45323 | F4: 45351 | G4: 3785575 | H4: =IF(ISNUMBER(SEARCH("cancel",AN4)),"Cancelled",IF(AND(AK4<>"",AL4<>"",AM4<>""),"Closed","Open")) -> Closed | I4: =IF(AND(AK4<>"",AL4<>"",AM4<>""),"All dates received",_xlfn.TEXTJOIN(" and ",TRUE(),IF(AK4="","No sailing date",""),IF(AL4="","No shipping advice sent",""),IF(AM4="","No docs dispatch date",""))) -> All dates received | J4: Thirty Second | K4: 4655 | L4: 320 | M4: AA/AB Highlands, SAS, Packed in 60kg Ecotact bags, CIF Sydney | N4: AA/AB TOP | R4: SAS | S4: Sydney | T4: =IF($H4="Cancelled","",IFERROR(((Q4+INDEX(Variables!$B$6:$D$6,IFERROR(MATCH(IF($B4="Robusta","Robusta",(IF($B4="","Arabica",$B4))&" - "&(IF($C4="","Commercial",$C4))),Variables!$B$1:$D$1,0),1)))*22.0462)*(L4/16.67),"")) -> 123067.26 | U4: 45281 | V4: =IF(ISNUMBER(U4),"Sent","") -> Sent | W4: 45303 | X4: =IF(ISNUMBER(W4),"Approved","") -> Approved | Z4: =IF($H4="Cancelled","",IFERROR(IF(F4="","",F4-Variables!$B$13),"")) -> 45336 | AA4: =IF($H4="Cancelled","",IFERROR(IF(W4="","",(AVERAGE(E4:F4)-W4)-Variables!$B$14),"")) -> 4 | AB4: 45072 | AC4: =IF($H4="Cancelled","",IFERROR(IF(AB4="","",IF(AND(W4="",Y4=""),"",IF(Y4>W4,Y4+Variables!$B$15+Variables!$B$16+Variables!$B$17-AB4,W4+Variables!$B$16+Variables!$B$17-AB4))),"")) -> 239 | AD4: ONE FCL/FCL | AE4: Kota Karim | AI4: ONEYMBAE00099900 | AJ4: 1802448513 | AK4: 45331 | AL4: 45334 | AM4: 45342 | AN4: Documents dispatched | AP4: =IF($H4="Cancelled","",IFERROR(IF(OR(AK4="",AB4=""),"",(AB4+Variables!$B$18-AK4)),"")) -> -252 | AQ4: =IF($H4="Cancelled","",IFERROR(IF(OR(AM4="",AK4=""),"",(AK4+Variables!$B$19)-AM4),"")) -> -6 | AR4: =IF($H4="Cancelled","",IFERROR(T4*INDEX(Variables!$B$7:$D$7,IFERROR(MATCH(IF($B4="Robusta","Robusta",(IF($B4="","Arabica",$B4))&" - "&(IF($C4="","Commercial",$C4))),Variables!$B$1:$D$1,0),1))*(AQ4/365),"")) -> -130.449 | AS4: =IF($H4="Cancelled","",IFERROR((T4*INDEX(Variables!$B$7:$D$7,IFERROR(MATCH(IF($B4="Robusta","Robusta",(IF($B4="","Arabica",$B4))&" - "&(IF($C4="","Commercial",$C4))),Variables!$B$1:$D$1,0),1))*IFERROR(IF(W4="","",(AVERAGE(E4:F4)-W4)-Variables!$B$14),"")/365)+(L4/16.67*INDEX(Variables!$B$8:$D$8,IFERROR(MATCH(IF($B4="Robusta","Robusta",(IF($B4="","Arabica",$B4))&" - "&(IF($C4="","Commercial",$C4))),Variables!$B$1:$D$1,0),1))*IFERROR(IF(W4="","",(AVERAGE(E4:F4)-W4)-Variables!$B$14),""))+(T4*INDEX(Variables!$B$9:$D$9,IFERROR(MATCH(IF($B4="Robusta","Robusta",(IF($B4="","Arabica",$B4))&" - "&(IF($C4="","Commercial",$C4))),Variables!$B$1:$D$1,0),1))*IFERROR(IF(W4="","",(AVERAGE(E4:F4)-W4)-Variables!$B$14),"")/365),"")) -> 152.08716 | AT4: =IF($H4="Cancelled","",IFERROR((T4*INDEX(Variables!$B$7:$D$7,IFERROR(MATCH(IF($B4="Robusta","Robusta",(IF($B4="","Arabica",$B4))&" - "&(IF($C4="","Commercial",$C4))),Variables!$B$1:$D$1,0),1))*AC4/365)+(L4/16.67*INDEX(Variables!$B$8:$D$8,IFERROR(MATCH(IF($B4="Robusta","Robusta",(IF($B4="","Arabica",$B4))&" - "&(IF($C4="","Commercial",$C4))),Variables!$B$1:$D$1,0),1))*AC4)+(T4*INDEX(Variables!$B$9:$D$9,IFERROR(MATCH(IF($B4="Robusta","Robusta",(IF($B4="","Arabica",$B4))&" - "&(IF($C4="","Commercial",$C4))),Variables!$B$1:$D$1,0),1))*AC4/365),"")) -> 9087.2078 | AU4: =IF($H4="Cancelled","",IFERROR((T4*INDEX(Variables!$B$7:$D$7,IFERROR(MATCH(IF($B4="Robusta","Robusta",(IF($B4="","Arabica",$B4))&" - "&(IF($C4="","Commercial",$C4))),Variables!$B$1:$D$1,0),1))*AP4/365)+(L4/16.67*INDEX(Variables!$B$8:$D$8,IFERROR(MATCH(IF($B4="Robusta","Robusta",(IF($B4="","Arabica",$B4))&" - "&(IF($C4="","Commercial",$C4))),Variables!$B$1:$D$1,0),1))*AP4)+(T4*INDEX(Variables!$B$9:$D$9,IFERROR(MATCH(IF($B4="Robusta","Robusta",(IF($B4="","Arabica",$B4))&" - "&(IF($C4="","Commercial",$C4))),Variables!$B$1:$D$1,0),1))*AP4/365),"")) -> -9581.4911 | AV4: =IF($H4="Cancelled","",IFERROR(IF(AK4="","",F4-AK4),"")) -> 20 | AW4: =IF($H4="Cancelled","",IFERROR(IF(AV4="","",(T4*INDEX(Variables!$B$7:$D$7,IFERROR(MATCH(IF($B4="Robusta","Robusta",(IF($B4="","Arabica",$B4))&" - "&(IF($C4="","Commercial",$C4))),Variables!$B$1:$D$1,0),1))*(AV4/365))+(T4*INDEX(Variables!$B$9:$D$9,IFERROR(MATCH(IF($B4="Robusta","Robusta",(IF($B4="","Arabica",$B4))&" - "&(IF($C4="","Commercial",$C4))),Variables!$B$1:$D$1,0),1))*(AV4/365))+(INDEX(Variables!$B$8:$D$8,IFERROR(MATCH(IF($B4="Robusta","Robusta",(IF($B4="","Arabica",$B4))&" - "&(IF($C4="","Commercial",$C4))),Variables!$B$1:$D$1,0),1))*L4/16.67)),"")) -> 456.4358
A5: Kenya | B5: Arabica | C5: Commercial | D5: 44945 | E5: 45352 | F5: 45382 | G5: 3785576 | H5: =IF(ISNUMBER(SEARCH("cancel",AN5)),"Cancelled",IF(AND(AK5<>"",AL5<>"",AM5<>""),"Closed","Open")) -> Closed | I5: =IF(AND(AK5<>"",AL5<>"",AM5<>""),"All dates received",_xlfn.TEXTJOIN(" and ",TRUE(),IF(AK5="","No sailing date",""),IF(AL5="","No shipping advice sent",""),IF(AM5="","No docs dispatch date",""))) -> All dates received | J5: Thirty Second | K5: 4656 | L5: 320 | M5: AA/AB Highlands, SAS, Packed in 60kg Ecotact bags, CIF Sydney | N5: AA/AB TOP | R5: SAS | S5: Sydney | T5: =IF($H5="Cancelled","",IFERROR(((Q5+INDEX(Variables!$B$6:$D$6,IFERROR(MATCH(IF($B5="Robusta","Robusta",(IF($B5="","Arabica",$B5))&" - "&(IF($C5="","Commercial",$C5))),Variables!$B$1:$D$1,0),1)))*22.0462)*(L5/16.67),"")) -> 123067.26 | U5: 45281 | V5: =IF(ISNUMBER(U5),"Sent","") -> Sent | W5: 45303 | X5: =IF(ISNUMBER(W5),"Approved","") -> Approved | Z5: =IF($H5="Cancelled","",IFERROR(IF(F5="","",F5-Variables!$B$13),"")) -> 45367 | AA5: =IF($H5="Cancelled","",IFERROR(IF(W5="","",(AVERAGE(E5:F5)-W5)-Variables!$B$14),"")) -> 34 | AB5: 45072 | AC5: =IF($H5="Cancelled","",IFERROR(IF(AB5="","",IF(AND(W5="",Y5=""),"",IF(Y5>W5,Y5+Variables!$B$15+Variables!$B$16+Variables!$B$17-AB5,W5+Variables!$B$16+Variables!$B$17-AB5))),"")) -> 239 | AD5: ONE FCL/FCL | AE5: Kota Lagu | AI5: ONEYMBAE00272900 | AJ5: 8945906211 | AK5: 45357 | AL5: 45357 | AM5: 45366 | AN5: Documents dispatched | AP5: =IF($H5="Cancelled","",IFERROR(IF(OR(AK5="",AB5=""),"",(AB5+Variables!$B$18-AK5)),"")) -> -278 | AQ5: =IF($H5="Cancelled","",IFERROR(IF(OR(AM5="",AK5=""),"",(AK5+Variables!$B$19)-AM5),"")) -> -4 | AR5: =IF($H5="Cancelled","",IFERROR(T5*INDEX(Variables!$B$7:$D$7,IFERROR(MATCH(IF($B5="Robusta","Robusta",(IF($B5="","Arabica",$B5))&" - "&(IF($C5="","Commercial",$C5))),Variables!$B$1:$D$1,0),1))*(AQ5/365),"")) -> -86.966 | AS5: =IF($H5="Cancelled","",IFERROR((T5*INDEX(Variables!$B$7:$D$7,IFERROR(MATCH(IF($B5="Robusta","Robusta",(IF($B5="","Arabica",$B5))&" - "&(IF($C5="","Commercial",$C5))),Variables!$B$1:$D$1,0),1))*IFERROR(IF(W5="","",(AVERAGE(E5:F5)-W5)-Variables!$B$14),"")/365)+(L5/16.67*INDEX(Variables!$B$8:$D$8,IFERROR(MATCH(IF($B5="Robusta","Robusta",(IF($B5="","Arabica",$B5))&" - "&(IF($C5="","Commercial",$C5))),Variables!$B$1:$D$1,0),1))*IFERROR(IF(W5="","",(AVERAGE(E5:F5)-W5)-Variables!$B$14),""))+(T5*INDEX(Variables!$B$9:$D$9,IFERROR(MATCH(IF($B5="Robusta","Robusta",(IF($B5="","Arabica",$B5))&" - "&(IF($C5="","Commercial",$C5))),Variables!$B$1:$D$1,0),1))*IFERROR(IF(W5="","",(AVERAGE(E5:F5)-W5)-Variables!$B$14),"")/365),"")) -> 1292.7409 | AT5: =IF($H5="Cancelled","",IFERROR((T5*INDEX(Variables!$B$7:$D$7,IFERROR(MATCH(IF($B5="Robusta","Robusta",(IF($B5="","Arabica",$B5))&" - "&(IF($C5="","Commercial",$C5))),Variables!$B$1:$D$1,0),1))*AC5/365)+(L5/16.67*INDEX(Variables!$B$8:$D$8,IFERROR(MATCH(IF($B5="Robusta","Robusta",(IF($B5="","Arabica",$B5))&" - "&(IF($C5="","Commercial",$C5))),Variables!$B$1:$D$1,0),1))*AC5)+(T5*INDEX(Variables!$B$9:$D$9,IFERROR(MATCH(IF($B5="Robusta","Robusta",(IF($B5="","Arabica",$B5))&" - "&(IF($C5="","Commercial",$C5))),Variables!$B$1:$D$1,0),1))*AC5/365),"")) -> 9087.2078 | AU5: =IF($H5="Cancelled","",IFERROR((T5*INDEX(Variables!$B$7:$D$7,IFERROR(MATCH(IF($B5="Robusta","Robusta",(IF($B5="","Arabica",$B5))&" - "&(IF($C5="","Commercial",$C5))),Variables!$B$1:$D$1,0),1))*AP5/365)+(L5/16.67*INDEX(Variables!$B$8:$D$8,IFERROR(MATCH(IF($B5="Robusta","Robusta",(IF($B5="","Arabica",$B5))&" - "&(IF($C5="","Commercial",$C5))),Variables!$B$1:$D$1,0),1))*AP5)+(T5*INDEX(Variables!$B$9:$D$9,IFERROR(MATCH(IF($B5="Robusta","Robusta",(IF($B5="","Arabica",$B5))&" - "&(IF($C5="","Commercial",$C5))),Variables!$B$1:$D$1,0),1))*AP5/365),"")) -> -10570.058 | AV5: =IF($H5="Cancelled","",IFERROR(IF(AK5="","",F5-AK5),"")) -> 25 | AW5: =IF($H5="Cancelled","",IFERROR(IF(AV5="","",(T5*INDEX(Variables!$B$7:$D$7,IFERROR(MATCH(IF($B5="Robusta","Robusta",(IF($B5="","Arabica",$B5))&" - "&(IF($C5="","Commercial",$C5))),Variables!$B$1:$D$1,0),1))*(AV5/365))+(T5*INDEX(Variables!$B$9:$D$9,IFERROR(MATCH(IF($B5="Robusta","Robusta",(IF($B5="","Arabica",$B5))&" - "&(IF($C5="","Commercial",$C5))),Variables!$B$1:$D$1,0),1))*(AV5/365))+(INDEX(Variables!$B$8:$D$8,IFERROR(MATCH(IF($B5="Robusta","Robusta",(IF($B5="","Arabica",$B5))&" - "&(IF($C5="","Commercial",$C5))),Variables!$B$1:$D$1,0),1))*L5/16.67)),"")) -> 566.54475
A6: Kenya | B6: Arabica | C6: Commercial | D6: 45069 | E6: 45292 | F6: 45322 | G6: 3785999 | H6: =IF(ISNUMBER(SEARCH("cancel",AN6)),"Cancelled",IF(AND(AK6<>"",AL6<>"",AM6<>""),"Closed","Open")) -> Closed | I6: =IF(AND(AK6<>"",AL6<>"",AM6<>""),"All dates received",_xlfn.TEXTJOIN(" and ",TRUE(),IF(AK6="","No sailing date",""),IF(AL6="","No shipping advice sent",""),IF(AM6="","No docs dispatch date",""))) -> All dates received | J6: BR | K6: 4703A | L6: 360 | M6: AB RA Certified | N6: ABC Certified | R6: SAS | S6: Hamburg | T6: =IF($H6="Cancelled","",IFERROR(((Q6+INDEX(Variables!$B$6:$D$6,IFERROR(MATCH(IF($B6="Robusta","Robusta",(IF($B6="","Arabica",$B6))&" - "&(IF($C6="","Commercial",$C6))),Variables!$B$1:$D$1,0),1)))*22.0462)*(L6/16.67),"")) -> 138450.67 | U6: 45281 | V6: =IF(ISNUMBER(U6),"Sent","") -> Sent | W6: 45287 | X6: =IF(ISNUMBER(W6),"Approved","") -> Approved | Z6: =IF($H6="Cancelled","",IFERROR(IF(F6="","",F6-Variables!$B$13),"")) -> 45307 | AA6: =IF($H6="Cancelled","",IFERROR(IF(W6="","",(AVERAGE(E6:F6)-W6)-Variables!$B$14),"")) -> -10 | AB6: 45331 | AC6: =IF($H6="Cancelled","",IFERROR(IF(AB6="","",IF(AND(W6="",Y6=""),"",IF(Y6>W6,Y6+Variables!$B$15+Variables!$B$16+Variables!$B$17-AB6,W6+Variables!$B$16+Variables!$B$17-AB6))),"")) -> -36 | AD6: MSC FCL/FCL | AE6: MSC Martina | AI6: MEDUM2614326 | AJ6: 3421511435 | AK6: 45331 | AL6: 45334 | AM6: 45336 | AN6: Documents dispatched | AP6: =IF($H6="Cancelled","",IFERROR(IF(OR(AK6="",AB6=""),"",(AB6+Variables!$B$18-AK6)),"")) -> 7 | AQ6: =IF($H6="Cancelled","",IFERROR(IF(OR(AM6="",AK6=""),"",(AK6+Variables!$B$19)-AM6),"")) -> 0 | AR6: =IF($H6="Cancelled","",IFERROR(T6*INDEX(Variables!$B$7:$D$7,IFERROR(MATCH(IF($B6="Robusta","Robusta",(IF($B6="","Arabica",$B6))&" - "&(IF($C6="","Commercial",$C6))),Variables!$B$1:$D$1,0),1))*(AQ6/365),"")) -> 0 | AS6: =IF($H6="Cancelled","",IFERROR((T6*INDEX(Variables!$B$7:$D$7,IFERROR(MATCH(IF($B6="Robusta","Robusta",(IF($B6="","Arabica",$B6))&" - "&(IF($C6="","Commercial",$C6))),Variables!$B$1:$D$1,0),1))*IFERROR(IF(W6="","",(AVERAGE(E6:F6)-W6)-Variables!$B$14),"")/365)+(L6/16.67*INDEX(Variables!$B$8:$D$8,IFERROR(MATCH(IF($B6="Robusta","Robusta",(IF($B6="","Arabica",$B6))&" - "&(IF($C6="","Commercial",$C6))),Variables!$B$1:$D$1,0),1))*IFERROR(IF(W6="","",(AVERAGE(E6:F6)-W6)-Variables!$B$14),""))+(T6*INDEX(Variables!$B$9:$D$9,IFERROR(MATCH(IF($B6="Robusta","Robusta",(IF($B6="","Arabica",$B6))&" - "&(IF($C6="","Commercial",$C6))),Variables!$B$1:$D$1,0),1))*IFERROR(IF(W6="","",(AVERAGE(E6:F6)-W6)-Variables!$B$14),"")/365),"")) -> -427.74514 | AT6: =IF($H6="Cancelled","",IFERROR((T6*INDEX(Variables!$B$7:$D$7,IFERROR(MATCH(IF($B6="Robusta","Robusta",(IF($B6="","Arabica",$B6))&" - "&(IF($C6="","Commercial",$C6))),Variables!$B$1:$D$1,0),1))*AC6/365)+(L6/16.67*INDEX(Variables!$B$8:$D$8,IFERROR(MATCH(IF($B6="Robusta","Robusta",(IF($B6="","Arabica",$B6))&" - "&(IF($C6="","Commercial",$C6))),Variables!$B$1:$D$1,0),1))*AC6)+(T6*INDEX(Variables!$B$9:$D$9,IFERROR(MATCH(IF($B6="Robusta","Robusta",(IF($B6="","Arabica",$B6))&" - "&(IF($C6="","Commercial",$C6))),Variables!$B$1:$D$1,0),1))*AC6/365),"")) -> -1539.8825 | AU6: =IF($H6="Cancelled","",IFERROR((T6*INDEX(Variables!$B$7:$D$7,IFERROR(MATCH(IF($B6="Robusta","Robusta",(IF($B6="","Arabica",$B6))&" - "&(IF($C6="","Commercial",$C6))),Variables!$B$1:$D$1,0),1))*AP6/365)+(L6/16.67*INDEX(Variables!$B$8:$D$8,IFERROR(MATCH(IF($B6="Robusta","Robusta",(IF($B6="","Arabica",$B6))&" - "&(IF($C6="","Commercial",$C6))),Variables!$B$1:$D$1,0),1))*AP6)+(T6*INDEX(Variables!$B$9:$D$9,IFERROR(MATCH(IF($B6="Robusta","Robusta",(IF($B6="","Arabica",$B6))&" - "&(IF($C6="","Commercial",$C6))),Variables!$B$1:$D$1,0),1))*AP6/365),"")) -> 299.4216 | AV6: =IF($H6="Cancelled","",IFERROR(IF(AK6="","",F6-AK6),"")) -> -9 | AW6: =IF($H6="Cancelled","",IFERROR(IF(AV6="","",(T6*INDEX(Variables!$B$7:$D$7,IFERROR(MATCH(IF($B6="Robusta","Robusta",(IF($B6="","Arabica",$B6))&" - "&(IF($C6="","Commercial",$C6))),Variables!$B$1:$D$1,0),1))*(AV6/365))+(T6*INDEX(Variables!$B$9:$D$9,IFERROR(MATCH(IF($B6="Robusta","Robusta",(IF($B6="","Arabica",$B6))&" - "&(IF($C6="","Commercial",$C6))),Variables!$B$1:$D$1,0),1))*(AV6/365))+(INDEX(Variables!$B$8:$D$8,IFERROR(MATCH(IF($B6="Robusta","Robusta",(IF($B6="","Arabica",$B6))&" - "&(IF($C6="","Commercial",$C6))),Variables!$B$1:$D$1,0),1))*L6/16.67)),"")) -> -204.97062
A7: Kenya | B7: Arabica | C7: Commercial | D7: 45069 | E7: 45292 | F7: 45322 | G7: 3785999 | H7: =IF(ISNUMBER(SEARCH("cancel",AN7)),"Cancelled",IF(AND(AK7<>"",AL7<>"",AM7<>""),"Closed","Open")) -> Closed | I7: =IF(AND(AK7<>"",AL7<>"",AM7<>""),"All dates received",_xlfn.TEXTJOIN(" and ",TRUE(),IF(AK7="","No sailing date",""),IF(AL7="","No shipping advice sent",""),IF(AM7="","No docs dispatch date",""))) -> All dates received | J7: BR | K7: 4703B | L7: 360 | M7: AB RA Certified | N7: ABC Certified | R7: SAS | S7: Hamburg | T7: =IF($H7="Cancelled","",IFERROR(((Q7+INDEX(Variables!$B$6:$D$6,IFERROR(MATCH(IF($B7="Robusta","Robusta",(IF($B7="","Arabica",$B7))&" - "&(IF($C7="","Commercial",$C7))),Variables!$B$1:$D$1,0),1)))*22.0462)*(L7/16.67),"")) -> 138450.67 | U7: 45281 | V7: =IF(ISNUMBER(U7),"Sent","") -> Sent | W7: 45287 | X7: =IF(ISNUMBER(W7),"Approved","") -> Approved | Z7: =IF($H7="Cancelled","",IFERROR(IF(F7="","",F7-Variables!$B$13),"")) -> 45307 | AA7: =IF($H7="Cancelled","",IFERROR(IF(W7="","",(AVERAGE(E7:F7)-W7)-Variables!$B$14),"")) -> -10 | AB7: 45336 | AC7: =IF($H7="Cancelled","",IFERROR(IF(AB7="","",IF(AND(W7="",Y7=""),"",IF(Y7>W7,Y7+Variables!$B$15+Variables!$B$16+Variables!$B$17-AB7,W7+Variables!$B$16+Variables!$B$17-AB7))),"")) -> -41 | AD7: MSC FCL/FCL | AE7: MSC Martina | AI7: MEDUM2614334 | AJ7: 3421511435 | AK7: 45331 | AL7: 45334 | AM7: 45336 | AN7: Documents dispatched | AP7: =IF($H7="Cancelled","",IFERROR(IF(OR(AK7="",AB7=""),"",(AB7+Variables!$B$18-AK7)),"")) -> 12 | AQ7: =IF($H7="Cancelled","",IFERROR(IF(OR(AM7="",AK7=""),"",(AK7+Variables!$B$19)-AM7),"")) -> 0 | AR7: =IF($H7="Cancelled","",IFERROR(T7*INDEX(Variables!$B$7:$D$7,IFERROR(MATCH(IF($B7="Robusta","Robusta",(IF($B7="","Arabica",$B7))&" - "&(IF($C7="","Commercial",$C7))),Variables!$B$1:$D$1,0),1))*(AQ7/365),"")) -> 0 | AS7: =IF($H7="Cancelled","",IFERROR((T7*INDEX(Variables!$B$7:$D$7,IFERROR(MATCH(IF($B7="Robusta","Robusta",(IF($B7="","Arabica",$B7))&" - "&(IF($C7="","Commercial",$C7))),Variables!$B$1:$D$1,0),1))*IFERROR(IF(W7="","",(AVERAGE(E7:F7)-W7)-Variables!$B$14),"")/365)+(L7/16.67*INDEX(Variables!$B$8:$D$8,IFERROR(MATCH(IF($B7="Robusta","Robusta",(IF($B7="","Arabica",$B7))&" - "&(IF($C7="","Commercial",$C7))),Variables!$B$1:$D$1,0),1))*IFERROR(IF(W7="","",(AVERAGE(E7:F7)-W7)-Variables!$B$14),""))+(T7*INDEX(Variables!$B$9:$D$9,IFERROR(MATCH(IF($B7="Robusta","Robusta",(IF($B7="","Arabica",$B7))&" - "&(IF($C7="","Commercial",$C7))),Variables!$B$1:$D$1,0),1))*IFERROR(IF(W7="","",(AVERAGE(E7:F7)-W7)-Variables!$B$14),"")/365),"")) -> -427.74514 | AT7: =IF($H7="Cancelled","",IFERROR((T7*INDEX(Variables!$B$7:$D$7,IFERROR(MATCH(IF($B7="Robusta","Robusta",(IF($B7="","Arabica",$B7))&" - "&(IF($C7="","Commercial",$C7))),Variables!$B$1:$D$1,0),1))*AC7/365)+(L7/16.67*INDEX(Variables!$B$8:$D$8,IFERROR(MATCH(IF($B7="Robusta","Robusta",(IF($B7="","Arabica",$B7))&" - "&(IF($C7="","Commercial",$C7))),Variables!$B$1:$D$1,0),1))*AC7)+(T7*INDEX(Variables!$B$9:$D$9,IFERROR(MATCH(IF($B7="Robusta","Robusta",(IF($B7="","Arabica",$B7))&" - "&(IF($C7="","Commercial",$C7))),Variables!$B$1:$D$1,0),1))*AC7/365),"")) -> -1753.7551 | AU7: =IF($H7="Cancelled","",IFERROR((T7*INDEX(Variables!$B$7:$D$7,IFERROR(MATCH(IF($B7="Robusta","Robusta",(IF($B7="","Arabica",$B7))&" - "&(IF($C7="","Commercial",$C7))),Variables!$B$1:$D$1,0),1))*AP7/365)+(L7/16.67*INDEX(Variables!$B$8:$D$8,IFERROR(MATCH(IF($B7="Robusta","Robusta",(IF($B7="","Arabica",$B7))&" - "&(IF($C7="","Commercial",$C7))),Variables!$B$1:$D$1,0),1))*AP7)+(T7*INDEX(Variables!$B$9:$D$9,IFERROR(MATCH(IF($B7="Robusta","Robusta",(IF($B7="","Arabica",$B7))&" - "&(IF($C7="","Commercial",$C7))),Variables!$B$1:$D$1,0),1))*AP7/365),"")) -> 513.29416 | AV7: =IF($H7="Cancelled","",IFERROR(IF(AK7="","",F7-AK7),"")) -> -9 | AW7: =IF($H7="Cancelled","",IFERROR(IF(AV7="","",(T7*INDEX(Variables!$B$7:$D$7,IFERROR(MATCH(IF($B7="Robusta","Robusta",(IF($B7="","Arabica",$B7))&" - "&(IF($C7="","Commercial",$C7))),Variables!$B$1:$D$1,0),1))*(AV7/365))+(T7*INDEX(Variables!$B$9:$D$9,IFERROR(MATCH(IF($B7="Robusta","Robusta",(IF($B7="","Arabica",$B7))&" - "&(IF($C7="","Commercial",$C7))),Variables!$B$1:$D$1,0),1))*(AV7/365))+(INDEX(Variables!$B$8:$D$8,IFERROR(MATCH(IF($B7="Robusta","Robusta",(IF($B7="","Arabica",$B7))&" - "&(IF($C7="","Commercial",$C7))),Variables!$B$1:$D$1,0),1))*L7/16.67)),"")) -> -204.97062
A8: Kenya | B8: Arabica | C8: Commercial | D8: 45133 | E8: 45292 | F8: 45322 | G8: 3786046 | H8: =IF(ISNUMBER(SEARCH("cancel",AN8)),"Cancelled",IF(AND(AK8<>"",AL8<>"",AM8<>""),"Closed","Open")) -> Open | I8: =IF(AND(AK8<>"",AL8<>"",AM8<>""),"All dates received",_xlfn.TEXTJOIN(" and ",TRUE(),IF(AK8="","No sailing date",""),IF(AL8="","No shipping advice sent",""),IF(AM8="","No docs dispatch date",""))) -> No shipping advice sent | J8: Jobin | L8: 320 | M8: Congo Kivu 4 | N8: AA | R8: SAS | S8: Hamburg | T8: =IF($H8="Cancelled","",IFERROR(((Q8+INDEX(Variables!$B$6:$D$6,IFERROR(MATCH(IF($B8="Robusta","Robusta",(IF($B8="","Arabica",$B8))&" - "&(IF($C8="","Commercial",$C8))),Variables!$B$1:$D$1,0),1)))*22.0462)*(L8/16.67),"")) -> 123067.26 | U8: 45265 | V8: =IF(ISNUMBER(U8),"Sent","") -> Sent | W8: 45271 | X8: =IF(ISNUMBER(W8),"Approved","") -> Approved | Z8: =IF($H8="Cancelled","",IFERROR(IF(F8="","",F8-Variables!$B$13),"")) -> 45307 | AA8: =IF($H8="Cancelled","",IFERROR(IF(W8="","",(AVERAGE(E8:F8)-W8)-Variables!$B$14),"")) -> 6 | AB8: 45390 | AC8: =IF($H8="Cancelled","",IFERROR(IF(AB8="","",IF(AND(W8="",Y8=""),"",IF(Y8>W8,Y8+Variables!$B$15+Variables!$B$16+Variables!$B$17-AB8,W8+Variables!$B$16+Variables!$B$17-AB8))),"")) -> -111 | AD8: MSC FCL/FCL | AE8: MSC Aria III | AI8: MEDUM2628615 | AJ8: N/A | AK8: 45343 | AM8: 45379 | AN8: Documents dispatched | AP8: =IF($H8="Cancelled","",IFERROR(IF(OR(AK8="",AB8=""),"",(AB8+Variables!$B$18-AK8)),"")) -> 54 | AQ8: =IF($H8="Cancelled","",IFERROR(IF(OR(AM8="",AK8=""),"",(AK8+Variables!$B$19)-AM8),"")) -> -31 | AR8: =IF($H8="Cancelled","",IFERROR(T8*INDEX(Variables!$B$7:$D$7,IFERROR(MATCH(IF($B8="Robusta","Robusta",(IF($B8="","Arabica",$B8))&" - "&(IF($C8="","Commercial",$C8))),Variables!$B$1:$D$1,0),1))*(AQ8/365),"")) -> -673.9865 | AS8: =IF($H8="Cancelled","",IFERROR((T8*INDEX(Variables!$B$7:$D$7,IFERROR(MATCH(IF($B8="Robusta","Robusta",(IF($B8="","Arabica",$B8))&" - "&(IF($C8="","Commercial",$C8))),Variables!$B$1:$D$1,0),1))*IFERROR(IF(W8="","",(AVERAGE(E8:F8)-W8)-Variables!$B$14),"")/365)+(L8/16.67*INDEX(Variables!$B$8:$D$8,IFERROR(MATCH(IF($B8="Robusta","Robusta",(IF($B8="","Arabica",$B8))&" - "&(IF($C8="","Commercial",$C8))),Variables!$B$1:$D$1,0),1))*IFERROR(IF(W8="","",(AVERAGE(E8:F8)-W8)-Variables!$B$14),""))+(T8*INDEX(Variables!$B$9:$D$9,IFERROR(MATCH(IF($B8="Robusta","Robusta",(IF($B8="","Arabica",$B8))&" - "&(IF($C8="","Commercial",$C8))),Variables!$B$1:$D$1,0),1))*IFERROR(IF(W8="","",(AVERAGE(E8:F8)-W8)-Variables!$B$14),"")/365),"")) -> 228.13074 | AT8: =IF($H8="Cancelled","",IFERROR((T8*INDEX(Variables!$B$7:$D$7,IFERROR(MATCH(IF($B8="Robusta","Robusta",(IF($B8="","Arabica",$B8))&" - "&(IF($C8="","Commercial",$C8))),Variables!$B$1:$D$1,0),1))*AC8/365)+(L8/16.67*INDEX(Variables!$B$8:$D$8,IFERROR(MATCH(IF($B8="Robusta","Robusta",(IF($B8="","Arabica",$B8))&" - "&(IF($C8="","Commercial",$C8))),Variables!$B$1:$D$1,0),1))*AC8)+(T8*INDEX(Variables!$B$9:$D$9,IFERROR(MATCH(IF($B8="Robusta","Robusta",(IF($B8="","Arabica",$B8))&" - "&(IF($C8="","Commercial",$C8))),Variables!$B$1:$D$1,0),1))*AC8/365),"")) -> -4220.4187 | AU8: =IF($H8="Cancelled","",IFERROR((T8*INDEX(Variables!$B$7:$D$7,IFERROR(MATCH(IF($B8="Robusta","Robusta",(IF($B8="","Arabica",$B8))&" - "&(IF($C8="","Commercial",$C8))),Variables!$B$1:$D$1,0),1))*AP8/365)+(L8/16.67*INDEX(Variables!$B$8:$D$8,IFERROR(MATCH(IF($B8="Robusta","Robusta",(IF($B8="","Arabica",$B8))&" - "&(IF($C8="","Commercial",$C8))),Variables!$B$1:$D$1,0),1))*AP8)+(T8*INDEX(Variables!$B$9:$D$9,IFERROR(MATCH(IF($B8="Robusta","Robusta",(IF($B8="","Arabica",$B8))&" - "&(IF($C8="","Commercial",$C8))),Variables!$B$1:$D$1,0),1))*AP8/365),"")) -> 2053.1767 | AV8: =IF($H8="Cancelled","",IFERROR(IF(AK8="","",F8-AK8),"")) -> -21 | AW8: =IF($H8="Cancelled","",IFERROR(IF(AV8="","",(T8*INDEX(Variables!$B$7:$D$7,IFERROR(MATCH(IF($B8="Robusta","Robusta",(IF($B8="","Arabica",$B8))&" - "&(IF($C8="","Commercial",$C8))),Variables!$B$1:$D$1,0),1))*(AV8/365))+(T8*INDEX(Variables!$B$9:$D$9,IFERROR(MATCH(IF($B8="Robusta","Robusta",(IF($B8="","Arabica",$B8))&" - "&(IF($C8="","Commercial",$C8))),Variables!$B$1:$D$1,0),1))*(AV8/365))+(INDEX(Variables!$B$8:$D$8,IFERROR(MATCH(IF($B8="Robusta","Robusta",(IF($B8="","Arabica",$B8))&" - "&(IF($C8="","Commercial",$C8))),Variables!$B$1:$D$1,0),1))*L8/16.67)),"")) -> -446.45759
A9: Kenya | B9: Arabica | C9: Commercial | D9: 45133 | E9: 45323 | F9: 45351 | G9: 3786047 | H9: =IF(ISNUMBER(SEARCH("cancel",AN9)),"Cancelled",IF(AND(AK9<>"",AL9<>"",AM9<>""),"Closed","Open")) -> Closed | I9: =IF(AND(AK9<>"",AL9<>"",AM9<>""),"All dates received",_xlfn.TEXTJOIN(" and ",TRUE(),IF(AK9="","No sailing date",""),IF(AL9="","No shipping advice sent",""),IF(AM9="","No docs dispatch date",""))) -> All dates received | J9: Jobin | L9: 320 | M9: Congo Kivu 4 | N9: AA | R9: SAS | S9: Lehavre | T9: =IF($H9="Cancelled","",IFERROR(((Q9+INDEX(Variables!$B$6:$D$6,IFERROR(MATCH(IF($B9="Robusta","Robusta",(IF($B9="","Arabica",$B9))&" - "&(IF($C9="","Commercial",$C9))),Variables!$B$1:$D$1,0),1)))*22.0462)*(L9/16.67),"")) -> 123067.26 | V9: =IF(ISNUMBER(U9),"Sent","") | W9: 45307 | X9: =IF(ISNUMBER(W9),"Approved","") -> Approved | Y9: 45379 | Z9: =IF($H9="Cancelled","",IFERROR(IF(F9="","",F9-Variables!$B$13),"")) -> 45336 | AA9: =IF($H9="Cancelled","",IFERROR(IF(W9="","",(AVERAGE(E9:F9)-W9)-Variables!$B$14),"")) -> 0 | AB9: 45390 | AC9: =IF($H9="Cancelled","",IFERROR(IF(AB9="","",IF(AND(W9="",Y9=""),"",IF(Y9>W9,Y9+Variables!$B$15+Variables!$B$16+Variables!$B$17-AB9,W9+Variables!$B$16+Variables!$B$17-AB9))),"")) -> 4 | AD9: MSC FCL/FCL | AE9: Msc Precision | AI9: MEDUM2649587 | AJ9: N/A | AK9: 45468 | AL9: 45471 | AM9: 45474 | AN9: Documents dispatched | AP9: =IF($H9="Cancelled","",IFERROR(IF(OR(AK9="",AB9=""),"",(AB9+Variables!$B$18-AK9)),"")) -> -71 | AQ9: =IF($H9="Cancelled","",IFERROR(IF(OR(AM9="",AK9=""),"",(AK9+Variables!$B$19)-AM9),"")) -> -1 | AR9: =IF($H9="Cancelled","",IFERROR(T9*INDEX(Variables!$B$7:$D$7,IFERROR(MATCH(IF($B9="Robusta","Robusta",(IF($B9="","Arabica",$B9))&" - "&(IF($C9="","Commercial",$C9))),Variables!$B$1:$D$1,0),1))*(AQ9/365),"")) -> -21.7415 | AS9: =IF($H9="Cancelled","",IFERROR((T9*INDEX(Variables!$B$7:$D$7,IFERROR(MATCH(IF($B9="Robusta","Robusta",(IF($B9="","Arabica",$B9))&" - "&(IF($C9="","Commercial",$C9))),Variables!$B$1:$D$1,0),1))*IFERROR(IF(W9="","",(AVERAGE(E9:F9)-W9)-Variables!$B$14),"")/365)+(L9/16.67*INDEX(Variables!$B$8:$D$8,IFERROR(MATCH(IF($B9="Robusta","Robusta",(IF($B9="","Arabica",$B9))&" - "&(IF($C9="","Commercial",$C9))),Variables!$B$1:$D$1,0),1))*IFERROR(IF(W9="","",(AVERAGE(E9:F9)-W9)-Variables!$B$14),""))+(T9*INDEX(Variables!$B$9:$D$9,IFERROR(MATCH(IF($B9="Robusta","Robusta",(IF($B9="","Arabica",$B9))&" - "&(IF($C9="","Commercial",$C9))),Variables!$B$1:$D$1,0),1))*IFERROR(IF(W9="","",(AVERAGE(E9:F9)-W9)-Variables!$B$14),"")/365),"")) -> 0 | AT9: =IF($H9="Cancelled","",IFERROR((T9*INDEX(Variables!$B$7:$D$7,IFERROR(MATCH(IF($B9="Robusta","Robusta",(IF($B9="","Arabica",$B9))&" - "&(IF($C9="","Commercial",$C9))),Variables!$B$1:$D$1,0),1))*AC9/365)+(L9/16.67*INDEX(Variables!$B$8:$D$8,IFERROR(MATCH(IF($B9="Robusta","Robusta",(IF($B9="","Arabica",$B9))&" - "&(IF($C9="","Commercial",$C9))),Variables!$B$1:$D$1,0),1))*AC9)+(T9*INDEX(Variables!$B$9:$D$9,IFERROR(MATCH(IF($B9="Robusta","Robusta",(IF($B9="","Arabica",$B9))&" - "&(IF($C9="","Commercial",$C9))),Variables!$B$1:$D$1,0),1))*AC9/365),"")) -> 152.08716 | AU9: =IF($H9="Cancelled","",IFERROR((T9*INDEX(Variables!$B$7:$D$7,IFERROR(MATCH(IF($B9="Robusta","Robusta",(IF($B9="","Arabica",$B9))&" - "&(IF($C9="","Commercial",$C9))),Variables!$B$1:$D$1,0),1))*AP9/365)+(L9/16.67*INDEX(Variables!$B$8:$D$8,IFERROR(MATCH(IF($B9="Robusta","Robusta",(IF($B9="","Arabica",$B9))&" - "&(IF($C9="","Commercial",$C9))),Variables!$B$1:$D$1,0),1))*AP9)+(T9*INDEX(Variables!$B$9:$D$9,IFERROR(MATCH(IF($B9="Robusta","Robusta",(IF($B9="","Arabica",$B9))&" - "&(IF($C9="","Commercial",$C9))),Variables!$B$1:$D$1,0),1))*AP9/365),"")) -> -2699.5471 | AV9: =IF($H9="Cancelled","",IFERROR(IF(AK9="","",F9-AK9),"")) -> -117 | AW9: =IF($H9="Cancelled","",IFERROR(IF(AV9="","",(T9*INDEX(Variables!$B$7:$D$7,IFERROR(MATCH(IF($B9="Robusta","Robusta",(IF($B9="","Arabica",$B9))&" - "&(IF($C9="","Commercial",$C9))),Variables!$B$1:$D$1,0),1))*(AV9/365))+(T9*INDEX(Variables!$B$9:$D$9,IFERROR(MATCH(IF($B9="Robusta","Robusta",(IF($B9="","Arabica",$B9))&" - "&(IF($C9="","Commercial",$C9))),Variables!$B$1:$D$1,0),1))*(AV9/365))+(INDEX(Variables!$B$8:$D$8,IFERROR(MATCH(IF($B9="Robusta","Robusta",(IF($B9="","Arabica",$B9))&" - "&(IF($C9="","Commercial",$C9))),Variables!$B$1:$D$1,0),1))*L9/16.67)),"")) -> -2560.5494
A10: Kenya | B10: Arabica | C10: Commercial | D10: 45134 | E10: 45352 | F10: 45382 | G10: 3786053 | H10: =IF(ISNUMBER(SEARCH("cancel",AN10)),"Cancelled",IF(AND(AK10<>"",AL10<>"",AM10<>""),"Closed","Open")) -> Closed | I10: =IF(AND(AK10<>"",AL10<>"",AM10<>""),"All dates received",_xlfn.TEXTJOIN(" and ",TRUE(),IF(AK10="","No sailing date",""),IF(AL10="","No shipping advice sent",""),IF(AM10="","No docs dispatch date",""))) -> All dates received | J10: Dong Suh | K10: 4719 | L10: 840 | M10: ABC FAQ | N10: ABC Minus | R10: SAS | S10: Busan | T10: =IF($H10="Cancelled","",IFERROR(((Q10+INDEX(Variables!$B$6:$D$6,IFERROR(MATCH(IF($B10="Robusta","Robusta",(IF($B10="","Arabica",$B10))&" - "&(IF($C10="","Commercial",$C10))),Variables!$B$1:$D$1,0),1)))*22.0462)*(L10/16.67),"")) -> 323051.55 | U10: 45328 | V10: =IF(ISNUMBER(U10),"Sent","") -> Sent | W10: 45359 | X10: =IF(ISNUMBER(W10),"Approved","") -> Approved | Z10: =IF($H10="Cancelled","",IFERROR(IF(F10="","",F10-Variables!$B$13),"")) -> 45367 | AA10: =IF($H10="Cancelled","",IFERROR(IF(W10="","",(AVERAGE(E10:F10)-W10)-Variables!$B$14),"")) -> -22 | AB10: 45397 | AC10: =IF($H10="Cancelled","",IFERROR(IF(AB10="","",IF(AND(W10="",Y10=""),"",IF(Y10>W10,Y10+Variables!$B$15+Variables!$B$16+Variables!$B$17-AB10,W10+Variables!$B$16+Variables!$B$17-AB10))),"")) -> -30 | AD10: Maersk/ONE FCL/FCL | AE10: Kota Karim | AI10: ONEYMBAE00232500 | AJ10: 6427984430 | AK10: 45384 | AL10: 45386 | AM10: 45397 | AN10: Documents dispatched | AP10: =IF($H10="Cancelled","",IFERROR(IF(OR(AK10="",AB10=""),"",(AB10+Variables!$B$18-AK10)),"")) -> 20 | AQ10: =IF($H10="Cancelled","",IFERROR(IF(OR(AM10="",AK10=""),"",(AK10+Variables!$B$19)-AM10),"")) -> -8 | AR10: =IF($H10="Cancelled","",IFERROR(T10*INDEX(Variables!$B$7:$D$7,IFERROR(MATCH(IF($B10="Robusta","Robusta",(IF($B10="","Arabica",$B10))&" - "&(IF($C10="","Commercial",$C10))),Variables!$B$1:$D$1,0),1))*(AQ10/365),"")) -> -456.5715 | AS10: =IF($H10="Cancelled","",IFERROR((T10*INDEX(Variables!$B$7:$D$7,IFERROR(MATCH(IF($B10="Robusta","Robusta",(IF($B10="","Arabica",$B10))&" - "&(IF($C10="","Commercial",$C10))),Variables!$B$1:$D$1,0),1))*IFERROR(IF(W10="","",(AVERAGE(E10:F10)-W10)-Variables!$B$14),"")/365)+(L10/16.67*INDEX(Variables!$B$8:$D$8,IFERROR(MATCH(IF($B10="Robusta","Robusta",(IF($B10="","Arabica",$B10))&" - "&(IF($C10="","Commercial",$C10))),Variables!$B$1:$D$1,0),1))*IFERROR(IF(W10="","",(AVERAGE(E10:F10)-W10)-Variables!$B$14),""))+(T10*INDEX(Variables!$B$9:$D$9,IFERROR(MATCH(IF($B10="Robusta","Robusta",(IF($B10="","Arabica",$B10))&" - "&(IF($C10="","Commercial",$C10))),Variables!$B$1:$D$1,0),1))*IFERROR(IF(W10="","",(AVERAGE(E10:F10)-W10)-Variables!$B$14),"")/365),"")) -> -2195.7584 | AT10: =IF($H10="Cancelled","",IFERROR((T10*INDEX(Variables!$B$7:$D$7,IFERROR(MATCH(IF($B10="Robusta","Robusta",(IF($B10="","Arabica",$B10))&" - "&(IF($C10="","Commercial",$C10))),Variables!$B$1:$D$1,0),1))*AC10/365)+(L10/16.67*INDEX(Variables!$B$8:$D$8,IFERROR(MATCH(IF($B10="Robusta","Robusta",(IF($B10="","Arabica",$B10))&" - "&(IF($C10="","Commercial",$C10))),Variables!$B$1:$D$1,0),1))*AC10)+(T10*INDEX(Variables!$B$9:$D$9,IFERROR(MATCH(IF($B10="Robusta","Robusta",(IF($B10="","Arabica",$B10))&" - "&(IF($C10="","Commercial",$C10))),Variables!$B$1:$D$1,0),1))*AC10/365),"")) -> -2994.216 | AU10: =IF($H10="Cancelled","",IFERROR((T10*INDEX(Variables!$B$7:$D$7,IFERROR(MATCH(IF($B10="Robusta","Robusta",(IF($B10="","Arabica",$B10))&" - "&(IF($C10="","Commercial",$C10))),Variables!$B$1:$D$1,0),1))*AP10/365)+(L10/16.67*INDEX(Variables!$B$8:$D$8,IFERROR(MATCH(IF($B10="Robusta","Robusta",(IF($B10="","Arabica",$B10))&" - "&(IF($C10="","Commercial",$C10))),Variables!$B$1:$D$1,0),1))*AP10)+(T10*INDEX(Variables!$B$9:$D$9,IFERROR(MATCH(IF($B10="Robusta","Robusta",(IF($B10="","Arabica",$B10))&" - "&(IF($C10="","Commercial",$C10))),Variables!$B$1:$D$1,0),1))*AP10/365),"")) -> 1996.144 | AV10: =IF($H10="Cancelled","",IFERROR(IF(AK10="","",F10-AK10),"")) -> -2 | AW10: =IF($H10="Cancelled","",IFERROR(IF(AV10="","",(T10*INDEX(Variables!$B$7:$D$7,IFERROR(MATCH(IF($B10="Robusta","Robusta",(IF($B10="","Arabica",$B10))&" - "&(IF($C10="","Commercial",$C10))),Variables!$B$1:$D$1,0),1))*(AV10/365))+(T10*INDEX(Variables!$B$9:$D$9,IFERROR(MATCH(IF($B10="Robusta","Robusta",(IF($B10="","Arabica",$B10))&" - "&(IF($C10="","Commercial",$C10))),Variables!$B$1:$D$1,0),1))*(AV10/365))+(INDEX(Variables!$B$8:$D$8,IFERROR(MATCH(IF($B10="Robusta","Robusta",(IF($B10="","Arabica",$B10))&" - "&(IF($C10="","Commercial",$C10))),Variables!$B$1:$D$1,0),1))*L10/16.67)),"")) -> -73.614397
A11: Kenya | B11: Arabica | C11: Commercial | D11: 45134 | E11: 45383 | F11: 45412 | G11: 3786051 | H11: =IF(ISNUMBER(SEARCH("cancel",AN11)),"Cancelled",IF(AND(AK11<>"",AL11<>"",AM11<>""),"Closed","Open")) -> Closed | I11: =IF(AND(AK11<>"",AL11<>"",AM11<>""),"All dates received",_xlfn.TEXTJOIN(" and ",TRUE(),IF(AK11="","No sailing date",""),IF(AL11="","No shipping advice sent",""),IF(AM11="","No docs dispatch date",""))) -> All dates received | J11: Dong Suh | K11: 4834 | L11: 840 | M11: AB FAQ | N11: ABC FAQ | R11: SAS | S11: Busan | T11: =IF($H11="Cancelled","",IFERROR(((Q11+INDEX(Variables!$B$6:$D$6,IFERROR(MATCH(IF($B11="Robusta","Robusta",(IF($B11="","Arabica",$B11))&" - "&(IF($C11="","Commercial",$C11))),Variables!$B$1:$D$1,0),1)))*22.0462)*(L11/16.67),"")) -> 323051.55 | U11: 45362 | V11: =IF(ISNUMBER(U11),"Sent","") -> Sent | W11: 45421 | X11: =IF(ISNUMBER(W11),"Approved","") -> Approved | Z11: =IF($H11="Cancelled","",IFERROR(IF(F11="","",F11-Variables!$B$13),"")) -> 45397 | AA11: =IF($H11="Cancelled","",IFERROR(IF(W11="","",(AVERAGE(E11:F11)-W11)-Variables!$B$14),"")) -> -53.5 | AB11: 45398 | AC11: =IF($H11="Cancelled","",IFERROR(IF(AB11="","",IF(AND(W11="",Y11=""),"",IF(Y11>W11,Y11+Variables!$B$15+Variables!$B$16+Variables!$B$17-AB11,W11+Variables!$B$16+Variables!$B$17-AB11))),"")) -> 31 | AD11: ONE FCL/FCL | AE11: Kota Krim | AI11: ONEYMBAE00665800 | AJ11: 7766 8468 8718 | AK11: 45437 | AL11: 45439 | AM11: 45447 | AN11: Documents dispatched | AP11: =IF($H11="Cancelled","",IFERROR(IF(OR(AK11="",AB11=""),"",(AB11+Variables!$B$18-AK11)),"")) -> -32 | AQ11: =IF($H11="Cancelled","",IFERROR(IF(OR(AM11="",AK11=""),"",(AK11+Variables!$B$19)-AM11),"")) -> -5 | AR11: =IF($H11="Cancelled","",IFERROR(T11*INDEX(Variables!$B$7:$D$7,IFERROR(MATCH(IF($B11="Robusta","Robusta",(IF($B11="","Arabica",$B11))&" - "&(IF($C11="","Commercial",$C11))),Variables!$B$1:$D$1,0),1))*(AQ11/365),"")) -> -285.35719 | AS11: =IF($H11="Cancelled","",IFERROR((T11*INDEX(Variables!$B$7:$D$7,IFERROR(MATCH(IF($B11="Robusta","Robusta",(IF($B11="","Arabica",$B11))&" - "&(IF($C11="","Commercial",$C11))),Variables!$B$1:$D$1,0),1))*IFERROR(IF(W11="","",(AVERAGE(E11:F11)-W11)-Variables!$B$14),"")/365)+(L11/16.67*INDEX(Variables!$B$8:$D$8,IFERROR(MATCH(IF($B11="Robusta","Robusta",(IF($B11="","Arabica",$B11))&" - "&(IF($C11="","Commercial",$C11))),Variables!$B$1:$D$1,0),1))*IFERROR(IF(W11="","",(AVERAGE(E11:F11)-W11)-Variables!$B$14),""))+(T11*INDEX(Variables!$B$9:$D$9,IFERROR(MATCH(IF($B11="Robusta","Robusta",(IF($B11="","Arabica",$B11))&" - "&(IF($C11="","Commercial",$C11))),Variables!$B$1:$D$1,0),1))*IFERROR(IF(W11="","",(AVERAGE(E11:F11)-W11)-Variables!$B$14),"")/365),"")) -> -5339.6851 | AT11: =IF($H11="Cancelled","",IFERROR((T11*INDEX(Variables!$B$7:$D$7,IFERROR(MATCH(IF($B11="Robusta","Robusta",(IF($B11="","Arabica",$B11))&" - "&(IF($C11="","Commercial",$C11))),Variables!$B$1:$D$1,0),1))*AC11/365)+(L11/16.67*INDEX(Variables!$B$8:$D$8,IFERROR(MATCH(IF($B11="Robusta","Robusta",(IF($B11="","Arabica",$B11))&" - "&(IF($C11="","Commercial",$C11))),Variables!$B$1:$D$1,0),1))*AC11)+(T11*INDEX(Variables!$B$9:$D$9,IFERROR(MATCH(IF($B11="Robusta","Robusta",(IF($B11="","Arabica",$B11))&" - "&(IF($C11="","Commercial",$C11))),Variables!$B$1:$D$1,0),1))*AC11/365),"")) -> 3094.0232 | AU11: =IF($H11="Cancelled","",IFERROR((T11*INDEX(Variables!$B$7:$D$7,IFERROR(MATCH(IF($B11="Robusta","Robusta",(IF($B11="","Arabica",$B11))&" - "&(IF($C11="","Commercial",$C11))),Variables!$B$1:$D$1,0),1))*AP11/365)+(L11/16.67*INDEX(Variables!$B$8:$D$8,IFERROR(MATCH(IF($B11="Robusta","Robusta",(IF($B11="","Arabica",$B11))&" - "&(IF($C11="","Commercial",$C11))),Variables!$B$1:$D$1,0),1))*AP11)+(T11*INDEX(Variables!$B$9:$D$9,IFERROR(MATCH(IF($B11="Robusta","Robusta",(IF($B11="","Arabica",$B11))&" - "&(IF($C11="","Commercial",$C11))),Variables!$B$1:$D$1,0),1))*AP11/365),"")) -> -3193.8304 | AV11: =IF($H11="Cancelled","",IFERROR(IF(AK11="","",F11-AK11),"")) -> -25 | AW11: =IF($H11="Cancelled","",IFERROR(IF(AV11="","",(T11*INDEX(Variables!$B$7:$D$7,IFERROR(MATCH(IF($B11="Robusta","Robusta",(IF($B11="","Arabica",$B11))&" - "&(IF($C11="","Commercial",$C11))),Variables!$B$1:$D$1,0),1))*(AV11/365))+(T11*INDEX(Variables!$B$9:$D$9,IFERROR(MATCH(IF($B11="Robusta","Robusta",(IF($B11="","Arabica",$B11))&" - "&(IF($C11="","Commercial",$C11))),Variables!$B$1:$D$1,0),1))*(AV11/365))+(INDEX(Variables!$B$8:$D$8,IFERROR(MATCH(IF($B11="Robusta","Robusta",(IF($B11="","Arabica",$B11))&" - "&(IF($C11="","Commercial",$C11))),Variables!$B$1:$D$1,0),1))*L11/16.67)),"")) -> -1403.18
A12: Kenya | B12: Arabica | C12: Commercial | D12: 45134 | E12: 45383 | F12: 45412 | G12: 3786054 | H12: =IF(ISNUMBER(SEARCH("cancel",AN12)),"Cancelled",IF(AND(AK12<>"",AL12<>"",AM12<>""),"Closed","Open")) -> Closed | I12: =IF(AND(AK12<>"",AL12<>"",AM12<>""),"All dates received",_xlfn.TEXTJOIN(" and ",TRUE(),IF(AK12="","No sailing date",""),IF(AL12="","No shipping advice sent",""),IF(AM12="","No docs dispatch date",""))) -> All dates received | J12: Dong Suh | K12: 4835 | L12: 840 | M12: ABC FAQ | N12: ABC Minus | R12: SAS | S12: Busan | T12: =IF($H12="Cancelled","",IFERROR(((Q12+INDEX(Variables!$B$6:$D$6,IFERROR(MATCH(IF($B12="Robusta","Robusta",(IF($B12="","Arabica",$B12))&" - "&(IF($C12="","Commercial",$C12))),Variables!$B$1:$D$1,0),1)))*22.0462)*(L12/16.67),"")) -> 323051.55 | U12: 45362 | V12: =IF(ISNUMBER(U12),"Sent","") -> Sent | W12: 45421 | X12: =IF(ISNUMBER(W12),"Approved","") -> Approved | Z12: =IF($H12="Cancelled","",IFERROR(IF(F12="","",F12-Variables!$B$13),"")) -> 45397 | AA12: =IF($H12="Cancelled","",IFERROR(IF(W12="","",(AVERAGE(E12:F12)-W12)-Variables!$B$14),"")) -> -53.5 | AB12: 45397 | AC12: =IF($H12="Cancelled","",IFERROR(IF(AB12="","",IF(AND(W12="",Y12=""),"",IF(Y12>W12,Y12+Variables!$B$15+Variables!$B$16+Variables!$B$17-AB12,W12+Variables!$B$16+Variables!$B$17-AB12))),"")) -> 32 | AD12: Evergreen FCL/FCL | AE12: Ever Dainty | AI12: 321400001449 | AJ12: 7769 3681 8540 | AK12: 45445 | AL12: 45448 | AM12: 45462 | AN12: Documents dispatched | AP12: =IF($H12="Cancelled","",IFERROR(IF(OR(AK12="",AB12=""),"",(AB12+Variables!$B$18-AK12)),"")) -> -41 | AQ12: =IF($H12="Cancelled","",IFERROR(IF(OR(AM12="",AK12=""),"",(AK12+Variables!$B$19)-AM12),"")) -> -12 | AR12: =IF($H12="Cancelled","",IFERROR(T12*INDEX(Variables!$B$7:$D$7,IFERROR(MATCH(IF($B12="Robusta","Robusta",(IF($B12="","Arabica",$B12))&" - "&(IF($C12="","Commercial",$C12))),Variables!$B$1:$D$1,0),1))*(AQ12/365),"")) -> -684.85725 | AS12: =IF($H12="Cancelled","",IFERROR((T12*INDEX(Variables!$B$7:$D$7,IFERROR(MATCH(IF($B12="Robusta","Robusta",(IF($B12="","Arabica",$B12))&" - "&(IF($C12="","Commercial",$C12))),Variables!$B$1:$D$1,0),1))*IFERROR(IF(W12="","",(AVERAGE(E12:F12)-W12)-Variables!$B$14),"")/365)+(L12/16.67*INDEX(Variables!$B$8:$D$8,IFERROR(MATCH(IF($B12="Robusta","Robusta",(IF($B12="","Arabica",$B12))&" - "&(IF($C12="","Commercial",$C12))),Variables!$B$1:$D$1,0),1))*IFERROR(IF(W12="","",(AVERAGE(E12:F12)-W12)-Variables!$B$14),""))+(T12*INDEX(Variables!$B$9:$D$9,IFERROR(MATCH(IF($B12="Robusta","Robusta",(IF($B12="","Arabica",$B12))&" - "&(IF($C12="","Commercial",$C12))),Variables!$B$1:$D$1,0),1))*IFERROR(IF(W12="","",(AVERAGE(E12:F12)-W12)-Variables!$B$14),"")/365),"")) -> -5339.6851 | AT12: =IF($H12="Cancelled","",IFERROR((T12*INDEX(Variables!$B$7:$D$7,IFERROR(MATCH(IF($B12="Robusta","Robusta",(IF($B12="","Arabica",$B12))&" - "&(IF($C12="","Commercial",$C12))),Variables!$B$1:$D$1,0),1))*AC12/365)+(L12/16.67*INDEX(Variables!$B$8:$D$8,IFERROR(MATCH(IF($B12="Robusta","Robusta",(IF($B12="","Arabica",$B12))&" - "&(IF($C12="","Commercial",$C12))),Variables!$B$1:$D$1,0),1))*AC12)+(T12*INDEX(Variables!$B$9:$D$9,IFERROR(MATCH(IF($B12="Robusta","Robusta",(IF($B12="","Arabica",$B12))&" - "&(IF($C12="","Commercial",$C12))),Variables!$B$1:$D$1,0),1))*AC12/365),"")) -> 3193.8304 | AU12: =IF($H12="Cancelled","",IFERROR((T12*INDEX(Variables!$B$7:$D$7,IFERROR(MATCH(IF($B12="Robusta","Robusta",(IF($B12="","Arabica",$B12))&" - "&(IF($C12="","Commercial",$C12))),Variables!$B$1:$D$1,0),1))*AP12/365)+(L12/16.67*INDEX(Variables!$B$8:$D$8,IFERROR(MATCH(IF($B12="Robusta","Robusta",(IF($B12="","Arabica",$B12))&" - "&(IF($C12="","Commercial",$C12))),Variables!$B$1:$D$1,0),1))*AP12)+(T12*INDEX(Variables!$B$9:$D$9,IFERROR(MATCH(IF($B12="Robusta","Robusta",(IF($B12="","Arabica",$B12))&" - "&(IF($C12="","Commercial",$C12))),Variables!$B$1:$D$1,0),1))*AP12/365),"")) -> -4092.0951 | AV12: =IF($H12="Cancelled","",IFERROR(IF(AK12="","",F12-AK12),"")) -> -33 | AW12: =IF($H12="Cancelled","",IFERROR(IF(AV12="","",(T12*INDEX(Variables!$B$7:$D$7,IFERROR(MATCH(IF($B12="Robusta","Robusta",(IF($B12="","Arabica",$B12))&" - "&(IF($C12="","Commercial",$C12))),Variables!$B$1:$D$1,0),1))*(AV12/365))+(T12*INDEX(Variables!$B$9:$D$9,IFERROR(MATCH(IF($B12="Robusta","Robusta",(IF($B12="","Arabica",$B12))&" - "&(IF($C12="","Commercial",$C12))),Variables!$B$1:$D$1,0),1))*(AV12/365))+(INDEX(Variables!$B$8:$D$8,IFERROR(MATCH(IF($B12="Robusta","Robusta",(IF($B12="","Arabica",$B12))&" - "&(IF($C12="","Commercial",$C12))),Variables!$B$1:$D$1,0),1))*L12/16.67)),"")) -> -1865.6376
A13: Kenya | B13: Arabica | C13: Commercial | D13: 45134 | E13: 45413 | F13: 45443 | G13: 3786052 | H13: =IF(ISNUMBER(SEARCH("cancel",AN13)),"Cancelled",IF(AND(AK13<>"",AL13<>"",AM13<>""),"Closed","Open")) -> Closed | I13: =IF(AND(AK13<>"",AL13<>"",AM13<>""),"All dates received",_xlfn.TEXTJOIN(" and ",TRUE(),IF(AK13="","No sailing date",""),IF(AL13="","No shipping advice sent",""),IF(AM13="","No docs dispatch date",""))) -> All dates received | J13: Dong Suh | K13: 4962 | L13: 560 | M13: AB FAQ | N13: ABC FAQ | R13: SAS | S13: Busan | T13: =IF($H13="Cancelled","",IFERROR(((Q13+INDEX(Variables!$B$6:$D$6,IFERROR(MATCH(IF($B13="Robusta","Robusta",(IF($B13="","Arabica",$B13))&" - "&(IF($C13="","Commercial",$C13))),Variables!$B$1:$D$1,0),1)))*22.0462)*(L13/16.67),"")) -> 215367.7 | U13: 45390 | V13: =IF(ISNUMBER(U13),"Sent","") -> Sent | X13: =IF(ISNUMBER(W13),"Approved","") | Z13: =IF($H13="Cancelled","",IFERROR(IF(F13="","",F13-Variables!$B$13),"")) -> 45428 | AA13: =IF($H13="Cancelled","",IFERROR(IF(W13="","",(AVERAGE(E13:F13)-W13)-Variables!$B$14),"")) | AB13: 45401 | AC13: =IF($H13="Cancelled","",IFERROR(IF(AB13="","",IF(AND(W13="",Y13=""),"",IF(Y13>W13,Y13+Variables!$B$15+Variables!$B$16+Variables!$B$17-AB13,W13+Variables!$B$16+Variables!$B$17-AB13))),"")) | AD13: ONE FCL/FCL | AE13: New Jersey Trader | AI13: ONEYMBAE00994600 | AJ13: 25 8936 6216 | AK13: 45462 | AL13: 45464 | AM13: 45477 | AN13: Documents dispatched | AP13: =IF($H13="Cancelled","",IFERROR(IF(OR(AK13="",AB13=""),"",(AB13+Variables!$B$18-AK13)),"")) -> -54 | AQ13: =IF($H13="Cancelled","",IFERROR(IF(OR(AM13="",AK13=""),"",(AK13+Variables!$B$19)-AM13),"")) -> -10 | AR13: =IF($H13="Cancelled","",IFERROR(T13*INDEX(Variables!$B$7:$D$7,IFERROR(MATCH(IF($B13="Robusta","Robusta",(IF($B13="","Arabica",$B13))&" - "&(IF($C13="","Commercial",$C13))),Variables!$B$1:$D$1,0),1))*(AQ13/365),"")) -> -380.47625 | AS13: =IF($H13="Cancelled","",IFERROR((T13*INDEX(Variables!$B$7:$D$7,IFERROR(MATCH(IF($B13="Robusta","Robusta",(IF($B13="","Arabica",$B13))&" - "&(IF($C13="","Commercial",$C13))),Variables!$B$1:$D$1,0),1))*IFERROR(IF(W13="","",(AVERAGE(E13:F13)-W13)-Variables!$B$14),"")/365)+(L13/16.67*INDEX(Variables!$B$8:$D$8,IFERROR(MATCH(IF($B13="Robusta","Robusta",(IF($B13="","Arabica",$B13))&" - "&(IF($C13="","Commercial",$C13))),Variables!$B$1:$D$1,0),1))*IFERROR(IF(W13="","",(AVERAGE(E13:F13)-W13)-Variables!$B$14),""))+(T13*INDEX(Variables!$B$9:$D$9,IFERROR(MATCH(IF($B13="Robusta","Robusta",(IF($B13="","Arabica",$B13))&" - "&(IF($C13="","Commercial",$C13))),Variables!$B$1:$D$1,0),1))*IFERROR(IF(W13="","",(AVERAGE(E13:F13)-W13)-Variables!$B$14),"")/365),"")) | AT13: =IF($H13="Cancelled","",IFERROR((T13*INDEX(Variables!$B$7:$D$7,IFERROR(MATCH(IF($B13="Robusta","Robusta",(IF($B13="","Arabica",$B13))&" - "&(IF($C13="","Commercial",$C13))),Variables!$B$1:$D$1,0),1))*AC13/365)+(L13/16.67*INDEX(Variables!$B$8:$D$8,IFERROR(MATCH(IF($B13="Robusta","Robusta",(IF($B13="","Arabica",$B13))&" - "&(IF($C13="","Commercial",$C13))),Variables!$B$1:$D$1,0),1))*AC13)+(T13*INDEX(Variables!$B$9:$D$9,IFERROR(MATCH(IF($B13="Robusta","Robusta",(IF($B13="","Arabica",$B13))&" - "&(IF($C13="","Commercial",$C13))),Variables!$B$1:$D$1,0),1))*AC13/365),"")) | AU13: =IF($H13="Cancelled","",IFERROR((T13*INDEX(Variables!$B$7:$D$7,IFERROR(MATCH(IF($B13="Robusta","Robusta",(IF($B13="","Arabica",$B13))&" - "&(IF($C13="","Commercial",$C13))),Variables!$B$1:$D$1,0),1))*AP13/365)+(L13/16.67*INDEX(Variables!$B$8:$D$8,IFERROR(MATCH(IF($B13="Robusta","Robusta",(IF($B13="","Arabica",$B13))&" - "&(IF($C13="","Commercial",$C13))),Variables!$B$1:$D$1,0),1))*AP13)+(T13*INDEX(Variables!$B$9:$D$9,IFERROR(MATCH(IF($B13="Robusta","Robusta",(IF($B13="","Arabica",$B13))&" - "&(IF($C13="","Commercial",$C13))),Variables!$B$1:$D$1,0),1))*AP13/365),"")) -> -3593.0592 | AV13: =IF($H13="Cancelled","",IFERROR(IF(AK13="","",F13-AK13),"")) -> -19 | AW13: =IF($H13="Cancelled","",IFERROR(IF(AV13="","",(T13*INDEX(Variables!$B$7:$D$7,IFERROR(MATCH(IF($B13="Robusta","Robusta",(IF($B13="","Arabica",$B13))&" - "&(IF($C13="","Commercial",$C13))),Variables!$B$1:$D$1,0),1))*(AV13/365))+(T13*INDEX(Variables!$B$9:$D$9,IFERROR(MATCH(IF($B13="Robusta","Robusta",(IF($B13="","Arabica",$B13))&" - "&(IF($C13="","Commercial",$C13))),Variables!$B$1:$D$1,0),1))*(AV13/365))+(INDEX(Variables!$B$8:$D$8,IFERROR(MATCH(IF($B13="Robusta","Robusta",(IF($B13="","Arabica",$B13))&" - "&(IF($C13="","Commercial",$C13))),Variables!$B$1:$D$1,0),1))*L13/16.67)),"")) -> -704.22452
