Workbook

Sheet Read Me
A1: Stocktake Optimization — Team Work Plan
A2: NKG East Africa / Ibero Kenya · Pathways Technologies · prepared 9 Oct 2026 · plan V1.0
A4: How to use this workbook
A5: Master Plan | B5: Every task with owner, support, dates, dependencies, deliverable and "done when". Update Status (drop-down) and % Done here only.
A6: Team Summary | B6: Counts, workload and next due date per person — all formulas from Master Plan.
A7: Person sheets | B7: One sheet per team member (live links to Master Plan rows) — send each person their tab.
A8: Next Week (12–16 Oct) | B8: Day-by-day plan for every person for the first build week.
A9: Gantt | B9: Weekly timeline; bars shade automatically from Start/End dates; green = complete.
A10: Milestones | B10: Key dates the sponsor tracks.
A11: NKG Actions | B11: What we need from NKG, by when, and which of our tasks it blocks.
A12: Meetings & Rhythm | B12: Recurring ceremonies (stand-up, status, reviews, steering).
A13: Holidays | B13: Public holidays excluded from "Work days" (Mashujaa Day Tue 20 Oct falls in Sprint 1).
A14: Red text | B14: Item still to be confirmed with NKG or the team.
A16: Team and responsibilities
A17: Name | B17: Role | C17: Owns
A18: Daphne Okwaro | B18: Project Manager / Data Analytics Lead | C18: Plan, NKG decisions, access, stakeholder management, status reporting, SIT/UAT/training/cutover coordination
A19: Moses Masibo | B19: Solution Architect | C19: Environments, solutions, ALM and Git, security model, data-model and engine design review, code review, PROD readiness
A20: Denis Otieno | B20: Data Engineer | C20: Email intake, validation, dataflows, Dataverse tables, master-data migration, reconciliation engine L1–L3, rules, tie-outs
A21: Nicole Akinyi | B21: Data Analyst | C21: Data profiling, mapping coverage, test data, Power BI model and reports, month-end pack, parallel-run analysis
A22: William Imo | B22: Power Apps Developer | C22: Stock Take app (counter phone/tablet app), offline sync, count flows F11–F12, counter training
A23: Andrew Tanui | B23: Power Apps Developer | C23: Stock Management Hub (plan, run, review, close, third parties, registers, admin), Hub flows
A24: Jones Alukwe | B24: Power Apps Developer / Copilot Developer | C24: Stock Control Centre (model-driven), BPFs, exceptions, corrections, sign-off gate, Copilot Stock Assistant
A25: Frankie Omasaja | B25: QA / Test & Documentation — role to confirm | C25: SIT scripts and execution, defect log, UAT scripts, user guides and training material formatting
A27: Phases
A28: Phase | B28: Dates | C28: Exit criteria
A29: 0 Discovery | B29: 1 – 9 Oct | C29: Sessions held, BRD V1.1, spec, mockups (done)
A30: 1 Design | B30: 5 – 16 Oct | C30: BRD/design signed; decisions OD1–OD5, OD9 closed; environments and Git ready
A31: 2 Sprint 1 | B31: 12 – 23 Oct | C31: Intake, tables, master data, app capture, wizard, mapping BPF demoed
A32: 3 Sprint 2 | B32: 26 Oct – 6 Nov | C32: Engine L1–L3, exceptions, corrections, workspace, sign-off, Power BI, Copilot T1–T5
A33: 4 SIT + parallel run | B33: 26 Oct – 6 Nov | C33: Tie-outs T1–T10 = 0; October count run in new solution (2–4 Nov)
A34: 5 Training | B34: 9 – 13 Nov | C34: ≥ 90% of named users trained; UAT release deployed
A35: 6 UAT | B35: 16 – 27 Nov | C35: UAT signed by every department
A36: 7 Cutover | B36: 23 Nov – 3 Dec | C36: PROD live; feeds clean 3 days; baseline approved; first live count 1–3 Dec
A37: 8 Hypercare | B37: 1 – 11 Dec | C37: First sign-off with residual = 0 by WD7 (9 Dec); handover complete
A38: 9 Acceptance | B38: 14 – 17 Dec | C38: Formal acceptance 17 Dec
A40: Capacity watch | B40: Jones (Control Centre + Copilot) and Andrew (Hub + parallel-run support) are heaviest in 2–6 Nov. Copilot topics T6–T10 are deliberately in training week; if Jones slips, Copilot moves into the UAT window (no reconciliation feature depends on it). Frankie's role is assumed as QA / documentation — confirm.

Sheet Team Summary
A1: Team Summary
A2: All figures are formulas over Master Plan.
A4: Name | B4: Role | C4: Tasks owned | D4: Complete | E4: In progress | F4: Not started | G4: Blocked / at risk | H4: Overdue | I4: Owned work days | J4: % complete (avg) | K4: Next open task due | L4: Also supporting (tasks)
A5: Daphne Okwaro | B5: Project Manager / Data Analytics Lead | C5: =COUNTIF('Master Plan'!$F$5:$F$130,A5) -> 27 | D5: =COUNTIFS('Master Plan'!$F$5:$F$130,A5,'Master Plan'!$O$5:$O$130,"Complete") -> 6 | E5: =COUNTIFS('Master Plan'!$F$5:$F$130,A5,'Master Plan'!$O$5:$O$130,"In progress") -> 1 | F5: =COUNTIFS('Master Plan'!$F$5:$F$130,A5,'Master Plan'!$O$5:$O$130,"Not started") -> 20 | G5: =COUNTIFS('Master Plan'!$F$5:$F$130,A5,'Master Plan'!$O$5:$O$130,"Blocked")+COUNTIFS('Master Plan'!$F$5:$F$130,A5,'Master Plan'!$O$5:$O$130,"At risk") -> 0 | H5: =COUNTIFS('Master Plan'!$F$5:$F$130,A5,'Master Plan'!$Q$5:$Q$130,"OVERDUE") -> 0 | I5: =SUMIF('Master Plan'!$F$5:$F$130,A5,'Master Plan'!$J$5:$J$130) -> 82 | J5: =IFERROR(AVERAGEIF('Master Plan'!$F$5:$F$130,A5,'Master Plan'!$P$5:$P$130),0) -> 0.23148148 | K5: =IFERROR(1/(1/_xlfn.MINIFS('Master Plan'!$I$5:$I$130,'Master Plan'!$F$5:$F$130,A5,'Master Plan'!$O$5:$O$130,"<>Complete")),"—") -> 46304 | L5: =COUNTIF('Master Plan'!$G$5:$G$130,"*"&LEFT(A5,FIND(" ",A5)-1)&"*")+COUNTIF('Master Plan'!$G$5:$G$130,"All") -> 13
A6: Moses Masibo | B6: Solution Architect | C6: =COUNTIF('Master Plan'!$F$5:$F$130,A6) -> 18 | D6: =COUNTIFS('Master Plan'!$F$5:$F$130,A6,'Master Plan'!$O$5:$O$130,"Complete") -> 0 | E6: =COUNTIFS('Master Plan'!$F$5:$F$130,A6,'Master Plan'!$O$5:$O$130,"In progress") -> 0 | F6: =COUNTIFS('Master Plan'!$F$5:$F$130,A6,'Master Plan'!$O$5:$O$130,"Not started") -> 18 | G6: =COUNTIFS('Master Plan'!$F$5:$F$130,A6,'Master Plan'!$O$5:$O$130,"Blocked")+COUNTIFS('Master Plan'!$F$5:$F$130,A6,'Master Plan'!$O$5:$O$130,"At risk") -> 0 | H6: =COUNTIFS('Master Plan'!$F$5:$F$130,A6,'Master Plan'!$Q$5:$Q$130,"OVERDUE") -> 0 | I6: =SUMIF('Master Plan'!$F$5:$F$130,A6,'Master Plan'!$J$5:$J$130) -> 66 | J6: =IFERROR(AVERAGEIF('Master Plan'!$F$5:$F$130,A6,'Master Plan'!$P$5:$P$130),0) -> 0 | K6: =IFERROR(1/(1/_xlfn.MINIFS('Master Plan'!$I$5:$I$130,'Master Plan'!$F$5:$F$130,A6,'Master Plan'!$O$5:$O$130,"<>Complete")),"—") -> 46308 | L6: =COUNTIF('Master Plan'!$G$5:$G$130,"*"&LEFT(A6,FIND(" ",A6)-1)&"*")+COUNTIF('Master Plan'!$G$5:$G$130,"All") -> 24
A7: Denis Otieno | B7: Data Engineer | C7: =COUNTIF('Master Plan'!$F$5:$F$130,A7) -> 23 | D7: =COUNTIFS('Master Plan'!$F$5:$F$130,A7,'Master Plan'!$O$5:$O$130,"Complete") -> 0 | E7: =COUNTIFS('Master Plan'!$F$5:$F$130,A7,'Master Plan'!$O$5:$O$130,"In progress") -> 0 | F7: =COUNTIFS('Master Plan'!$F$5:$F$130,A7,'Master Plan'!$O$5:$O$130,"Not started") -> 23 | G7: =COUNTIFS('Master Plan'!$F$5:$F$130,A7,'Master Plan'!$O$5:$O$130,"Blocked")+COUNTIFS('Master Plan'!$F$5:$F$130,A7,'Master Plan'!$O$5:$O$130,"At risk") -> 0 | H7: =COUNTIFS('Master Plan'!$F$5:$F$130,A7,'Master Plan'!$Q$5:$Q$130,"OVERDUE") -> 0 | I7: =SUMIF('Master Plan'!$F$5:$F$130,A7,'Master Plan'!$J$5:$J$130) -> 81 | J7: =IFERROR(AVERAGEIF('Master Plan'!$F$5:$F$130,A7,'Master Plan'!$P$5:$P$130),0) -> 0 | K7: =IFERROR(1/(1/_xlfn.MINIFS('Master Plan'!$I$5:$I$130,'Master Plan'!$F$5:$F$130,A7,'Master Plan'!$O$5:$O$130,"<>Complete")),"—") -> 46308 | L7: =COUNTIF('Master Plan'!$G$5:$G$130,"*"&LEFT(A7,FIND(" ",A7)-1)&"*")+COUNTIF('Master Plan'!$G$5:$G$130,"All") -> 21
A8: Nicole Akinyi | B8: Data Analyst | C8: =COUNTIF('Master Plan'!$F$5:$F$130,A8) -> 12 | D8: =COUNTIFS('Master Plan'!$F$5:$F$130,A8,'Master Plan'!$O$5:$O$130,"Complete") -> 0 | E8: =COUNTIFS('Master Plan'!$F$5:$F$130,A8,'Master Plan'!$O$5:$O$130,"In progress") -> 0 | F8: =COUNTIFS('Master Plan'!$F$5:$F$130,A8,'Master Plan'!$O$5:$O$130,"Not started") -> 12 | G8: =COUNTIFS('Master Plan'!$F$5:$F$130,A8,'Master Plan'!$O$5:$O$130,"Blocked")+COUNTIFS('Master Plan'!$F$5:$F$130,A8,'Master Plan'!$O$5:$O$130,"At risk") -> 0 | H8: =COUNTIFS('Master Plan'!$F$5:$F$130,A8,'Master Plan'!$Q$5:$Q$130,"OVERDUE") -> 0 | I8: =SUMIF('Master Plan'!$F$5:$F$130,A8,'Master Plan'!$J$5:$J$130) -> 46 | J8: =IFERROR(AVERAGEIF('Master Plan'!$F$5:$F$130,A8,'Master Plan'!$P$5:$P$130),0) -> 0 | K8: =IFERROR(1/(1/_xlfn.MINIFS('Master Plan'!$I$5:$I$130,'Master Plan'!$F$5:$F$130,A8,'Master Plan'!$O$5:$O$130,"<>Complete")),"—") -> 46311 | L8: =COUNTIF('Master Plan'!$G$5:$G$130,"*"&LEFT(A8,FIND(" ",A8)-1)&"*")+COUNTIF('Master Plan'!$G$5:$G$130,"All") -> 26
A9: William Imo | B9: Power Apps Developer | C9: =COUNTIF('Master Plan'!$F$5:$F$130,A9) -> 13 | D9: =COUNTIFS('Master Plan'!$F$5:$F$130,A9,'Master Plan'!$O$5:$O$130,"Complete") -> 0 | E9: =COUNTIFS('Master Plan'!$F$5:$F$130,A9,'Master Plan'!$O$5:$O$130,"In progress") -> 0 | F9: =COUNTIFS('Master Plan'!$F$5:$F$130,A9,'Master Plan'!$O$5:$O$130,"Not started") -> 13 | G9: =COUNTIFS('Master Plan'!$F$5:$F$130,A9,'Master Plan'!$O$5:$O$130,"Blocked")+COUNTIFS('Master Plan'!$F$5:$F$130,A9,'Master Plan'!$O$5:$O$130,"At risk") -> 0 | H9: =COUNTIFS('Master Plan'!$F$5:$F$130,A9,'Master Plan'!$Q$5:$Q$130,"OVERDUE") -> 0 | I9: =SUMIF('Master Plan'!$F$5:$F$130,A9,'Master Plan'!$J$5:$J$130) -> 41 | J9: =IFERROR(AVERAGEIF('Master Plan'!$F$5:$F$130,A9,'Master Plan'!$P$5:$P$130),0) -> 0 | K9: =IFERROR(1/(1/_xlfn.MINIFS('Master Plan'!$I$5:$I$130,'Master Plan'!$F$5:$F$130,A9,'Master Plan'!$O$5:$O$130,"<>Complete")),"—") -> 46308 | L9: =COUNTIF('Master Plan'!$G$5:$G$130,"*"&LEFT(A9,FIND(" ",A9)-1)&"*")+COUNTIF('Master Plan'!$G$5:$G$130,"All") -> 12
A10: Andrew Tanui | B10: Power Apps Developer | C10: =COUNTIF('Master Plan'!$F$5:$F$130,A10) -> 13 | D10: =COUNTIFS('Master Plan'!$F$5:$F$130,A10,'Master Plan'!$O$5:$O$130,"Complete") -> 0 | E10: =COUNTIFS('Master Plan'!$F$5:$F$130,A10,'Master Plan'!$O$5:$O$130,"In progress") -> 0 | F10: =COUNTIFS('Master Plan'!$F$5:$F$130,A10,'Master Plan'!$O$5:$O$130,"Not started") -> 13 | G10: =COUNTIFS('Master Plan'!$F$5:$F$130,A10,'Master Plan'!$O$5:$O$130,"Blocked")+COUNTIFS('Master Plan'!$F$5:$F$130,A10,'Master Plan'!$O$5:$O$130,"At risk") -> 0 | H10: =COUNTIFS('Master Plan'!$F$5:$F$130,A10,'Master Plan'!$Q$5:$Q$130,"OVERDUE") -> 0 | I10: =SUMIF('Master Plan'!$F$5:$F$130,A10,'Master Plan'!$J$5:$J$130) -> 37 | J10: =IFERROR(AVERAGEIF('Master Plan'!$F$5:$F$130,A10,'Master Plan'!$P$5:$P$130),0) -> 0 | K10: =IFERROR(1/(1/_xlfn.MINIFS('Master Plan'!$I$5:$I$130,'Master Plan'!$F$5:$F$130,A10,'Master Plan'!$O$5:$O$130,"<>Complete")),"—") -> 46308 | L10: =COUNTIF('Master Plan'!$G$5:$G$130,"*"&LEFT(A10,FIND(" ",A10)-1)&"*")+COUNTIF('Master Plan'!$G$5:$G$130,"All") -> 14
A11: Jones Alukwe | B11: Power Apps Developer / Copilot Developer | C11: =COUNTIF('Master Plan'!$F$5:$F$130,A11) -> 14 | D11: =COUNTIFS('Master Plan'!$F$5:$F$130,A11,'Master Plan'!$O$5:$O$130,"Complete") -> 0 | E11: =COUNTIFS('Master Plan'!$F$5:$F$130,A11,'Master Plan'!$O$5:$O$130,"In progress") -> 0 | F11: =COUNTIFS('Master Plan'!$F$5:$F$130,A11,'Master Plan'!$O$5:$O$130,"Not started") -> 14 | G11: =COUNTIFS('Master Plan'!$F$5:$F$130,A11,'Master Plan'!$O$5:$O$130,"Blocked")+COUNTIFS('Master Plan'!$F$5:$F$130,A11,'Master Plan'!$O$5:$O$130,"At risk") -> 0 | H11: =COUNTIFS('Master Plan'!$F$5:$F$130,A11,'Master Plan'!$Q$5:$Q$130,"OVERDUE") -> 0 | I11: =SUMIF('Master Plan'!$F$5:$F$130,A11,'Master Plan'!$J$5:$J$130) -> 47 | J11: =IFERROR(AVERAGEIF('Master Plan'!$F$5:$F$130,A11,'Master Plan'!$P$5:$P$130),0) -> 0 | K11: =IFERROR(1/(1/_xlfn.MINIFS('Master Plan'!$I$5:$I$130,'Master Plan'!$F$5:$F$130,A11,'Master Plan'!$O$5:$O$130,"<>Complete")),"—") -> 46308 | L11: =COUNTIF('Master Plan'!$G$5:$G$130,"*"&LEFT(A11,FIND(" ",A11)-1)&"*")+COUNTIF('Master Plan'!$G$5:$G$130,"All") -> 14
A12: Frankie Omasaja | B12: QA / Test & Documentation — role to confirm | C12: =COUNTIF('Master Plan'!$F$5:$F$130,A12) -> 6 | D12: =COUNTIFS('Master Plan'!$F$5:$F$130,A12,'Master Plan'!$O$5:$O$130,"Complete") -> 0 | E12: =COUNTIFS('Master Plan'!$F$5:$F$130,A12,'Master Plan'!$O$5:$O$130,"In progress") -> 0 | F12: =COUNTIFS('Master Plan'!$F$5:$F$130,A12,'Master Plan'!$O$5:$O$130,"Not started") -> 6 | G12: =COUNTIFS('Master Plan'!$F$5:$F$130,A12,'Master Plan'!$O$5:$O$130,"Blocked")+COUNTIFS('Master Plan'!$F$5:$F$130,A12,'Master Plan'!$O$5:$O$130,"At risk") -> 0 | H12: =COUNTIFS('Master Plan'!$F$5:$F$130,A12,'Master Plan'!$Q$5:$Q$130,"OVERDUE") -> 0 | I12: =SUMIF('Master Plan'!$F$5:$F$130,A12,'Master Plan'!$J$5:$J$130) -> 35 | J12: =IFERROR(AVERAGEIF('Master Plan'!$F$5:$F$130,A12,'Master Plan'!$P$5:$P$130),0) -> 0 | K12: =IFERROR(1/(1/_xlfn.MINIFS('Master Plan'!$I$5:$I$130,'Master Plan'!$F$5:$F$130,A12,'Master Plan'!$O$5:$O$130,"<>Complete")),"—") -> 46311 | L12: =COUNTIF('Master Plan'!$G$5:$G$130,"*"&LEFT(A12,FIND(" ",A12)-1)&"*")+COUNTIF('Master Plan'!$G$5:$G$130,"All") -> 12
A13: Total | C13: =SUM(C5:C12) -> 126 | D13: =SUM(D5:D12) -> 6 | E13: =SUM(E5:E12) -> 1 | F13: =SUM(F5:F12) -> 119 | G13: =SUM(G5:G12) -> 0 | H13: =SUM(H5:H12) -> 0 | I13: =SUM(I5:I12) -> 435

Sheet Master Plan
A1: Stocktake Optimization — Master Task Plan (NKG East Africa)
A2: Edit Status and % Done here only — person sheets, Gantt and Team Summary update from this sheet. Red text = to confirm with NKG.
A4: ID | B4: Phase | C4: Workstream | D4: Task | E4: Detailed description / steps | F4: Owner | G4: Support | H4: Start | I4: End | J4: Work days | K4: Depends on | L4: Deliverable / output | M4: Done when (acceptance) | N4: Spec ref | O4: Status | P4: % Done | Q4: Overdue? | R4: Notes / blockers
A5: PM-01 | B5: 0 Discovery | C5: Project management | D5: Project kick-off and warehouse walk-through | E5: Kick-off with NKG; walk the warehouse floor; observe stacking, rows A–G / sections 1–14, bag tags, pockets, lights. | F5: Daphne Okwaro | G5: All | H5: 46296 | I5: 46296 | J5: =NETWORKDAYS(H5,I5,Holidays!$A$5:$A$12) -> 1 | L5: Kick-off notes | M5: Held with NKG stakeholders | N5: — | O5: Complete | P5: 1 | Q5: =IF(AND(O5<>"Complete",I5<TODAY()),"OVERDUE","")
A6: PM-02 | B6: 0 Discovery | C6: Project management | D6: Discovery sessions: Finance, Warehouse & Operations, Trade & QC, Logistics | E6: Run four sessions; record and transcribe; capture process, pain points, reports, data owners. | F6: Daphne Okwaro | G6: Moses Masibo, Denis Otieno, Nicole Akinyi | H6: 46297 | I6: 46303 | J6: =NETWORKDAYS(H6,I6,Holidays!$A$5:$A$12) -> 5 | K6: PM-01 | L6: Recordings + notes | M6: All four sessions held and transcribed | N6: BRD | O6: Complete | P6: 1 | Q6: =IF(AND(O6<>"Complete",I6<TODAY()),"OVERDUE","")
A7: PM-03 | B7: 0 Discovery | C7: Project management | D7: BRD V1.1 (red = items to confirm) | E7: Update the BRD from all recordings; mark unconfirmed items in red. | F7: Daphne Okwaro | G7: Nicole Akinyi | H7: 46300 | I7: 46304 | J7: =NETWORKDAYS(H7,I7,Holidays!$A$5:$A$12) -> 5 | K7: PM-02 | L7: STOCKTAKE_BRD_V1.1.docx | M7: Issued to team | N7: BRD | O7: Complete | P7: 1 | Q7: =IF(AND(O7<>"Complete",I7<TODAY()),"OVERDUE","")
A8: PM-04 | B8: 0 Discovery | C8: Design | D8: Developer Build Specification V1.0 + screen mockups | E8: Write the build specification (Sections 1–22 + appendices) and 10 screen mockups. | F8: Daphne Okwaro | G8: Moses Masibo | H8: 46302 | I8: 46304 | J8: =NETWORKDAYS(H8,I8,Holidays!$A$5:$A$12) -> 3 | K8: PM-03 | L8: Spec V1.0 + mockups PDF | M8: Issued to team | N8: All | O8: Complete | P8: 1 | Q8: =IF(AND(O8<>"Complete",I8<TODAY()),"OVERDUE","")
A9: PM-05 | B9: 0 Discovery | C9: Access | D9: System access request sent (NKG emails, Power Platform, Git, ITB environment) | E9: Request NKG accounts for all 8 team members, environment maker access, Git, legacy ITB environment. | F9: Daphne Okwaro | G9: Moses Masibo | H9: 46300 | I9: 46301 | J9: =NETWORKDAYS(H9,I9,Holidays!$A$5:$A$12) -> 2 | L9: Access request email | M9: Sent; ITB environment access received | N9: 16 | O9: Complete | P9: 1 | Q9: =IF(AND(O9<>"Complete",I9<TODAY()),"OVERDUE","")
A10: PM-06 | B10: 0 Discovery | C10: Weekly status | D10: Weekly status report #1 | E10: Status email (Word + HTML) to NKG. | F10: Daphne Okwaro | H10: 46297 | I10: 46297 | J10: =NETWORKDAYS(H10,I10,Holidays!$A$5:$A$12) -> 1 | L10: Status report | M10: Sent | N10: — | O10: Complete | P10: 1 | Q10: =IF(AND(O10<>"Complete",I10<TODAY()),"OVERDUE","")
A11: PM-10 | B11: 1 Design | C11: Weekly status | D11: Weekly status report #2 | E11: Progress: discovery complete, BRD V1.1, build spec, mockups; next week: design sign-off, decisions OD1–OD9, sprint 1 start. | F11: Daphne Okwaro | H11: 46304 | I11: 46304 | J11: =NETWORKDAYS(H11,I11,Holidays!$A$5:$A$12) -> 1 | K11: PM-04 | L11: Status report | M11: Sent to NKG distribution list | N11: — | O11: In progress | P11: 0.25 | Q11: =IF(AND(O11<>"Complete",I11<TODAY()),"OVERDUE","")
A12: PM-11 | B12: 1 Design | C12: Stakeholders | D12: Circulate BRD V1.1, Build Spec and mockups to NKG for review | E12: Email to Carol, Maina, Mathew, Denis Koech, department leads; ask for written comments by Wed 14 Oct; attach mockups PDF. | F12: Daphne Okwaro | H12: 46307 | I12: 46307 | J12: =NETWORKDAYS(H12,I12,Holidays!$A$5:$A$12) -> 1 | K12: PM-04 | L12: Review email | M12: Sent; every reviewer acknowledged | N12: — | O12: Not started | P12: 0 | Q12: =IF(AND(O12<>"Complete",I12<TODAY()),"OVERDUE","")
A13: PM-12 | B13: 1 Design | C13: Decisions | D13: Open-decision log OD1–OD9 (red items) | E13: Create decision log (decision, options, recommendation, owner, needed-by). Book 30-min calls per owner. Chase daily until closed. OD1 cut-off rule; OD2 unit rule (pocket, lights); OD3 Low Grade posting; OD4 provisional stock location; OD5 count tolerance; OD6 write-off thresholds; OD7 sign-off order; OD8 Copilot approval; OD9 licensing/environments. | F13: Daphne Okwaro | G13: Moses Masibo | H13: 46307 | I13: 46311 | J13: =NETWORKDAYS(H13,I13,Holidays!$A$5:$A$12) -> 5 | K13: PM-11 | L13: Decision log | M13: OD1–OD5 and OD9 closed by 16 Oct; OD6–OD8 by 23 Oct | N13: 22.3 | O13: Not started | P13: 0 | Q13: =IF(AND(O13<>"Complete",I13<TODAY()),"OVERDUE","")
A14: PM-13 | B14: 1 Design | C14: Stakeholders | D14: Design walkthrough with NKG (mockups + zero-variance model) | E14: 2-hour session, Digitization Project Team Boardroom / Teams. Demo mockups screen by screen; explain residual = 0 gate; collect feedback. | F14: Daphne Okwaro | G14: Moses Masibo, William Imo, Andrew Tanui, Jones Alukwe | H14: 46308 | I14: 46308 | J14: =NETWORKDAYS(H14,I14,Holidays!$A$5:$A$12) -> 1 | K14: PM-11 | L14: Feedback list | M14: Feedback logged and triaged into backlog | N14: 3, 4, 9–14 | O14: Not started | P14: 0 | Q14: =IF(AND(O14<>"Complete",I14<TODAY()),"OVERDUE","")
A15: PM-14 | B15: 1 Design | C15: Stakeholders | D15: Obtain BRD and design sign-off | E15: Update BRD/spec for walkthrough feedback (V1.2); obtain written sign-off from the approval table. | F15: Daphne Okwaro | G15: Moses Masibo | H15: 46309 | I15: 46311 | J15: =NETWORKDAYS(H15,I15,Holidays!$A$5:$A$12) -> 3 | K15: PM-13, PM-12 | L15: Signed BRD V1.2 + Spec V1.1 | M15: Signatures/approval emails received | N15: Doc control | O15: Not started | P15: 0 | Q15: =IF(AND(O15<>"Complete",I15<TODAY()),"OVERDUE","")
A16: PM-15 | B16: 1 Design | C16: Data feeds | D16: Formal data-feed request to XBS and Comtras/BRIC owners | E16: Request: (1) sample files for every feed S1–S15 by 14 Oct; (2) scheduled daily email to shared mailbox at 07:00 with subject STK|<SOURCE>|<YYYYMMDD>|<HHMM>; (3) named backup sender. | F16: Daphne Okwaro | G16: Denis Otieno | H16: 46307 | I16: 46309 | J16: =NETWORKDAYS(H16,I16,Holidays!$A$5:$A$12) -> 3 | L16: Feed request email + owner list | M16: Every feed has a named owner and a start date | N16: 7.1–7.2 | O16: Not started | P16: 0 | Q16: =IF(AND(O16<>"Complete",I16<TODAY()),"OVERDUE","")
A17: PM-16 | B17: 1 Design | C17: Access | D17: Licensing and environment confirmation with NKG IT | E17: Confirm Power Apps Premium for Hub/Control Centre users, service account stk.svc, shared mailbox, DEV/UAT/PROD Dataverse environments, Copilot Studio availability. | F17: Daphne Okwaro | G17: Moses Masibo | H17: 46307 | I17: 46311 | J17: =NETWORKDAYS(H17,I17,Holidays!$A$5:$A$12) -> 5 | L17: Confirmation email from NKG IT | M17: Licences and environments confirmed in writing | N17: 15, 16 | O17: Not started | P17: 0 | Q17: =IF(AND(O17<>"Complete",I17<TODAY()),"OVERDUE","")
A18: MO-01 | B18: 1 Design | C18: Architecture | D18: Inventory the ITB (John Nyongesa) solution | E18: Export managed solution "NKG Stock Solution" and all flows; list every app, flow, dataflow, table, SharePoint list, connection and owner; note what to keep/rebuild/retire. | F18: Moses Masibo | G18: Denis Otieno | H18: 46307 | I18: 46308 | J18: =NETWORKDAYS(H18,I18,Holidays!$A$5:$A$12) -> 2 | K18: PM-05 | L18: ITB inventory sheet + exported zip in Git /legacy | M18: Inventory reviewed with team | N18: 2, 16.4 | O18: Not started | P18: 0 | Q18: =IF(AND(O18<>"Complete",I18<TODAY()),"OVERDUE","")
A19: MO-02 | B19: 1 Design | C19: Architecture | D19: Ownership-transfer plan for ITB apps and flows | E19: Plan transfer of flows/apps from the external account to stk.svc so nothing stops when the external account is removed; agree date with NKG IT. | F19: Moses Masibo | H19: 46308 | I19: 46309 | J19: =NETWORKDAYS(H19,I19,Holidays!$A$5:$A$12) -> 2 | K19: MO-01 | L19: Transfer plan | M19: NKG IT agreed date | N19: 16.4 | O19: Not started | P19: 0 | Q19: =IF(AND(O19<>"Complete",I19<TODAY()),"OVERDUE","")
A20: MO-03 | B20: 1 Design | C20: Environments | D20: Request/confirm DEV, UAT, PROD environments and DLP policy | E20: Dataverse in each; DLP Business group: Dataverse, SharePoint, Outlook, Teams, Approvals, Power BI; block consumer connectors. | F20: Moses Masibo | G20: Daphne Okwaro | H20: 46307 | I20: 46311 | J20: =NETWORKDAYS(H20,I20,Holidays!$A$5:$A$12) -> 5 | K20: PM-16 | L20: Environments live | M20: Team can open DEV as makers | N20: 16.1, 15.2 | O20: Not started | P20: 0 | Q20: =IF(AND(O20<>"Complete",I20<TODAY()),"OVERDUE","")
A21: MO-04 | B21: 1 Design | C21: ALM | D21: Create publisher (prefix stk) and solutions in DEV | E21: STK Core, STK Apps, STK Automation, STK Copilot; environment-variable and connection-reference standards. | F21: Moses Masibo | H21: 46309 | I21: 46310 | J21: =NETWORKDAYS(H21,I21,Holidays!$A$5:$A$12) -> 2 | K21: MO-03 | L21: Solutions in DEV | M21: All devs building inside solutions | N21: 16.2, App. D | O21: Not started | P21: 0 | Q21: =IF(AND(O21<>"Complete",I21<TODAY()),"OVERDUE","")
A22: MO-05 | B22: 1 Design | C22: ALM | D22: Git repository and branching | E22: Create repo (/solutions, /powerbi, /docs, /test, /legacy); main/develop/feature branches; PR rule (Moses reviews); access for all 8. | F22: Moses Masibo | H22: 46308 | I22: 46310 | J22: =NETWORKDAYS(H22,I22,Holidays!$A$5:$A$12) -> 3 | K22: PM-05 | L22: Git repo | M22: First commit by every developer | N22: 16.3 | O22: Not started | P22: 0 | Q22: =IF(AND(O22<>"Complete",I22<TODAY()),"OVERDUE","")
A23: MO-06 | B23: 1 Design | C23: Data model | D23: Data-model review (34 tables, keys, alternate keys) | E23: Review with Denis: columns, choice sets, relationships, alternate keys (stk_localid, rule+key), audit settings. | F23: Moses Masibo | G23: Denis Otieno | H23: 46309 | I23: 46311 | J23: =NETWORKDAYS(H23,I23,Holidays!$A$5:$A$12) -> 3 | K23: MO-04 | L23: Approved ERD | M23: Signed off by Moses | N23: 6 | O23: Not started | P23: 0 | Q23: =IF(AND(O23<>"Complete",I23<TODAY()),"OVERDUE","")
A24: NI-01 | B24: 1 Design | C24: Data analysis | D24: Profile sample files from every feed | E24: For each file: row counts, keys, duplicates, blanks, grade/quality codes, units, date formats; compare to Appendix E templates. | F24: Nicole Akinyi | G24: Denis Otieno | H24: 46308 | I24: 46311 | J24: =NETWORKDAYS(H24,I24,Holidays!$A$5:$A$12) -> 4 | K24: PM-15 | L24: Profiling report | M24: Issues list sent to data owners | N24: 7.2, App. E | O24: Not started | P24: 0 | Q24: =IF(AND(O24<>"Complete",I24<TODAY()),"OVERDUE","")
A25: DO-01 | B25: 1 Design | C25: Data engineering | D25: Review ITB dataflows and staging | E25: Understand current dataflows → Dataverse staging → SharePoint lists; note reusable logic and known failures. | F25: Denis Otieno | G25: Moses Masibo | H25: 46307 | I25: 46308 | J25: =NETWORKDAYS(H25,I25,Holidays!$A$5:$A$12) -> 2 | K25: PM-05 | L25: Notes in Git /docs | M25: Reviewed with Moses | N25: 2 | O25: Not started | P25: 0 | Q25: =IF(AND(O25<>"Complete",I25<TODAY()),"OVERDUE","")
A26: DO-02 | B26: 1 Design | C26: Data engineering | D26: Finalise intake file templates and column mappings | E26: Agree exact column names per feed with owners; publish templates in STK-Intake/Templates. | F26: Denis Otieno | G26: Nicole Akinyi | H26: 46309 | I26: 46311 | J26: =NETWORKDAYS(H26,I26,Holidays!$A$5:$A$12) -> 3 | K26: NI-01 | L26: Templates S1–S15 | M26: Owners confirm they can produce them | N26: App. E | O26: Not started | P26: 0 | Q26: =IF(AND(O26<>"Complete",I26<TODAY()),"OVERDUE","")
A27: WI-01 | B27: 1 Design | C27: Stock Take app | D27: Review ITB Stock Take app | E27: Walk every screen and formula; note delegation warnings, performance, what to keep/rebuild. | F27: William Imo | H27: 46307 | I27: 46308 | J27: =NETWORKDAYS(H27,I27,Holidays!$A$5:$A$12) -> 2 | K27: PM-05 | L27: Review notes | M27: Shared at stand-up | N27: 9 | O27: Not started | P27: 0 | Q27: =IF(AND(O27<>"Complete",I27<TODAY()),"OVERDUE","")
A28: AN-01 | B28: 1 Design | C28: Hub | D28: Review ITB Stock Management app | E28: Admin, Import, Dashboard, Reports, Stock Takes approvals: document logic and data sources. | F28: Andrew Tanui | H28: 46307 | I28: 46308 | J28: =NETWORKDAYS(H28,I28,Holidays!$A$5:$A$12) -> 2 | K28: PM-05 | L28: Review notes | M28: Shared at stand-up | N28: 10 | O28: Not started | P28: 0 | Q28: =IF(AND(O28<>"Complete",I28<TODAY()),"OVERDUE","")
A29: JO-01 | B29: 1 Design | C29: Control Centre / Copilot | D29: Copilot Studio and model-driven readiness check | E29: Check Copilot Studio availability/licensing in tenant; list knowledge sources; draft model-driven site map. | F29: Jones Alukwe | G29: Moses Masibo | H29: 46307 | I29: 46308 | J29: =NETWORKDAYS(H29,I29,Holidays!$A$5:$A$12) -> 2 | K29: PM-16 | L29: Readiness note | M29: Input to OD8 | N29: 11, 14 | O29: Not started | P29: 0 | Q29: =IF(AND(O29<>"Complete",I29<TODAY()),"OVERDUE","")
A30: WI-02 | B30: 1 Design | C30: Shared UI | D30: Shared component library (NKG theme) | E30: Header, buttons, chips, tiles, input fields in NKG Green #006330 palette; published as component library for all canvas apps. | F30: William Imo | G30: Andrew Tanui | H30: 46308 | I30: 46309 | J30: =NETWORKDAYS(H30,I30,Holidays!$A$5:$A$12) -> 2 | K30: MO-04 | L30: Component library | M30: Used by Stock Take app and Hub | N30: 9.1 | O30: Not started | P30: 0 | Q30: =IF(AND(O30<>"Complete",I30<TODAY()),"OVERDUE","")
A31: FR-01 | B31: 1 Design | C31: Testing | D31: Test strategy and defect process | E31: Defect log (severity 1–4, owner, status), test case template, SIT script structure per area. | F31: Frankie Omasaja | G31: Daphne Okwaro | H31: 46308 | I31: 46311 | J31: =NETWORKDAYS(H31,I31,Holidays!$A$5:$A$12) -> 4 | K31: PM-04 | L31: Test strategy + defect log | M31: Approved by PM | N31: 18 | O31: Not started | P31: 0 | Q31: =IF(AND(O31<>"Complete",I31<TODAY()),"OVERDUE","")
A32: PM-20 | B32: 2 Sprint 1 | C32: Delivery | D32: Sprint 1 planning | E32: Assign Sprint 1 stories; confirm capacity (Mashujaa Day Tue 20 Oct is a public holiday). | F32: Daphne Okwaro | G32: All | H32: 46307 | I32: 46307 | J32: =NETWORKDAYS(H32,I32,Holidays!$A$5:$A$12) -> 1 | L32: Sprint 1 board | M32: Every story has owner and estimate | N32: 19 | O32: Not started | P32: 0 | Q32: =IF(AND(O32<>"Complete",I32<TODAY()),"OVERDUE","")
A33: MO-07 | B33: 2 Sprint 1 | C33: Environments | D33: Shared mailbox and SharePoint STK-Intake site | E33: With NKG IT: create mailbox stocktake.data@nkg.coffee; library STK-Intake with Incoming/Rejected/Processed/Templates; permissions for stk.svc. | F33: Moses Masibo | G33: Denis Otieno | H33: 46310 | I33: 46311 | J33: =NETWORKDAYS(H33,I33,Holidays!$A$5:$A$12) -> 2 | K33: PM-16 | L33: Mailbox + library | M33: Test email lands and is readable by flow | N33: 7.1 | O33: Not started | P33: 0 | Q33: =IF(AND(O33<>"Complete",I33<TODAY()),"OVERDUE","")
A34: DO-03 | B34: 2 Sprint 1 | C34: Data model | D34: Create Dataverse tables in STK Core | E34: Build 34 stk_ tables with columns, choices, alternate keys, relationships, auditing; stk_config seeded with keys. | F34: Denis Otieno | G34: Moses Masibo | H34: 46310 | I34: 46316 | J34: =NETWORKDAYS(H34,I34,Holidays!$A$5:$A$12) -> 4 | K34: MO-06 | L34: Tables in DEV | M34: ERD = DEV schema; solution exported to Git | N34: 6 | O34: Not started | P34: 0 | Q34: =IF(AND(O34<>"Complete",I34<TODAY()),"OVERDUE","")
A35: DO-04 | B35: 2 Sprint 1 | C35: Intake | D35: F01 Receive intake email | E35: Trigger on shared mailbox; parse subject; sender allow-list; save attachment as <SOURCE>_<YYYYMMDD>_<HHMM>.<ext>; log to stk_loadlog. | F35: Denis Otieno | H35: 46314 | I35: 46316 | J35: =NETWORKDAYS(H35,I35,Holidays!$A$5:$A$12) -> 2 | K35: MO-07, DO-03 | L35: Flow F01 | M35: 10 test emails processed correctly, bad sender rejected | N35: 12.2 | O35: Not started | P35: 0 | Q35: =IF(AND(O35<>"Complete",I35<TODAY()),"OVERDUE","")
A36: DO-05 | B36: 2 Sprint 1 | C36: Intake | D36: F02 Validate file (V1–V7) | E36: Columns, types, dates, row counts, duplicates, control totals, period; move to Rejected + reply with reason, or Processed + trigger load. | F36: Denis Otieno | G36: Nicole Akinyi | H36: 46316 | I36: 46318 | J36: =NETWORKDAYS(H36,I36,Holidays!$A$5:$A$12) -> 3 | K36: DO-04 | L36: Flow F02 | M36: Each V-rule has a failing test file that is rejected with the right reason | N36: 7.3 | O36: Not started | P36: 0 | Q36: =IF(AND(O36<>"Complete",I36<TODAY()),"OVERDUE","")
A37: DO-06 | B37: 2 Sprint 1 | C37: Intake | D37: Dataflows to staging + F03 load | E37: One dataflow per source (XBS stock, XBS movements, 526, 537, contracts, SNI, provisional, third-party); F03 refresh, poll, snapshot header, row-count check. | F37: Denis Otieno | H37: 46314 | I37: 46318 | J37: =NETWORKDAYS(H37,I37,Holidays!$A$5:$A$12) -> 4 | K37: DO-03 | L37: Dataflows + F03 | M37: T1 completeness passes for every sample file | N37: 7, 12.2 | O37: Not started | P37: 0 | Q37: =IF(AND(O37<>"Complete",I37<TODAY()),"OVERDUE","")
A38: DO-07 | B38: 2 Sprint 1 | C38: Master data | D38: Master-data migration | E38: Load warehouses, locations, zones, grades, quality codes, packing types, secondary/primary baskets, contracts, mappings from ITB lists and Comtras. | F38: Denis Otieno | G38: Nicole Akinyi | H38: 46316 | I38: 46318 | J38: =NETWORKDAYS(H38,I38,Holidays!$A$5:$A$12) -> 3 | K38: DO-03 | L38: Master data in DEV | M38: Counts tie to sources; T2 coverage report produced | N38: 7.5 | O38: Not started | P38: 0 | Q38: =IF(AND(O38<>"Complete",I38<TODAY()),"OVERDUE","")
A39: NI-02 | B39: 2 Sprint 1 | C39: Data analysis | D39: Mapping coverage analysis | E39: Outturn → grade → secondary → primary basket; list unmapped and conflicting outturns for Trade/QC with eq60 impact. | F39: Nicole Akinyi | G39: Denis Otieno | H39: 46310 | I39: 46316 | J39: =NETWORKDAYS(H39,I39,Holidays!$A$5:$A$12) -> 4 | K39: NI-01 | L39: Coverage report + unmapped list | M39: List sent to Trade and QC | N39: 8.2, 11.2 | O39: Not started | P39: 0 | Q39: =IF(AND(O39<>"Complete",I39<TODAY()),"OVERDUE","")
A40: NI-03 | B40: 2 Sprint 1 | C40: Testing | D40: Build test data sets | E40: Scenarios for every RI code and EX01–EX20: found-elsewhere, pockets, lights, timing, third-party, SNI, provisional, wrong basket, roll-over. | F40: Nicole Akinyi | G40: Frankie Omasaja | H40: 46314 | I40: 46318 | J40: =NETWORKDAYS(H40,I40,Holidays!$A$5:$A$12) -> 4 | K40: DO-02 | L40: Test data pack in Git /test | M40: Each scenario has expected result | N40: 8.4, 8.5, 18 | O40: Not started | P40: 0 | Q40: =IF(AND(O40<>"Complete",I40<TODAY()),"OVERDUE","")
A41: WI-03 | B41: 2 Sprint 1 | C41: Stock Take app | D41: S1 Sign-in/version check and S2 Home | E41: SSO, role & warehouse load, App.MinVersion check; Home tiles, banner with cut-off and time left. | F41: William Imo | H41: 46310 | I41: 46311 | J41: =NETWORKDAYS(H41,I41,Holidays!$A$5:$A$12) -> 2 | K41: WI-02 | L41: Screens S1–S2 | M41: Demoed at stand-up | N41: 9.2 | O41: Not started | P41: 0 | Q41: =IF(AND(O41<>"Complete",I41<TODAY()),"OVERDUE","")
...

Sheet Next Week 12-16 Oct
A1: Next week, day by day (Mon 12 – Fri 16 Oct)
A2: Daily stand-up 09:00. Design walkthrough with NKG on Tue 13 Oct.
A4: Person | B4: Mon 12 Oct | C4: Tue 13 Oct | D4: Wed 14 Oct | E4: Thu 15 Oct | F4: Fri 16 Oct
A5: Daphne Okwaro | B5: Sprint 1 planning 09:30; circulate BRD/spec/mockups (PM-11); send feed request (PM-15); NKG IT licensing email (PM-16) | C5: Create decision log; book calls with OD owners; prepare walkthrough deck | D5: Design walkthrough with NKG (PM-13); log feedback | E5: Chase feed samples and decisions; update BRD/spec to V1.2 | F5: Collect sign-offs (PM-14); steering check-in; weekly status #3
A6: Moses Masibo | B6: ITB inventory: export solution and flows (MO-01); request environments (MO-03) | C6: Finish ITB inventory; Git repo set-up (MO-05); ownership-transfer plan (MO-02) | D6: Walkthrough with NKG; create publisher + solutions (MO-04) | E6: Data-model review with Denis (MO-06); env-variable standards | F6: Mailbox/SharePoint with NKG IT (MO-07); approve ERD
A7: Denis Otieno | B7: Review ITB dataflows (DO-01); support feed request | C7: Finish dataflow review; list reusable logic | D7: Draft intake templates (DO-02); data-model review prep | E7: Data-model review with Moses; start Dataverse tables (DO-03) | F7: Templates agreed with owners; continue tables
A8: Nicole Akinyi | B8: Prepare profiling checklist; support decision log | C8: Profile first sample files received (NI-01) | D8: Continue profiling; issues list to owners | E8: Start mapping coverage analysis (NI-02) | F8: Profiling report final; coverage first cut
A9: William Imo | B9: Review ITB Stock Take app (WI-01) | C9: Finish review; start component library (WI-02) | D9: Walkthrough demo support; finish component library | E9: S1 Sign-in and version check (WI-03) | F9: S2 Home; demo at stand-up
A10: Andrew Tanui | B10: Review ITB Stock Management app (AN-01) | C10: Finish review; help William with component library | D10: Walkthrough demo support; plan Hub screens | E10: Admin screens: warehouses, grades (AN-02) | F10: Admin: packing types, unit rules, config editor
A11: Jones Alukwe | B11: Copilot Studio and model-driven readiness check (JO-01) | C11: Finish readiness note; draft site map | D11: Walkthrough demo support (mockups 04–07, 09) | E11: Model-driven app shell: site map (JO-02) | F11: Master-data forms and views
A12: Frankie Omasaja | B12: Read BRD, spec and mockups; set up defect log | C12: Test strategy draft (FR-01) | D12: Walkthrough: capture questions as test cases | E12: SIT script template per area | F12: Test strategy approved by PM

Sheet Gantt
A1: Gantt (weekly)
A2: Bars fill from Master Plan dates. Dark green = complete; light green = planned; red = overdue.
A4: ID | B4: Task | C4: Owner | D4: Start | E4: End | F4: Status | G4: 46293 | H4: 46300 | I4: 46307 | J4: 46314 | K4: 46321 | L4: 46328 | M4: 46335 | N4: 46342 | O4: 46349 | P4: 46356 | Q4: 46363 | R4: 46370
A5: =IF('Master Plan'!A5="","",'Master Plan'!A5) -> PM-01 | B5: =IF('Master Plan'!D5="","",'Master Plan'!D5) -> Project kick-off and warehouse walk-through | C5: =IF('Master Plan'!F5="","",'Master Plan'!F5) -> Daphne Okwaro | D5: =IF('Master Plan'!H5="","",'Master Plan'!H5) -> 46296 | E5: =IF('Master Plan'!I5="","",'Master Plan'!I5) -> 46296 | F5: =IF('Master Plan'!O5="","",'Master Plan'!O5) -> Complete
A6: =IF('Master Plan'!A6="","",'Master Plan'!A6) -> PM-02 | B6: =IF('Master Plan'!D6="","",'Master Plan'!D6) -> Discovery sessions: Finance, Warehouse & Operations, Trade & QC, Logistics | C6: =IF('Master Plan'!F6="","",'Master Plan'!F6) -> Daphne Okwaro | D6: =IF('Master Plan'!H6="","",'Master Plan'!H6) -> 46297 | E6: =IF('Master Plan'!I6="","",'Master Plan'!I6) -> 46303 | F6: =IF('Master Plan'!O6="","",'Master Plan'!O6) -> Complete
A7: =IF('Master Plan'!A7="","",'Master Plan'!A7) -> PM-03 | B7: =IF('Master Plan'!D7="","",'Master Plan'!D7) -> BRD V1.1 (red = items to confirm) | C7: =IF('Master Plan'!F7="","",'Master Plan'!F7) -> Daphne Okwaro | D7: =IF('Master Plan'!H7="","",'Master Plan'!H7) -> 46300 | E7: =IF('Master Plan'!I7="","",'Master Plan'!I7) -> 46304 | F7: =IF('Master Plan'!O7="","",'Master Plan'!O7) -> Complete
A8: =IF('Master Plan'!A8="","",'Master Plan'!A8) -> PM-04 | B8: =IF('Master Plan'!D8="","",'Master Plan'!D8) -> Developer Build Specification V1.0 + screen mockups | C8: =IF('Master Plan'!F8="","",'Master Plan'!F8) -> Daphne Okwaro | D8: =IF('Master Plan'!H8="","",'Master Plan'!H8) -> 46302 | E8: =IF('Master Plan'!I8="","",'Master Plan'!I8) -> 46304 | F8: =IF('Master Plan'!O8="","",'Master Plan'!O8) -> Complete
A9: =IF('Master Plan'!A9="","",'Master Plan'!A9) -> PM-05 | B9: =IF('Master Plan'!D9="","",'Master Plan'!D9) -> System access request sent (NKG emails, Power Platform, Git, ITB environment) | C9: =IF('Master Plan'!F9="","",'Master Plan'!F9) -> Daphne Okwaro | D9: =IF('Master Plan'!H9="","",'Master Plan'!H9) -> 46300 | E9: =IF('Master Plan'!I9="","",'Master Plan'!I9) -> 46301 | F9: =IF('Master Plan'!O9="","",'Master Plan'!O9) -> Complete
A10: =IF('Master Plan'!A10="","",'Master Plan'!A10) -> PM-06 | B10: =IF('Master Plan'!D10="","",'Master Plan'!D10) -> Weekly status report #1 | C10: =IF('Master Plan'!F10="","",'Master Plan'!F10) -> Daphne Okwaro | D10: =IF('Master Plan'!H10="","",'Master Plan'!H10) -> 46297 | E10: =IF('Master Plan'!I10="","",'Master Plan'!I10) -> 46297 | F10: =IF('Master Plan'!O10="","",'Master Plan'!O10) -> Complete
A11: =IF('Master Plan'!A11="","",'Master Plan'!A11) -> PM-10 | B11: =IF('Master Plan'!D11="","",'Master Plan'!D11) -> Weekly status report #2 | C11: =IF('Master Plan'!F11="","",'Master Plan'!F11) -> Daphne Okwaro | D11: =IF('Master Plan'!H11="","",'Master Plan'!H11) -> 46304 | E11: =IF('Master Plan'!I11="","",'Master Plan'!I11) -> 46304 | F11: =IF('Master Plan'!O11="","",'Master Plan'!O11) -> In progress
A12: =IF('Master Plan'!A12="","",'Master Plan'!A12) -> PM-11 | B12: =IF('Master Plan'!D12="","",'Master Plan'!D12) -> Circulate BRD V1.1, Build Spec and mockups to NKG for review | C12: =IF('Master Plan'!F12="","",'Master Plan'!F12) -> Daphne Okwaro | D12: =IF('Master Plan'!H12="","",'Master Plan'!H12) -> 46307 | E12: =IF('Master Plan'!I12="","",'Master Plan'!I12) -> 46307 | F12: =IF('Master Plan'!O12="","",'Master Plan'!O12) -> Not started
A13: =IF('Master Plan'!A13="","",'Master Plan'!A13) -> PM-12 | B13: =IF('Master Plan'!D13="","",'Master Plan'!D13) -> Open-decision log OD1–OD9 (red items) | C13: =IF('Master Plan'!F13="","",'Master Plan'!F13) -> Daphne Okwaro | D13: =IF('Master Plan'!H13="","",'Master Plan'!H13) -> 46307 | E13: =IF('Master Plan'!I13="","",'Master Plan'!I13) -> 46311 | F13: =IF('Master Plan'!O13="","",'Master Plan'!O13) -> Not started
A14: =IF('Master Plan'!A14="","",'Master Plan'!A14) -> PM-13 | B14: =IF('Master Plan'!D14="","",'Master Plan'!D14) -> Design walkthrough with NKG (mockups + zero-variance model) | C14: =IF('Master Plan'!F14="","",'Master Plan'!F14) -> Daphne Okwaro | D14: =IF('Master Plan'!H14="","",'Master Plan'!H14) -> 46308 | E14: =IF('Master Plan'!I14="","",'Master Plan'!I14) -> 46308 | F14: =IF('Master Plan'!O14="","",'Master Plan'!O14) -> Not started
A15: =IF('Master Plan'!A15="","",'Master Plan'!A15) -> PM-14 | B15: =IF('Master Plan'!D15="","",'Master Plan'!D15) -> Obtain BRD and design sign-off | C15: =IF('Master Plan'!F15="","",'Master Plan'!F15) -> Daphne Okwaro | D15: =IF('Master Plan'!H15="","",'Master Plan'!H15) -> 46309 | E15: =IF('Master Plan'!I15="","",'Master Plan'!I15) -> 46311 | F15: =IF('Master Plan'!O15="","",'Master Plan'!O15) -> Not started
A16: =IF('Master Plan'!A16="","",'Master Plan'!A16) -> PM-15 | B16: =IF('Master Plan'!D16="","",'Master Plan'!D16) -> Formal data-feed request to XBS and Comtras/BRIC owners | C16: =IF('Master Plan'!F16="","",'Master Plan'!F16) -> Daphne Okwaro | D16: =IF('Master Plan'!H16="","",'Master Plan'!H16) -> 46307 | E16: =IF('Master Plan'!I16="","",'Master Plan'!I16) -> 46309 | F16: =IF('Master Plan'!O16="","",'Master Plan'!O16) -> Not started
... A130: =IF('Master Plan'!A130="","",'Master Plan'!A130) -> PM-70 | B130: =IF('Master Plan'!D130="","",'Master Plan'!D130) -> Final acceptance and project close | C130: =IF('Master Plan'!F130="","",'Master Plan'!F130) -> Daphne Okwaro | D130: =IF('Master Plan'!H130="","",'Master Plan'!H130) -> 46370 | E130: =IF('Master Plan'!I130="","",'Master Plan'!I130) -> 46373 | F130: =IF('Master Plan'!O130="","",'Master Plan'!O130) -> Not started

Sheet Milestones
A1: Milestones
A2: Days to go counts calendar days from today.
A4: # | B4: Milestone | C4: Date | D4: Owner | E4: Status | F4: Days to go
A5: 1 | B5: Discovery complete | C5: 46304 | D5: Daphne Okwaro | E5: Complete | F5: =IF(E5="Complete","—",C5-TODAY()) -> —
A6: 2 | B6: BRD and design signed off | C6: 46311 | D6: Daphne Okwaro | E6: Planned | F6: =IF(E6="Complete","—",C6-TODAY()) -> 7
A7: 3 | B7: All open decisions OD1–OD9 closed | C7: 46318 | D7: Daphne Okwaro | E7: Planned | F7: =IF(E7="Complete","—",C7-TODAY()) -> 14
A8: 4 | B8: Feeds arriving automatically in DEV mailbox | C8: 46316 | D8: Denis Otieno | E8: Planned | F8: =IF(E8="Complete","—",C8-TODAY()) -> 12
A9: 5 | B9: Sprint 1 demo | C9: 46318 | D9: Daphne Okwaro | E9: Planned | F9: =IF(E9="Complete","—",C9-TODAY()) -> 14
A10: 6 | B10: October parallel count (count 2–4 Nov) | C10: 46330 | D10: Daphne Okwaro | E10: Planned | F10: =IF(E10="Complete","—",C10-TODAY()) -> 26
A11: 7 | B11: Sprint 2 demo / SIT exit | C11: 46332 | D11: Daphne Okwaro | E11: Planned | F11: =IF(E11="Complete","—",C11-TODAY()) -> 28
A12: 8 | B12: Training complete | C12: 46339 | D12: Daphne Okwaro | E12: Planned | F12: =IF(E12="Complete","—",C12-TODAY()) -> 35
A13: 9 | B13: UAT signed off + go/no-go | C13: 46353 | D13: Daphne Okwaro | E13: Planned | F13: =IF(E13="Complete","—",C13-TODAY()) -> 49
A14: 10 | B14: PROD final deployment | C14: 46356 | D14: Moses Masibo | E14: Planned | F14: =IF(E14="Complete","—",C14-TODAY()) -> 52
A15: 11 | B15: First live count closed (November) | C15: 46359 | D15: Daphne Okwaro | E15: Planned | F15: =IF(E15="Complete","—",C15-TODAY()) -> 55
A16: 12 | B16: First sign-off with residual = 0 (WD7) | C16: 46365 | D16: Daphne Okwaro | E16: Planned | F16: =IF(E16="Complete","—",C16-TODAY()) -> 61
... A18: 14 | B18: Final acceptance / go-live (business case) | C18: 46373 | D18: Daphne Okwaro | E18: Planned | F18: =IF(E18="Complete","—",C18-TODAY()) -> 69

Sheet NKG Actions
A1: What we need from NKG
A2: Send this list with the weekly status. Late items push the dependent task.
A4: ID | B4: What we need | C4: NKG owner | D4: Needed by | E4: Blocks our task | F4: Our task owner | G4: Status | H4: Days late
A5: NK-01 | B5: Review BRD V1.1, spec and mockups; send comments | C5: Carol, Maina, Mathew, Denis Koech, department leads | D5: 46309 | E5: PM-11 | F5: =INDEX('Master Plan'!$F$5:$F$130,MATCH(E5,'Master Plan'!$A$5:$A$130,0)) -> Daphne Okwaro | G5: Requested | H5: =IF(AND(G5<>"Received",TODAY()>D5),TODAY()-D5,"")
A6: NK-02 | B6: OD1 Cut-off rule (last 3 days posting window vs Day 1 download) | C6: Finance + Operations | D6: 46311 | E6: PM-12 | F6: =INDEX('Master Plan'!$F$5:$F$130,MATCH(E6,'Master Plan'!$A$5:$A$130,0)) -> Daphne Okwaro | G6: Requested | H6: =IF(AND(G6<>"Received",TODAY()>D6),TODAY()-D6,"")
A7: NK-03 | B7: OD2 Unit rule for pockets and lights | C7: Warehouse (Luis Brian) | D7: 46311 | E7: PM-12 | F7: =INDEX('Master Plan'!$F$5:$F$130,MATCH(E7,'Master Plan'!$A$5:$A$130,0)) -> Daphne Okwaro | G7: Requested | H7: =IF(AND(G7<>"Received",TODAY()>D7),TODAY()-D7,"")
A8: NK-04 | B8: OD3 Low Grade posting method in Comtras/BRIC | C8: Finance + Trade | D8: 46311 | E8: PM-12 | F8: =INDEX('Master Plan'!$F$5:$F$130,MATCH(E8,'Master Plan'!$A$5:$A$130,0)) -> Daphne Okwaro | G8: Requested | H8: =IF(AND(G8<>"Received",TODAY()>D8),TODAY()-D8,"")
A9: NK-05 | B9: OD4 Where provisional stock is shown | C9: Trade + Finance | D9: 46311 | E9: PM-12 | F9: =INDEX('Master Plan'!$F$5:$F$130,MATCH(E9,'Master Plan'!$A$5:$A$130,0)) -> Daphne Okwaro | G9: Requested | H9: =IF(AND(G9<>"Received",TODAY()>D9),TODAY()-D9,"")
A10: NK-06 | B10: OD5 Count tolerance (proposed 0 eq60) | C10: Operations | D10: 46311 | E10: PM-12 | F10: =INDEX('Master Plan'!$F$5:$F$130,MATCH(E10,'Master Plan'!$A$5:$A$130,0)) -> Daphne Okwaro | G10: Requested | H10: =IF(AND(G10<>"Received",TODAY()>D10),TODAY()-D10,"")
A11: NK-07 | B11: OD6 Write-off approval thresholds | C11: Finance | D11: 46318 | E11: PM-12 | F11: =INDEX('Master Plan'!$F$5:$F$130,MATCH(E11,'Master Plan'!$A$5:$A$130,0)) -> Daphne Okwaro | G11: Requested | H11: =IF(AND(G11<>"Received",TODAY()>D11),TODAY()-D11,"")
A12: NK-08 | B12: OD7 Sign-off order and signatories | C12: Finance | D12: 46318 | E12: PM-12 | F12: =INDEX('Master Plan'!$F$5:$F$130,MATCH(E12,'Master Plan'!$A$5:$A$130,0)) -> Daphne Okwaro | G12: Requested | H12: =IF(AND(G12<>"Received",TODAY()>D12),TODAY()-D12,"")
A13: NK-09 | B13: OD8 Copilot Studio approval and licensing | C13: NKG IT | D13: 46318 | E13: PM-12 | F13: =INDEX('Master Plan'!$F$5:$F$130,MATCH(E13,'Master Plan'!$A$5:$A$130,0)) -> Daphne Okwaro | G13: Requested | H13: =IF(AND(G13<>"Received",TODAY()>D13),TODAY()-D13,"")
A14: NK-10 | B14: OD9 Licences (Premium), service account, DEV/UAT/PROD environments | C14: NKG IT | D14: 46311 | E14: PM-16 | F14: =INDEX('Master Plan'!$F$5:$F$130,MATCH(E14,'Master Plan'!$A$5:$A$130,0)) -> Daphne Okwaro | G14: Requested | H14: =IF(AND(G14<>"Received",TODAY()>D14),TODAY()-D14,"")
A15: NK-11 | B15: Sample files for every feed (XBS stock & movements, 526, 537, contracts, SNI, provisional, third-party) | C15: XBS and Comtras/BRIC owners, Logistics | D15: 46309 | E15: PM-15 | F15: =INDEX('Master Plan'!$F$5:$F$130,MATCH(E15,'Master Plan'!$A$5:$A$130,0)) -> Daphne Okwaro | G15: Requested | H15: =IF(AND(G15<>"Received",TODAY()>D15),TODAY()-D15,"")
A16: NK-12 | B16: Scheduled daily emails of feeds to the shared mailbox at 07:00 | C16: XBS and Comtras/BRIC owners | D16: 46316 | E16: DO-04 | F16: =INDEX('Master Plan'!$F$5:$F$130,MATCH(E16,'Master Plan'!$A$5:$A$130,0)) -> Denis Otieno | G16: Requested | H16: =IF(AND(G16<>"Received",TODAY()>D16),TODAY()-D16,"")
... A24: NK-20 | B24: Approve opening baseline | C24: Finance + Operations | D24: 46358 | E24: DO-21 | F24: =INDEX('Master Plan'!$F$5:$F$130,MATCH(E24,'Master Plan'!$A$5:$A$130,0)) -> Denis Otieno | G24: Requested | H24: =IF(AND(G24<>"Received",TODAY()>D24),TODAY()-D24,"")

Sheet Meetings & Rhythm
A1: Meetings and working rhythm
A2: Location: Digitization Project Team Boardroom / Microsoft Teams Meeting
A4: Meeting / routine | B4: When | C4: Who | D4: Organiser | E4: Period | F4: Notes
A5: Daily stand-up (15 min) | B5: Every working day 09:00 | C5: All team | D5: Daphne Okwaro | E5: 12 Oct – 11 Dec | F5: Yesterday / today / blockers; update the plan statuses
A6: Weekly status report to NKG | B6: Every Friday | C6: NKG distribution list | D6: Daphne Okwaro | E6: 9 Oct – 11 Dec | F6: Word + email; RAG, progress, next week, decisions needed
A7: Decision chase (OD1–OD9) | B7: Daily until closed | C7: Decision owners | D7: Daphne Okwaro | E7: 12 – 23 Oct | F7: One message per open decision
A8: RAID log update | B8: Every Friday | C8: Team | D8: Daphne Okwaro | E8: 9 Oct – 11 Dec | F8: Risks, assumptions, issues, dependencies
A9: PR code review | B9: Within 1 working day of each PR | C9: Developers | D9: Moses Masibo | E9: 12 Oct – 11 Dec | F9: Naming, no hard-coded values, error handling
A10: Sprint planning | B10: Mon 12 Oct, Mon 26 Oct | C10: All team | D10: Daphne Okwaro | E10: — | F10: 1 hour
A11: Sprint review / demo to NKG | B11: Fri 23 Oct, Fri 6 Nov | C11: NKG + team | D11: Daphne Okwaro | E11: — | F11: 1 hour, Teams
A12: Steering check-in with sponsor | B12: Fri 16 Oct, 30 Oct, 13 Nov, 27 Nov, 11 Dec | C12: NKG sponsors | D12: Daphne Okwaro | E12: — | F12: 30 min
A13: UAT defect triage | B13: Daily 16:00 | C13: Team + UAT leads | D13: Daphne Okwaro | E13: 16 – 27 Nov | F13: Severity, owner, fix date
A14: Budget tracking | B14: Last Friday of month | C14: Pathways | D14: Daphne Okwaro | E14: Oct – Dec | F14: Against USD 24,753

Sheet Daphne
A1: Daphne Okwaro — Project Manager / Data Analytics Lead
A2: Owns: Plan, NKG decisions, access, stakeholder management, status reporting, SIT/UAT/training/cutover coordination. Live links to Master Plan — update status there.
A4: ID | B4: Phase | C4: Task | D4: Detailed description / steps | E4: Support | F4: Start | G4: End | H4: Work days | I4: Depends on | J4: Deliverable | K4: Done when | L4: Spec ref | M4: Status | N4: Overdue?
A5: =IF('Master Plan'!A5="","",'Master Plan'!A5) -> PM-01 | B5: =IF('Master Plan'!B5="","",'Master Plan'!B5) -> 0 Discovery | C5: =IF('Master Plan'!D5="","",'Master Plan'!D5) -> Project kick-off and warehouse walk-through | D5: =IF('Master Plan'!E5="","",'Master Plan'!E5) -> Kick-off with NKG; walk the warehouse floor; observe stacking, rows A–G / sections 1–14, bag tags, pockets, lights. | E5: =IF('Master Plan'!G5="","",'Master Plan'!G5) -> All | F5: =IF('Master Plan'!H5="","",'Master Plan'!H5) -> 46296 | G5: =IF('Master Plan'!I5="","",'Master Plan'!I5) -> 46296 | H5: =IF('Master Plan'!J5="","",'Master Plan'!J5) -> 1 | I5: =IF('Master Plan'!K5="","",'Master Plan'!K5) | J5: =IF('Master Plan'!L5="","",'Master Plan'!L5) -> Kick-off notes | K5: =IF('Master Plan'!M5="","",'Master Plan'!M5) -> Held with NKG stakeholders | L5: =IF('Master Plan'!N5="","",'Master Plan'!N5) -> — | M5: =IF('Master Plan'!O5="","",'Master Plan'!O5) -> Complete | N5: =IF('Master Plan'!Q5="","",'Master Plan'!Q5)
A6: =IF('Master Plan'!A10="","",'Master Plan'!A10) -> PM-06 | B6: =IF('Master Plan'!B10="","",'Master Plan'!B10) -> 0 Discovery | C6: =IF('Master Plan'!D10="","",'Master Plan'!D10) -> Weekly status report #1 | D6: =IF('Master Plan'!E10="","",'Master Plan'!E10) -> Status email (Word + HTML) to NKG. | E6: =IF('Master Plan'!G10="","",'Master Plan'!G10) | F6: =IF('Master Plan'!H10="","",'Master Plan'!H10) -> 46297 | G6: =IF('Master Plan'!I10="","",'Master Plan'!I10) -> 46297 | H6: =IF('Master Plan'!J10="","",'Master Plan'!J10) -> 1 | I6: =IF('Master Plan'!K10="","",'Master Plan'!K10) | J6: =IF('Master Plan'!L10="","",'Master Plan'!L10) -> Status report | K6: =IF('Master Plan'!M10="","",'Master Plan'!M10) -> Sent | L6: =IF('Master Plan'!N10="","",'Master Plan'!N10) -> — | M6: =IF('Master Plan'!O10="","",'Master Plan'!O10) -> Complete | N6: =IF('Master Plan'!Q10="","",'Master Plan'!Q10)
A7: =IF('Master Plan'!A6="","",'Master Plan'!A6) -> PM-02 | B7: =IF('Master Plan'!B6="","",'Master Plan'!B6) -> 0 Discovery | C7: =IF('Master Plan'!D6="","",'Master Plan'!D6) -> Discovery sessions: Finance, Warehouse & Operations, Trade & QC, Logistics | D7: =IF('Master Plan'!E6="","",'Master Plan'!E6) -> Run four sessions; record and transcribe; capture process, pain points, reports, data owners. | E7: =IF('Master Plan'!G6="","",'Master Plan'!G6) -> Moses Masibo, Denis Otieno, Nicole Akinyi | F7: =IF('Master Plan'!H6="","",'Master Plan'!H6) -> 46297 | G7: =IF('Master Plan'!I6="","",'Master Plan'!I6) -> 46303 | H7: =IF('Master Plan'!J6="","",'Master Plan'!J6) -> 5 | I7: =IF('Master Plan'!K6="","",'Master Plan'!K6) -> PM-01 | J7: =IF('Master Plan'!L6="","",'Master Plan'!L6) -> Recordings + notes | K7: =IF('Master Plan'!M6="","",'Master Plan'!M6) -> All four sessions held and transcribed | L7: =IF('Master Plan'!N6="","",'Master Plan'!N6) -> BRD | M7: =IF('Master Plan'!O6="","",'Master Plan'!O6) -> Complete | N7: =IF('Master Plan'!Q6="","",'Master Plan'!Q6)
A8: =IF('Master Plan'!A9="","",'Master Plan'!A9) -> PM-05 | B8: =IF('Master Plan'!B9="","",'Master Plan'!B9) -> 0 Discovery | C8: =IF('Master Plan'!D9="","",'Master Plan'!D9) -> System access request sent (NKG emails, Power Platform, Git, ITB environment) | D8: =IF('Master Plan'!E9="","",'Master Plan'!E9) -> Request NKG accounts for all 8 team members, environment maker access, Git, legacy ITB environment. | E8: =IF('Master Plan'!G9="","",'Master Plan'!G9) -> Moses Masibo | F8: =IF('Master Plan'!H9="","",'Master Plan'!H9) -> 46300 | G8: =IF('Master Plan'!I9="","",'Master Plan'!I9) -> 46301 | H8: =IF('Master Plan'!J9="","",'Master Plan'!J9) -> 2 | I8: =IF('Master Plan'!K9="","",'Master Plan'!K9) | J8: =IF('Master Plan'!L9="","",'Master Plan'!L9) -> Access request email | K8: =IF('Master Plan'!M9="","",'Master Plan'!M9) -> Sent; ITB environment access received | L8: =IF('Master Plan'!N9="","",'Master Plan'!N9) -> 16 | M8: =IF('Master Plan'!O9="","",'Master Plan'!O9) -> Complete | N8: =IF('Master Plan'!Q9="","",'Master Plan'!Q9)
A9: =IF('Master Plan'!A7="","",'Master Plan'!A7) -> PM-03 | B9: =IF('Master Plan'!B7="","",'Master Plan'!B7) -> 0 Discovery | C9: =IF('Master Plan'!D7="","",'Master Plan'!D7) -> BRD V1.1 (red = items to confirm) | D9: =IF('Master Plan'!E7="","",'Master Plan'!E7) -> Update the BRD from all recordings; mark unconfirmed items in red. | E9: =IF('Master Plan'!G7="","",'Master Plan'!G7) -> Nicole Akinyi | F9: =IF('Master Plan'!H7="","",'Master Plan'!H7) -> 46300 | G9: =IF('Master Plan'!I7="","",'Master Plan'!I7) -> 46304 | H9: =IF('Master Plan'!J7="","",'Master Plan'!J7) -> 5 | I9: =IF('Master Plan'!K7="","",'Master Plan'!K7) -> PM-02 | J9: =IF('Master Plan'!L7="","",'Master Plan'!L7) -> STOCKTAKE_BRD_V1.1.docx | K9: =IF('Master Plan'!M7="","",'Master Plan'!M7) -> Issued to team | L9: =IF('Master Plan'!N7="","",'Master Plan'!N7) -> BRD | M9: =IF('Master Plan'!O7="","",'Master Plan'!O7) -> Complete | N9: =IF('Master Plan'!Q7="","",'Master Plan'!Q7)
A10: =IF('Master Plan'!A8="","",'Master Plan'!A8) -> PM-04 | B10: =IF('Master Plan'!B8="","",'Master Plan'!B8) -> 0 Discovery | C10: =IF('Master Plan'!D8="","",'Master Plan'!D8) -> Developer Build Specification V1.0 + screen mockups | D10: =IF('Master Plan'!E8="","",'Master Plan'!E8) -> Write the build specification (Sections 1–22 + appendices) and 10 screen mockups. | E10: =IF('Master Plan'!G8="","",'Master Plan'!G8) -> Moses Masibo | F10: =IF('Master Plan'!H8="","",'Master Plan'!H8) -> 46302 | G10: =IF('Master Plan'!I8="","",'Master Plan'!I8) -> 46304 | H10: =IF('Master Plan'!J8="","",'Master Plan'!J8) -> 3 | I10: =IF('Master Plan'!K8="","",'Master Plan'!K8) -> PM-03 | J10: =IF('Master Plan'!L8="","",'Master Plan'!L8) -> Spec V1.0 + mockups PDF | K10: =IF('Master Plan'!M8="","",'Master Plan'!M8) -> Issued to team | L10: =IF('Master Plan'!N8="","",'Master Plan'!N8) -> All | M10: =IF('Master Plan'!O8="","",'Master Plan'!O8) -> Complete | N10: =IF('Master Plan'!Q8="","",'Master Plan'!Q8)
A11: =IF('Master Plan'!A11="","",'Master Plan'!A11) -> PM-10 | B11: =IF('Master Plan'!B11="","",'Master Plan'!B11) -> 1 Design | C11: =IF('Master Plan'!D11="","",'Master Plan'!D11) -> Weekly status report #2 | D11: =IF('Master Plan'!E11="","",'Master Plan'!E11) -> Progress: discovery complete, BRD V1.1, build spec, mockups; next week: design sign-off, decisions OD1–OD9, sprint 1 start. | E11: =IF('Master Plan'!G11="","",'Master Plan'!G11) | F11: =IF('Master Plan'!H11="","",'Master Plan'!H11) -> 46304 | G11: =IF('Master Plan'!I11="","",'Master Plan'!I11) -> 46304 | H11: =IF('Master Plan'!J11="","",'Master Plan'!J11) -> 1 | I11: =IF('Master Plan'!K11="","",'Master Plan'!K11) -> PM-04 | J11: =IF('Master Plan'!L11="","",'Master Plan'!L11) -> Status report | K11: =IF('Master Plan'!M11="","",'Master Plan'!M11) -> Sent to NKG distribution list | L11: =IF('Master Plan'!N11="","",'Master Plan'!N11) -> — | M11: =IF('Master Plan'!O11="","",'Master Plan'!O11) -> In progress | N11: =IF('Master Plan'!Q11="","",'Master Plan'!Q11)
A12: =IF('Master Plan'!A12="","",'Master Plan'!A12) -> PM-11 | B12: =IF('Master Plan'!B12="","",'Master Plan'!B12) -> 1 Design | C12: =IF('Master Plan'!D12="","",'Master Plan'!D12) -> Circulate BRD V1.1, Build Spec and mockups to NKG for review | D12: =IF('Master Plan'!E12="","",'Master Plan'!E12) -> Email to Carol, Maina, Mathew, Denis Koech, department leads; ask for written comments by Wed 14 Oct; attach mockups PDF. | E12: =IF('Master Plan'!G12="","",'Master Plan'!G12) | F12: =IF('Master Plan'!H12="","",'Master Plan'!H12) -> 46307 | G12: =IF('Master Plan'!I12="","",'Master Plan'!I12) -> 46307 | H12: =IF('Master Plan'!J12="","",'Master Plan'!J12) -> 1 | I12: =IF('Master Plan'!K12="","",'Master Plan'!K12) -> PM-04 | J12: =IF('Master Plan'!L12="","",'Master Plan'!L12) -> Review email | K12: =IF('Master Plan'!M12="","",'Master Plan'!M12) -> Sent; every reviewer acknowledged | L12: =IF('Master Plan'!N12="","",'Master Plan'!N12) -> — | M12: =IF('Master Plan'!O12="","",'Master Plan'!O12) -> Not started | N12: =IF('Master Plan'!Q12="","",'Master Plan'!Q12)
A13: =IF('Master Plan'!A32="","",'Master Plan'!A32) -> PM-20 | B13: =IF('Master Plan'!B32="","",'Master Plan'!B32) -> 2 Sprint 1 | C13: =IF('Master Plan'!D32="","",'Master Plan'!D32) -> Sprint 1 planning | D13: =IF('Master Plan'!E32="","",'Master Plan'!E32) -> Assign Sprint 1 stories; confirm capacity (Mashujaa Day Tue 20 Oct is a public holiday). | E13: =IF('Master Plan'!G32="","",'Master Plan'!G32) -> All | F13: =IF('Master Plan'!H32="","",'Master Plan'!H32) -> 46307 | G13: =IF('Master Plan'!I32="","",'Master Plan'!I32) -> 46307 | H13: =IF('Master Plan'!J32="","",'Master Plan'!J32) -> 1 | I13: =IF('Master Plan'!K32="","",'Master Plan'!K32) | J13: =IF('Master Plan'!L32="","",'Master Plan'!L32) -> Sprint 1 board | K13: =IF('Master Plan'!M32="","",'Master Plan'!M32) -> Every story has owner and estimate | L13: =IF('Master Plan'!N32="","",'Master Plan'!N32) -> 19 | M13: =IF('Master Plan'!O32="","",'Master Plan'!O32) -> Not started | N13: =IF('Master Plan'!Q32="","",'Master Plan'!Q32)
A14: =IF('Master Plan'!A16="","",'Master Plan'!A16) -> PM-15 | B14: =IF('Master Plan'!B16="","",'Master Plan'!B16) -> 1 Design | C14: =IF('Master Plan'!D16="","",'Master Plan'!D16) -> Formal data-feed request to XBS and Comtras/BRIC owners | D14: =IF('Master Plan'!E16="","",'Master Plan'!E16) -> Request: (1) sample files for every feed S1–S15 by 14 Oct; (2) scheduled daily email to shared mailbox at 07:00 with subject STK|<SOURCE>|<YYYYMMDD>|<HHMM>; (3) named backup sender. | E14: =IF('Master Plan'!G16="","",'Master Plan'!G16) -> Denis Otieno | F14: =IF('Master Plan'!H16="","",'Master Plan'!H16) -> 46307 | G14: =IF('Master Plan'!I16="","",'Master Plan'!I16) -> 46309 | H14: =IF('Master Plan'!J16="","",'Master Plan'!J16) -> 3 | I14: =IF('Master Plan'!K16="","",'Master Plan'!K16) | J14: =IF('Master Plan'!L16="","",'Master Plan'!L16) -> Feed request email + owner list | K14: =IF('Master Plan'!M16="","",'Master Plan'!M16) -> Every feed has a named owner and a start date | L14: =IF('Master Plan'!N16="","",'Master Plan'!N16) -> 7.1–7.2 | M14: =IF('Master Plan'!O16="","",'Master Plan'!O16) -> Not started | N14: =IF('Master Plan'!Q16="","",'Master Plan'!Q16)
