Workbook

Sheet Tool Decisions
A1: Tool decisions — what we use and why
A2: Prepared 9 Oct 2026 · Pathways Technologies for NKG East Africa
A4: Layer | B4: Tool | C4: Why | D4: When we would change
A5: Operational data store | B5: Dataverse | C5: The apps, flows, approvals, audit and security all need a transactional store. Dataverse gives alternate keys (no duplicates), field security, audit and business process flows out of the box. | D5: Not expected to change.
A6: Data intake (now) | B6: Email → SharePoint → Power Query dataflow → Dataverse | C6: No API access to XBS or Comtras today. Scheduled report emails are fully automatic once the senders are scheduled, and need no IT integration. | D6: Swap to API/gateway per source when NKG grants access (C12, C13).
A7: Data intake (target) | B7: Custom connector (REST API) or on-premises data gateway (SQL view) | C7: Removes the email dependency and gives near real-time data. | D7: When XBS/Comtras API or read-only DB access is approved.
A8: Reconciliation engine | B8: Power Query dataflows + Power Automate on Dataverse | C8: Volumes (~1,000 outturns, ~50k lines per snapshot) fit comfortably; one platform to support. | D8: Move to a Fabric notebook only if the performance test (MO-13) misses the 30-minute target.
A9: Microsoft Fabric | B9: Optional, phase 2 | C9: Not required to deliver zero-variance reconciliation. Useful for long history, trends and Direct Lake reporting if NKG already has Fabric capacity. | D9: Confirm whether NKG has a Fabric capacity (F-SKU); if yes, enable Dataverse Link to Fabric after go-live.
A10: Apps | B10: Power Apps canvas (Stock Take app, Hub) + model-driven (Control Centre) | C10: Canvas for mobile counting and operational screens; model-driven for finance-grade forms, views, BPFs and audit. | D10: —
A11: Automation | B11: Power Automate cloud flows | C11: Native to Dataverse, Outlook, SharePoint, Teams and Approvals; owned by service account. | D11: —
A12: Reporting | B12: Power BI (Dataverse connector, PBIP in Git) | C12: Standard NKG reporting tool; RLS; embedded in Control Centre. | D12: Direct Lake if Fabric is adopted.
A13: AI assistant | B13: Copilot Studio | C13: Read-only assistant in Teams and the Control Centre, answers from Dataverse with the user's own permissions. | D13: Depends on Copilot approval/licensing (OD8); fallback = search and views.
A14: ALM | B14: Solutions, pac CLI, pipelines, Git | C14: Repeatable deployments DEV → UAT → PROD; no dependency on any personal account. | D14: —
A16: Discipline colours
A17: Power Apps
A18: Power Automate
A19: UI
A20: UX
A21: Data Engineering
A22: Data Analyst
A23: Copilot
A24: Architecture / ALM
A25: Testing / QA

Sheet Development Tasks
A1: Stocktake Optimization — Development Task Matrix
A2: Every build task, the discipline it belongs to, the tool used and how it connects. Red = to confirm with NKG. Plan ID links to STOCKTAKE_Team_Work_Plan.xlsx.
A4: Dev ID | B4: Module | C4: Development task | D4: What is built | E4: Discipline | F4: Tool / platform | G4: How (integration method) | H4: Now vs target | I4: Owner | J4: Work-plan ID | K4: Start | L4: End | M4: Work days | N4: Licence needed | O4: Status
A5: A01 | B5: Foundation | C5: Set up DEV / UAT / PROD environments with Dataverse | D5: Three environments, Dataverse database, region, admins | E5: Architecture / ALM | F5: Power Platform Admin Center | G5: Admin centre configuration (manual, scripted later with pac admin) | H5: Now | I5: Moses Masibo | J5: MO-03 | K5: 46307 | L5: 46311 | M5: =IFERROR(NETWORKDAYS(K5,L5,DATE(2026,10,20)),"") -> 5 | N5: Power Apps/Automate Premium | O5: Not started
A6: A02 | B6: Foundation | C6: DLP policy | D6: Business group: Dataverse, SharePoint, Outlook, Teams, Approvals, Power BI, Copilot Studio; block consumer connectors | E6: Architecture / ALM | F6: Power Platform Admin Center | G6: Tenant/environment DLP policy | H6: Now | I6: Moses Masibo | J6: MO-03 | K6: 46307 | L6: 46311 | M6: =IFERROR(NETWORKDAYS(K6,L6,DATE(2026,10,20)),"") -> 5 | N6: Standard M365 | O6: Not started
A7: A03 | B7: Foundation | C7: Publisher (prefix stk) and 4 solutions | D7: STK Core, STK Apps, STK Automation, STK Copilot | E7: Architecture / ALM | F7: Power Apps maker portal (Solutions) | G7: Solution framework | H7: Now | I7: Moses Masibo | J7: MO-04 | K7: 46309 | L7: 46310 | M7: =IFERROR(NETWORKDAYS(K7,L7,DATE(2026,10,20)),"") -> 2 | N7: Power Apps/Automate Premium | O7: Not started
A8: A04 | B8: Foundation | C8: Environment variables and connection references | D8: Mailbox, SharePoint URL, thresholds, Teams channel; one connection reference per connector | E8: Architecture / ALM | F8: Dataverse solution components | G8: Deployment settings JSON per environment | H8: Now | I8: Moses Masibo | J8: MO-04 | K8: 46310 | L8: 46311 | M8: =IFERROR(NETWORKDAYS(K8,L8,DATE(2026,10,20)),"") -> 2 | N8: Power Apps/Automate Premium | O8: Not started
A9: A05 | B9: Foundation | C9: Service account stk.svc | D9: Owns all flows/connections; licensed; MFA exception for automation | E9: Architecture / ALM | F9: Entra ID + M365 admin | G9: Admin set-up by NKG IT | H9: Now | I9: Moses Masibo | J9: PM-16 | K9: 46307 | L9: 46311 | M9: =IFERROR(NETWORKDAYS(K9,L9,DATE(2026,10,20)),"") -> 5 | N9: Power Apps/Automate Premium | O9: Not started
A10: A06 | B10: Foundation | C10: Git repository and branching | D10: /solutions /powerbi /docs /test /legacy; main/develop/feature; PR review | E10: Architecture / ALM | F10: Azure DevOps or GitHub — confirm | G10: Git + pac solution unpack | H10: Now | I10: Moses Masibo | J10: MO-05 | K10: 46308 | L10: 46310 | M10: =IFERROR(NETWORKDAYS(K10,L10,DATE(2026,10,20)),"") -> 3 | N10: Standard M365 | O10: Not started
A11: A07 | B11: Foundation | C11: Build and release pipeline | D11: Export → unpack → commit → managed build → deploy UAT/PROD | E11: Architecture / ALM | F11: Power Platform Pipelines / pac CLI in DevOps | G11: pac CLI + Power Platform Build Tools | H11: Now | I11: Moses Masibo | J11: MO-09 | K11: 46316 | L11: 46318 | M11: =IFERROR(NETWORKDAYS(K11,L11,DATE(2026,10,20)),"") -> 3 | N11: Power Apps/Automate Premium | O11: Not started
A12: A08 | B12: Foundation | C12: Security roles and Entra groups | D12: 10 roles, SG-STK-<Role> groups mapped to Dataverse teams | E12: Architecture / ALM | F12: Dataverse security + Entra ID | G12: Group teams (Entra group sync) | H12: Now | I12: Moses Masibo | J12: MO-08 | K12: 46314 | L12: 46318 | M12: =IFERROR(NETWORKDAYS(K12,L12,DATE(2026,10,20)),"") -> 4 | N12: Power Apps/Automate Premium | O12: Not started
A13: A09 | B13: Foundation | C13: Field-level security and auditing | D13: Hide expected qty from counters; protect approvals/config; audit on all stk_ tables | E13: Architecture / ALM | F13: Dataverse | G13: Field security profiles + audit settings | H13: Now | I13: Moses Masibo | J13: MO-08 | K13: 46314 | L13: 46318 | M13: =IFERROR(NETWORKDAYS(K13,L13,DATE(2026,10,20)),"") -> 4 | N13: Power Apps/Automate Premium | O13: Not started
A14: A10 | B14: Foundation | C14: Take over ITB solution | D14: Export managed solution, transfer flow/app ownership to stk.svc, store in Git /legacy | E14: Architecture / ALM | F14: Power Platform Admin Center | G14: Admin ownership change + solution export | H14: Now | I14: Moses Masibo | J14: MO-01, MO-02 | K14: 46307 | L14: 46309 | M14: =IFERROR(NETWORKDAYS(K14,L14,DATE(2026,10,20)),"") -> 3 | N14: Power Apps/Automate Premium | O14: Not started
A15: A11 | B15: Foundation | C15: Health monitoring and housekeeping (F40, F41) | D15: Hourly flow health check; weekly archive and purge | E15: Power Automate | F15: Power Automate cloud flows | G15: Power Platform for Admins connector + Dataverse connector | H15: Now | I15: Moses Masibo | J15: MO-11 | K15: 46328 | L15: 46330 | M15: =IFERROR(NETWORKDAYS(K15,L15,DATE(2026,10,20)),"") -> 3 | N15: Power Apps/Automate Premium | O15: Not started
A16: B01 | B16: Data model | C16: Reference tables | D16: stk_warehouse, location, zone, grade, qualitycode, packingtype, config | E16: Data Engineering | F16: Dataverse | G16: Table design in solution | H16: Now | I16: Denis Otieno | J16: DO-03 | K16: 46310 | L16: 46316 | M16: =IFERROR(NETWORKDAYS(K16,L16,DATE(2026,10,20)),"") -> 4 | N16: Power Apps/Automate Premium | O16: Not started
... A33: C11 | B33: Data intake | C33: Manual upload fallback | D33: Hub screen uploads file into Incoming so the same validation runs | E33: Power Apps | F33: Power Apps canvas (Hub) | G33: Attachment control → flow → SharePoint create file | H33: Now | I33: Andrew Tanui | J33: AN-10 | K33: 46331 | L33: 46332 | M33: =IFERROR(NETWORKDAYS(K33,L33,DATE(2026,10,20)),"") -> 2 | N33: Power Apps/Automate Premium | O33: Not started
A34: C12 | B34: Data intake | C34: XBS API custom connector | D34: Replace email intake for XBS when API/DB access is granted; downstream unchanged | E34: Data Engineering | F34: Power Platform custom connector (or on-premises data gateway) | G34: REST API (OpenAPI definition) or SQL via on-premises data gateway | H34: Target (when NKG grants API access) | I34: Denis Otieno | J34: — | K34: TBC | L34: TBC | M34: =IFERROR(NETWORKDAYS(K34,L34,DATE(2026,10,20)),"") | N34: Power Apps/Automate Premium | O34: Not started
A35: C13 | B35: Data intake | C35: Comtras/BRIC API custom connector | D35: Same as C12 for 526/537/contracts | E35: Data Engineering | F35: Power Platform custom connector / gateway | G35: REST API or SQL read-only view via gateway | H35: Target (when NKG grants API access) | I35: Denis Otieno | J35: — | K35: TBC | L35: TBC | M35: =IFERROR(NETWORKDAYS(K35,L35,DATE(2026,10,20)),"") | N35: Power Apps/Automate Premium | O35: Not started
A36: C14 | B36: Data intake | C36: Optional: Fabric ingestion pipeline | D36: If volumes grow: Data Factory pipeline lands files/API data in Lakehouse, Dataflow Gen2 writes curated tables | E36: Data Engineering | F36: Microsoft Fabric (Data Factory, Dataflow Gen2) | G36: Pipeline copy activity / REST / SQL connector | H36: Target (phase 2, optional) | I36: Denis Otieno | J36: — | K36: TBC | L36: TBC | M36: =IFERROR(NETWORKDAYS(K36,L36,DATE(2026,10,20)),"") | N36: Fabric capacity (F-SKU) — confirm NKG has it | O36: Not started
A37: D01 | B37: Master data | C37: Migrate reference data from ITB SharePoint lists | D37: Warehouses, locations, grades, packing types | E37: Data Engineering | F37: Power Query dataflow → Dataverse | G37: SharePoint list connector (one-off load) | H37: Now | I37: Denis Otieno | J37: DO-07 | K37: 46316 | L37: 46318 | M37: =IFERROR(NETWORKDAYS(K37,L37,DATE(2026,10,20)),"") -> 3 | N37: Power Apps/Automate Premium | O37: Not started
A38: D02 | B38: Master data | C38: Load baskets, contracts and mappings | D38: Secondary → primary baskets; outturn → grade → basket mapping | E38: Data Engineering | F38: Power Query dataflow → Dataverse | G38: Excel extracts from Comtras (file) → dataflow | H38: Now | I38: Denis Otieno | J38: DO-07 | K38: 46316 | L38: 46318 | M38: =IFERROR(NETWORKDAYS(K38,L38,DATE(2026,10,20)),"") -> 3 | N38: Power Apps/Automate Premium | O38: Not started
A39: D03 | B39: Master data | C39: Mapping coverage analysis | D39: Unmapped/conflicting outturns with eq60 impact for Trade/QC | E39: Data Analyst | F39: Power BI Desktop / Excel | G39: Dataverse connector (Power Query) | H39: Now | I39: Nicole Akinyi | J39: NI-02 | K39: 46310 | L39: 46316 | M39: =IFERROR(NETWORKDAYS(K39,L39,DATE(2026,10,20)),"") -> 4 | N39: Power BI Pro | O39: Not started
A40: D04 | B40: Master data | C40: Data profiling of sample files | D40: Row counts, keys, duplicates, blanks, codes vs templates | E40: Data Analyst | F40: Power Query / Excel (or Fabric notebook if available) | G40: File-based profiling | H40: Now | I40: Nicole Akinyi | J40: NI-01 | K40: 46308 | L40: 46311 | M40: =IFERROR(NETWORKDAYS(K40,L40,DATE(2026,10,20)),"") -> 4 | N40: Standard M365 | O40: Not started
A41: E01 | B41: Engine | C41: Normalisation (units, kg, eq60) | D41: Apply unit rules and packing nominal kg to every position | E41: Data Engineering | F41: Power Query dataflow → Dataverse | G41: Computed columns in dataflow (one rule set) | H41: Now | I41: Denis Otieno | J41: DO-09 | K41: 46321 | L41: 46323 | M41: =IFERROR(NETWORKDAYS(K41,L41,DATE(2026,10,20)),"") -> 3 | N41: Power Apps/Automate Premium | O41: Not started
A42: E02 | B42: Engine | C42: Mass balance | D42: Opening + receipts − issues ± adjustments = closing per outturn | E42: Data Engineering | F42: Power Query dataflow → Dataverse | G42: Group/merge in dataflow; results to stk_reconline | H42: Now | I42: Denis Otieno | J42: DO-09 | K42: 46321 | L42: 46323 | M42: =IFERROR(NETWORKDAYS(K42,L42,DATE(2026,10,20)),"") -> 3 | N42: Power Apps/Automate Premium | O42: Not started
A43: E03 | B43: Engine | C43: L1 Physical vs XBS | D43: Count vs locked snapshot; attach reconciling items in fixed order; EX01/EX02 | E43: Data Engineering | F43: Dataflow + Power Automate (F30) | G43: Dataverse connector; child flows per RI rule | H43: Now | I43: Denis Otieno | J43: DO-10 | K43: 46322 | L43: 46324 | M43: =IFERROR(NETWORKDAYS(K43,L43,DATE(2026,10,20)),"") -> 3 | N43: Power Apps/Automate Premium | O43: Not started
A44: E04 | B44: Engine | C44: L2 XBS vs Comtras | D44: SNI add-back, provisional, registers; RI DOWNGRADE, WRONG-BASKET, ROLLOVER etc.; EX15 | E44: Data Engineering | F44: Dataflow + Power Automate | G44: Dataverse connector | H44: Now | I44: Denis Otieno | J44: DO-11 | K44: 46324 | L44: 46329 | M44: =IFERROR(NETWORKDAYS(K44,L44,DATE(2026,10,20)),"") -> 4 | N44: Power Apps/Automate Premium | O44: Not started
A45: E05 | B45: Engine | C45: L3 Baskets vs Contracts | D45: Basket balances vs contract open qty with lineage | E45: Data Engineering | F45: Dataflow + Power Automate | G45: Dataverse connector | H45: Now | I45: Denis Otieno | J45: DO-12 | K45: 46328 | L45: 46330 | M45: =IFERROR(NETWORKDAYS(K45,L45,DATE(2026,10,20)),"") -> 3 | N45: Power Apps/Automate Premium | O45: Not started
A46: E06 | B46: Engine | C46: Residual calculation and run log | D46: Residual = raw − Σ RI − Σ posted corrections; stk_reconrun header | E46: Data Engineering | F46: Dataverse (rollup/calculated) + flow | G46: Dataverse Web API via connector | H46: Now | I46: Denis Otieno | J46: DO-10 | K46: 46322 | L46: 46324 | M46: =IFERROR(NETWORKDAYS(K46,L46,DATE(2026,10,20)),"") -> 3 | N46: Power Apps/Automate Premium | O46: Not started
A47: E07 | B47: Engine | C47: Optional: engine in Fabric notebook | D47: If Dataverse/flow run time exceeds NFR-02 at full volume, move L1–L3 to a PySpark/SQL notebook writing back to Dataverse | E47: Data Engineering | F47: Microsoft Fabric notebook (optional) | G47: Link to Fabric + Dataverse Web API write-back | H47: Fallback only if performance test fails | I47: Denis Otieno | J47: MO-13 | K47: TBC | L47: TBC | M47: =IFERROR(NETWORKDAYS(K47,L47,DATE(2026,10,20)),"") | N47: Fabric capacity (F-SKU) — confirm NKG has it | O47: Not started
A48: F01 | B48: Rules | C48: F20 Daily rules run EX05–EX20 | D48: Mass balance and rule checks at 08:15 | E48: Power Automate | F48: Power Automate cloud flow | G48: Recurrence trigger + Dataverse connector + child flows | H48: Now | I48: Denis Otieno | J48: DO-13 | K48: 46323 | L48: 46330 | M48: =IFERROR(NETWORKDAYS(K48,L48,DATE(2026,10,20)),"") -> 6 | N48: Power Apps/Automate Premium | O48: Not started
A49: F02 | B49: Rules | C49: Exception upsert child flow | D49: Upsert on alternate key rule+key; auto-close when cleared | E49: Power Automate | F49: Power Automate child flow | G49: Dataverse "Upsert a row" (alternate key) | H49: Now | I49: Denis Otieno | J49: DO-13 | K49: 46323 | L49: 46330 | M49: =IFERROR(NETWORKDAYS(K49,L49,DATE(2026,10,20)),"") -> 6 | N49: Power Apps/Automate Premium | O49: Not started
A50: F03 | B50: Rules | C50: F21 Exception notifications and escalation | D50: Owner alerts, 16:00 reminders, escalate after SLA × 2 | E50: Power Automate | F50: Power Automate cloud flow | G50: Teams connector (adaptive card) + Outlook connector | H50: Now | I50: Jones Alukwe | J50: JO-05 | K50: 46322 | L50: 46324 | M50: =IFERROR(NETWORKDAYS(K50,L50,DATE(2026,10,20)),"") -> 3 | N50: Standard M365 | O50: Not started
A51: F04 | B51: Rules | C51: F23 Provisional auto-match; F28 correction posting check | D51: Close provisional on XBS receipt; confirm corrections from next snapshot / EX13 | E51: Power Automate | F51: Power Automate cloud flows | G51: Dataverse "When a row is added" trigger | H51: Now | I51: Denis Otieno | J51: DO-14 | K51: 46329 | L51: 46331 | M51: =IFERROR(NETWORKDAYS(K51,L51,DATE(2026,10,20)),"") -> 3 | N51: Power Apps/Automate Premium | O51: Not started
A52: G01 | B52: UX | C52: User personas and journeys | D52: Counter, supervisor, Ops admin, Trade, QC, Logistics, Finance, Management — tasks and pain points from discovery | E52: UX | F52: Figma / PowerPoint | G52: Workshop output from discovery recordings | H52: Now | I52: William Imo | J52: PM-13 | K52: 46307 | L52: 46308 | M52: =IFERROR(NETWORKDAYS(K52,L52,DATE(2026,10,20)),"") -> 2 | N52: Standard M365 | O52: Not started
A53: G02 | B53: UX | C53: Wireframes and clickable prototype | D53: Based on the 10 mockups; refine after NKG walkthrough | E53: UX | F53: Figma (or Power Apps prototype) | G53: Design review with NKG | H53: Now | I53: William Imo | J53: PM-13 | K53: 46307 | L53: 46309 | M53: =IFERROR(NETWORKDAYS(K53,L53,DATE(2026,10,20)),"") -> 3 | N53: Standard M365 | O53: Not started
A54: G03 | B54: UX | C54: Count journey design (blind count, found-elsewhere, offline) | D54: One location at a time; 3 taps per line target; error states | E54: UX | F54: Figma | G54: Usability walk-through with 2 counters on the floor | H54: Now | I54: William Imo | J54: WI-05 | K54: 46309 | L54: 46311 | M54: =IFERROR(NETWORKDAYS(K54,L54,DATE(2026,10,20)),"") -> 3 | N54: Standard M365 | O54: Not started
A55: G04 | B55: UX | C55: Reconciliation workspace journey | D55: Summary-first, drill-down, side panel evidence; residual always visible | E55: UX | F55: Figma | G55: Review with Finance | H55: Now | I55: Jones Alukwe | J55: JO-06 | K55: 46321 | L55: 46322 | M55: =IFERROR(NETWORKDAYS(K55,L55,DATE(2026,10,20)),"") -> 2 | N55: Standard M365 | O55: Not started
A56: G05 | B56: UX | C56: Usability tests | D56: Counters (phone, gloves, far zones), supervisors, Finance; SUS score ≥ 70 | E56: UX | F56: Power Apps (UAT build) | G56: Moderated test sessions | H56: Now | I56: Frankie Omasaja | J56: WI-10 | K56: 46329 | L56: 46331 | M56: =IFERROR(NETWORKDAYS(K56,L56,DATE(2026,10,20)),"") -> 3 | N56: Standard M365 | O56: Not started
A57: G06 | B57: UX | C57: Accessibility review | D57: Font ≥ 16 pt, contrast, colour not only signal, 44 px targets | E57: UX | F57: Power Apps Accessibility checker | G57: App checker + manual review | H57: Now | I57: William Imo | J57: WI-10 | K57: 46330 | L57: 46331 | M57: =IFERROR(NETWORKDAYS(K57,L57,DATE(2026,10,20)),"") -> 2 | N57: Standard M365 | O57: Not started
...

Sheet By Discipline
A1: Summary by discipline and tool
A2: Formulas over Development Tasks.
A4: Discipline | B4: Tasks | C4: Work days | D4: Main tools | E4: Main people
A5: Power Apps | B5: =COUNTIF('Development Tasks'!$E$5:$E$108,A5) -> 24 | C5: =SUMIF('Development Tasks'!$E$5:$E$108,A5,'Development Tasks'!$M$5:$M$108) -> 65 | D5: Power Apps canvas (Stock Take app, Hub), model-driven (Control Centre), custom pages | E5: William, Andrew, Jones
A6: Power Automate | B6: =COUNTIF('Development Tasks'!$E$5:$E$108,A6) -> 13 | C6: =SUMIF('Development Tasks'!$E$5:$E$108,A6,'Development Tasks'!$M$5:$M$108) -> 42 | D6: Cloud flows F01–F41, child flows, Approvals, Teams adaptive cards, Outlook | E6: Denis, Jones, Andrew, William
A7: UI | B7: =COUNTIF('Development Tasks'!$E$5:$E$108,A7) -> 5 | C7: =SUMIF('Development Tasks'!$E$5:$E$108,A7,'Development Tasks'!$M$5:$M$108) -> 11 | D7: Power Apps component library, NKG theme, SVG icons, QR label template | E7: William, Andrew, Jones
A8: UX | B8: =COUNTIF('Development Tasks'!$E$5:$E$108,A8) -> 6 | C8: =SUMIF('Development Tasks'!$E$5:$E$108,A8,'Development Tasks'!$M$5:$M$108) -> 15 | D8: Figma / prototypes, usability tests, accessibility checker | E8: William, Jones, Frankie
A9: Data Engineering | B9: =COUNTIF('Development Tasks'!$E$5:$E$108,A9) -> 26 | C9: =SUMIF('Development Tasks'!$E$5:$E$108,A9,'Development Tasks'!$M$5:$M$108) -> 101 | D9: Dataverse, Power Query dataflows, custom connectors / gateway (target), Fabric (optional) | E9: Denis, Moses
A10: Data Analyst | B10: =COUNTIF('Development Tasks'!$E$5:$E$108,A10) -> 10 | C10: =SUMIF('Development Tasks'!$E$5:$E$108,A10,'Development Tasks'!$M$5:$M$108) -> 30 | D10: Power BI (PBIP, DAX, RLS, paginated), Excel, Power Query | E10: Nicole
A11: Copilot | B11: =COUNTIF('Development Tasks'!$E$5:$E$108,A11) -> 7 | C11: =SUMIF('Development Tasks'!$E$5:$E$108,A11,'Development Tasks'!$M$5:$M$108) -> 20 | D11: Copilot Studio, SharePoint knowledge, agent flows, Teams | E11: Jones, Nicole
A12: Architecture / ALM | B12: =COUNTIF('Development Tasks'!$E$5:$E$108,A12) -> 10 | C12: =SUMIF('Development Tasks'!$E$5:$E$108,A12,'Development Tasks'!$M$5:$M$108) -> 36 | D12: Admin centre, solutions, pac CLI, pipelines, Git, Entra ID, DLP | E12: Moses
A13: Testing / QA | B13: =COUNTIF('Development Tasks'!$E$5:$E$108,A13) -> 3 | C13: =SUMIF('Development Tasks'!$E$5:$E$108,A13,'Development Tasks'!$M$5:$M$108) -> 26 | D13: Test scripts, Power Apps Test Engine, Monitor | E13: Frankie, Moses
A14: Total | B14: =SUM(B5:B13) -> 104 | C14: =SUM(C5:C13) -> 346

Sheet Integration Methods
A1: How each source connects — now and later
A2: We have no API access to XBS or Comtras yet, so we start with scheduled email files. Downstream logic does not change when APIs arrive.
A4: Source | B4: Now (interim) | C4: Target | D4: Owner | E4: Ask / note
A5: XBS (warehouse/outturn) | B5: Scheduled report email (Excel/CSV) to shared mailbox → SharePoint → dataflow | C5: REST API custom connector, or read-only SQL view via on-premises data gateway | D5: XBS system owner / NKG IT | E5: Ask: API documentation, read-only DB view, gateway server
A6: Comtras / BRIC (526, 537, contracts) | B6: Scheduled report email to shared mailbox | C6: REST API or read-only SQL view via gateway | D6: Comtras/BRIC owner / Finance | E6: Ask: report scheduler access, API/DB access
A7: Sun Systems (if needed for values) | B7: Monthly export email | C7: Sun connector / SQL view via gateway | D7: Finance | E7: Scope to confirm
A8: SNI, provisional, third-party balances | B8: Excel templates emailed by Logistics/Trade | C8: Remain email/form-based (no system of record) | D8: Logistics, Trade | E8: Templates in STK-Intake/Templates
A9: Physical count | B9: Stock Take app writes directly to Dataverse | C9: Same | D9: Operations | E9: —
A10: Corrections back to XBS/Comtras | B10: Weekly Excel batch emailed to system owners; confirmed by next snapshot | C10: Post via API when write access is granted | D10: System owners | E10: Never write to source systems without approval
A11: Power BI | B11: Dataverse connector (TDS endpoint), scheduled refresh triggered by flow | C11: Direct Lake on Fabric (optional) | D11: Pathways / NKG IT | E11: —
